Workbook
Name _xlfn_BAHTTEXT: none
Name _xlfn_IFERROR: none
Name _xlfn_SINGLE: none
Name DB: Intro!$D$15:$D$16
Name Excel_BuiltIn__FilterDatabase: Other_SCH09!$A$1:$A$4
Name Excel_BuiltIn__FilterDatabase: Tel_SCH03!$A$1:$A$4
Name month: #REF!
Name PRD: Intro!$D$13
Name Print_Area_MI: #REF!
Name RV: Intro!$D$17
Name YR: Intro!$D$14

Sheet GLAC
A1: GLACNO | B1: GLAC_NAME | C1: GLAC_CRDR | D1: GLAC_BI | E1: GLAC_CBFWD | F1: GLAC_CB01 | G1: GLAC_CB02 | H1: GLAC_CB03 | I1: GLAC_CB04 | J1: GLAC_CB05 | K1: GLAC_CB06 | L1: GLAC_CB07 | M1: GLAC_CB08 | N1: GLAC_CB09 | O1: GLAC_CB10 | P1: GLAC_CB11 | Q1: GLAC_CB12 | R1: GLAC_CB13 | S1: GLAC_CB14 | T1: GLAC_CB15 | U1: GLAC_CB16 | V1: GLAC_CB17 | W1: GLAC_CB18 | X1: GLAC_CB19 | Y1: GLAC_CB20 | Z1: GLAC_CB21 | AA1: GLAC_CB22 | AB1: GLAC_CB23 | AC1: GLAC_CB24 | AD1: GLAC_CB25 | AE1: GLAC_CB26 | AF1: GLAC_PBFWD | AG1: GLAC_PB01 | AH1: GLAC_PB02 | AI1: GLAC_PB03 | AJ1: GLAC_PB04 | AK1: GLAC_PB05 | AL1: GLAC_PB06 | AM1: GLAC_PB07 | AN1: GLAC_PB08 | AO1: GLAC_PB09 | AP1: GLAC_PB10 | AQ1: GLAC_PB11 | AR1: GLAC_PB12 | AS1: GLAC_PB13 | AT1: GLAC_CBG01 | AU1: GLAC_CBG02 | AV1: GLAC_CBG03 | AW1: GLAC_CBG04 | AX1: GLAC_CBG05 | AY1: GLAC_CBG06 | AZ1: GLAC_CBG07 | BA1: GLAC_CBG08 | BB1: GLAC_CBG09 | BC1: GLAC_CBG10 | BD1: GLAC_CBG11 | BE1: GLAC_CBG12 | BF1: GLAC_CBG13 | BG1: GLAC_PBG01 | BH1: GLAC_PBG02 | BI1: GLAC_PBG03 | BJ1: GLAC_PBG04 | BK1: GLAC_PBG05 | BL1: GLAC_PBG06 | BM1: GLAC_PBG07 | BN1: GLAC_PBG08 | BO1: GLAC_PBG09 | BP1: GLAC_PBG10 | BQ1: GLAC_PBG11 | BR1: GLAC_PBG12 | BS1: GLAC_PBG13 | BT1: GLAC_NBG01 | BU1: GLAC_NBG02 | BV1: GLAC_NBG03 | BW1: GLAC_NBG04 | BX1: GLAC_NBG05 | BY1: GLAC_NBG06 | BZ1: GLAC_NBG07 | CA1: GLAC_NBG08 | CB1: GLAC_NBG09 | CC1: GLAC_NBG10 | CD1: GLAC_NBG11 | CE1: GLAC_NBG12 | CF1: GLAC_NBG13 | CG1: CBG01R1 | CH1: CBG02R1 | CI1: CBG03R1 | CJ1: CBG04R1 | CK1: CBG05R1 | CL1: CBG06R1 | CM1: CBG07R1 | CN1: CBG08R1 | CO1: CBG09R1 | CP1: CBG10R1 | CQ1: CBG11R1 | CR1: CBG12R1 | CS1: CBG13R1 | CT1: CBG01R2 | CU1: CBG02R2 | CV1: CBG03R2 | CW1: CBG04R2 | CX1: CBG05R2 | CY1: CBG06R2 | CZ1: CBG07R2 | DB1: CBG09R2 | DC1: CBG10R2 | DD1: CBG11R2 | DE1: CBG12R2 | DF1: CBG13R2 | DG1: CBG01R3 | DH1: CBG02R3 | DI1: CBG03R3 | DJ1: CBG04R3 | DK1: CBG05R3 | DL1: CBG06R3 | DM1: CBG07R3 | DN1: CBG08R3 | DO1: CBG09R3 | DP1: CBG10R3 | DQ1: CBG11R3 | DR1: CBG12R3 | DS1: CBG13R3 | DT1: CBG01R4 | DU1: CBG02R4 | DV1: CBG03R4 | DW1: CBG04R4 | DX1: CBG05R4 | DY1: CBG06R4 | DZ1: CBG07R4 | EA1: CBG08R4 | EB1: CBG09R4 | EC1: CBG10R4 | ED1: CBG11R4 | EE1: CBG12R4 | EF1: CBG13R4
A2: 100*** | B2: ***ASSETS*** | C2: D | D2: H | E2: 0 | F2: 0 | G2: 0 | H2: 0 | I2: 0 | J2: 0 | K2: 0 | L2: 0 | M2: 0 | N2: 0 | O2: 0 | P2: 0 | Q2: 0 | R2: 0 | S2: 0 | T2: 0 | U2: 0 | V2: 0 | W2: 0 | X2: 0 | Y2: 0 | Z2: 0 | AA2: 0 | AB2: 0 | AC2: 0 | AD2: 0 | AE2: 0 | AF2: 0 | AG2: 0 | AH2: 0 | AI2: 0 | AJ2: 0 | AK2: 0 | AL2: 0 | AM2: 0 | AN2: 0 | AO2: 0 | AP2: 0 | AQ2: 0 | AR2: 0 | AS2: 0 | AT2: 0 | AU2: 0 | AV2: 0 | AW2: 0 | AX2: 0 | AY2: 0 | AZ2: 0 | BA2: 0 | BB2: 0 | BC2: 0 | BD2: 0 | BE2: 0 | BF2: 0 | BG2: 0 | BH2: 0 | BI2: 0 | BJ2: 0 | BK2: 0 | BL2: 0 | BM2: 0 | BN2: 0 | BO2: 0 | BP2: 0 | BQ2: 0 | BR2: 0 | BS2: 0 | BT2: 0 | BU2: 0 | BV2: 0 | BW2: 0 | BX2: 0 | BY2: 0 | BZ2: 0 | CA2: 0 | CB2: 0 | CC2: 0 | CD2: 0 | CE2: 0 | CF2: 0 | CG2: 0 | CH2: 0 | CI2: 0 | CJ2: 0 | CK2: 0 | CL2: 0 | CM2: 0 | CN2: 0 | CO2: 0 | CP2: 0 | CQ2: 0 | CR2: 0 | CS2: 0 | CT2: 0 | CU2: 0 | CV2: 0 | CW2: 0 | CX2: 0 | CY2: 0 | CZ2: 0 | DB2: 0 | DC2: 0 | DD2: 0 | DE2: 0 | DF2: 0 | DG2: 0 | DH2: 0 | DI2: 0 | DJ2: 0 | DK2: 0 | DL2: 0 | DM2: 0 | DN2: 0 | DO2: 0 | DP2: 0 | DQ2: 0 | DR2: 0 | DS2: 0 | DT2: 0 | DU2: 0 | DV2: 0 | DW2: 0 | DX2: 0 | DY2: 0 | DZ2: 0 | EA2: 0 | EB2: 0 | EC2: 0 | ED2: 0 | EE2: 0 | EF2: 0
A3: 110*** | B3: ***CURRENT ASSETS*** | C3: D | D3: H | E3: 0 | F3: 0 | G3: 0 | H3: 0 | I3: 0 | J3: 0 | K3: 0 | L3: 0 | M3: 0 | N3: 0 | O3: 0 | P3: 0 | Q3: 0 | R3: 0 | S3: 0 | T3: 0 | U3: 0 | V3: 0 | W3: 0 | X3: 0 | Y3: 0 | Z3: 0 | AA3: 0 | AB3: 0 | AC3: 0 | AD3: 0 | AE3: 0 | AF3: 0 | AG3: 0 | AH3: 0 | AI3: 0 | AJ3: 0 | AK3: 0 | AL3: 0 | AM3: 0 | AN3: 0 | AO3: 0 | AP3: 0 | AQ3: 0 | AR3: 0 | AS3: 0 | AT3: 0 | AU3: 0 | AV3: 0 | AW3: 0 | AX3: 0 | AY3: 0 | AZ3: 0 | BA3: 0 | BB3: 0 | BC3: 0 | BD3: 0 | BE3: 0 | BF3: 0 | BG3: 0 | BH3: 0 | BI3: 0 | BJ3: 0 | BK3: 0 | BL3: 0 | BM3: 0 | BN3: 0 | BO3: 0 | BP3: 0 | BQ3: 0 | BR3: 0 | BS3: 0 | BT3: 0 | BU3: 0 | BV3: 0 | BW3: 0 | BX3: 0 | BY3: 0 | BZ3: 0 | CA3: 0 | CB3: 0 | CC3: 0 | CD3: 0 | CE3: 0 | CF3: 0 | CG3: 0 | CH3: 0 | CI3: 0 | CJ3: 0 | CK3: 0 | CL3: 0 | CM3: 0 | CN3: 0 | CO3: 0 | CP3: 0 | CQ3: 0 | CR3: 0 | CS3: 0 | CT3: 0 | CU3: 0 | CV3: 0 | CW3: 0 | CX3: 0 | CY3: 0 | CZ3: 0 | DB3: 0 | DC3: 0 | DD3: 0 | DE3: 0 | DF3: 0 | DG3: 0 | DH3: 0 | DI3: 0 | DJ3: 0 | DK3: 0 | DL3: 0 | DM3: 0 | DN3: 0 | DO3: 0 | DP3: 0 | DQ3: 0 | DR3: 0 | DS3: 0 | DT3: 0 | DU3: 0 | DV3: 0 | DW3: 0 | DX3: 0 | DY3: 0 | DZ3: 0 | EA3: 0 | EB3: 0 | EC3: 0 | ED3: 0 | EE3: 0 | EF3: 0
A4: 110100 | B4: CASH ON HAND | C4: D | D4: B | E4: 0 | F4: 0 | G4: 0 | H4: 0 | I4: 0 | J4: 0 | K4: 0 | L4: 0 | M4: 0 | N4: 0 | O4: 0 | P4: 0 | Q4: 0 | R4: 0 | S4: 0 | T4: 0 | U4: 0 | V4: 0 | W4: 0 | X4: 0 | Y4: 0 | Z4: 0 | AA4: 0 | AB4: 0 | AC4: 0 | AD4: 0 | AE4: 0 | AF4: 0 | AG4: 0 | AH4: 0 | AI4: 0 | AJ4: 0 | AK4: 0 | AL4: 0 | AM4: 0 | AN4: 0 | AO4: 0 | AP4: 0 | AQ4: 0 | AR4: 0 | AS4: 0 | AT4: 0 | AU4: 0 | AV4: 0 | AW4: 0 | AX4: 0 | AY4: 0 | AZ4: 0 | BA4: 0 | BB4: 0 | BC4: 0 | BD4: 0 | BE4: 0 | BF4: 0 | BG4: 0 | BH4: 0 | BI4: 0 | BJ4: 0 | BK4: 0 | BL4: 0 | BM4: 0 | BN4: 0 | BO4: 0 | BP4: 0 | BQ4: 0 | BR4: 0 | BS4: 0 | BT4: 0 | BU4: 0 | BV4: 0 | BW4: 0 | BX4: 0 | BY4: 0 | BZ4: 0 | CA4: 0 | CB4: 0 | CC4: 0 | CD4: 0 | CE4: 0 | CF4: 0 | CG4: 0 | CH4: 0 | CI4: 0 | CJ4: 0 | CK4: 0 | CL4: 0 | CM4: 0 | CN4: 0 | CO4: 0 | CP4: 0 | CQ4: 0 | CR4: 0 | CS4: 0 | CT4: 0 | CU4: 0 | CV4: 0 | CW4: 0 | CX4: 0 | CY4: 0 | CZ4: 0 | DB4: 0 | DC4: 0 | DD4: 0 | DE4: 0 | DF4: 0 | DG4: 0 | DH4: 0 | DI4: 0 | DJ4: 0 | DK4: 0 | DL4: 0 | DM4: 0 | DN4: 0 | DO4: 0 | DP4: 0 | DQ4: 0 | DR4: 0 | DS4: 0 | DT4: 0 | DU4: 0 | DV4: 0 | DW4: 0 | DX4: 0 | DY4: 0 | DZ4: 0 | EA4: 0 | EB4: 0 | EC4: 0 | ED4: 0 | EE4: 0 | EF4: 0
A5: 110200 | B5: PETTY CASH | C5: D | D5: B | E5: 30000 | F5: 0 | G5: 0 | H5: 0 | I5: 0 | J5: 0 | K5: 0 | L5: 0 | M5: 0 | N5: 0 | O5: 0 | P5: 0 | Q5: 0 | R5: 0 | S5: 0 | T5: 0 | U5: 0 | V5: 0 | W5: 0 | X5: 0 | Y5: 0 | Z5: 0 | AA5: 0 | AB5: 0 | AC5: 0 | AD5: 0 | AE5: 0 | AF5: 30000 | AG5: 0 | AH5: 0 | AI5: 0 | AJ5: 0 | AK5: 0 | AL5: 0 | AM5: 0 | AN5: 0 | AO5: 0 | AP5: 0 | AQ5: 0 | AR5: 0 | AS5: 0 | AT5: 0 | AU5: 0 | AV5: 0 | AW5: 0 | AX5: 0 | AY5: 0 | AZ5: 0 | BA5: 0 | BB5: 0 | BC5: 0 | BD5: 0 | BE5: 0 | BF5: 0 | BG5: 0 | BH5: 0 | BI5: 0 | BJ5: 0 | BK5: 0 | BL5: 0 | BM5: 0 | BN5: 0 | BO5: 0 | BP5: 0 | BQ5: 0 | BR5: 0 | BS5: 0 | BT5: 0 | BU5: 0 | BV5: 0 | BW5: 0 | BX5: 0 | BY5: 0 | BZ5: 0 | CA5: 0 | CB5: 0 | CC5: 0 | CD5: 0 | CE5: 0 | CF5: 0 | CG5: 0 | CH5: 0 | CI5: 0 | CJ5: 0 | CK5: 0 | CL5: 0 | CM5: 0 | CN5: 0 | CO5: 0 | CP5: 0 | CQ5: 0 | CR5: 0 | CS5: 0 | CT5: 0 | CU5: 0 | CV5: 0 | CW5: 0 | CX5: 0 | CY5: 0 | CZ5: 0 | DB5: 0 | DC5: 0 | DD5: 0 | DE5: 0 | DF5: 0 | DG5: 0 | DH5: 0 | DI5: 0 | DJ5: 0 | DK5: 0 | DL5: 0 | DM5: 0 | DN5: 0 | DO5: 0 | DP5: 0 | DQ5: 0 | DR5: 0 | DS5: 0 | DT5: 0 | DU5: 0 | DV5: 0 | DW5: 0 | DX5: 0 | DY5: 0 | DZ5: 0 | EA5: 0 | EB5: 0 | EC5: 0 | ED5: 0 | EE5: 0 | EF5: 0
A6: 110310 | B6: HOUSE FUND - FRONT OFFICE | C6: D | D6: B | E6: 40000 | F6: 0 | G6: 0 | H6: 0 | I6: 0 | J6: 0 | K6: 0 | L6: 0 | M6: 0 | N6: 0 | O6: 0 | P6: 0 | Q6: 0 | R6: 0 | S6: 0 | T6: 0 | U6: 0 | V6: 0 | W6: 0 | X6: 0 | Y6: 0 | Z6: 0 | AA6: 0 | AB6: 0 | AC6: 0 | AD6: 0 | AE6: 0 | AF6: 40000 | AG6: 0 | AH6: 0 | AI6: 0 | AJ6: 0 | AK6: 0 | AL6: 0 | AM6: 0 | AN6: 0 | AO6: 0 | AP6: 0 | AQ6: 0 | AR6: 0 | AS6: 0 | AT6: 0 | AU6: 0 | AV6: 0 | AW6: 0 | AX6: 0 | AY6: 0 | AZ6: 0 | BA6: 0 | BB6: 0 | BC6: 0 | BD6: 0 | BE6: 0 | BF6: 0 | BG6: 0 | BH6: 0 | BI6: 0 | BJ6: 0 | BK6: 0 | BL6: 0 | BM6: 0 | BN6: 0 | BO6: 0 | BP6: 0 | BQ6: 0 | BR6: 0 | BS6: 0 | BT6: 0 | BU6: 0 | BV6: 0 | BW6: 0 | BX6: 0 | BY6: 0 | BZ6: 0 | CA6: 0 | CB6: 0 | CC6: 0 | CD6: 0 | CE6: 0 | CF6: 0 | CG6: 0 | CH6: 0 | CI6: 0 | CJ6: 0 | CK6: 0 | CL6: 0 | CM6: 0 | CN6: 0 | CO6: 0 | CP6: 0 | CQ6: 0 | CR6: 0 | CS6: 0 | CT6: 0 | CU6: 0 | CV6: 0 | CW6: 0 | CX6: 0 | CY6: 0 | CZ6: 0 | DB6: 0 | DC6: 0 | DD6: 0 | DE6: 0 | DF6: 0 | DG6: 0 | DH6: 0 | DI6: 0 | DJ6: 0 | DK6: 0 | DL6: 0 | DM6: 0 | DN6: 0 | DO6: 0 | DP6: 0 | DQ6: 0 | DR6: 0 | DS6: 0 | DT6: 0 | DU6: 0 | DV6: 0 | DW6: 0 | DX6: 0 | DY6: 0 | DZ6: 0 | EA6: 0 | EB6: 0 | EC6: 0 | ED6: 0 | EE6: 0 | EF6: 0
A7: 110320 | B7: HOUSE FUND - RESTAURANT | C7: D | D7: B | E7: 8000 | F7: 0 | G7: 0 | H7: 0 | I7: 0 | J7: 0 | K7: 0 | L7: 0 | M7: 0 | N7: 0 | O7: 0 | P7: 0 | Q7: 0 | R7: 0 | S7: 0 | T7: 0 | U7: 0 | V7: 0 | W7: 0 | X7: 0 | Y7: 0 | Z7: 0 | AA7: 0 | AB7: 0 | AC7: 0 | AD7: 0 | AE7: 0 | AF7: 5000 | AG7: 0 | AH7: 0 | AI7: 0 | AJ7: 0 | AK7: 0 | AL7: 0 | AM7: 0 | AN7: 0 | AO7: 0 | AP7: 0 | AQ7: 0 | AR7: 3000 | AS7: 0 | AT7: 0 | AU7: 0 | AV7: 0 | AW7: 0 | AX7: 0 | AY7: 0 | AZ7: 0 | BA7: 0 | BB7: 0 | BC7: 0 | BD7: 0 | BE7: 0 | BF7: 0 | BG7: 0 | BH7: 0 | BI7: 0 | BJ7: 0 | BK7: 0 | BL7: 0 | BM7: 0 | BN7: 0 | BO7: 0 | BP7: 0 | BQ7: 0 | BR7: 0 | BS7: 0 | BT7: 0 | BU7: 0 | BV7: 0 | BW7: 0 | BX7: 0 | BY7: 0 | BZ7: 0 | CA7: 0 | CB7: 0 | CC7: 0 | CD7: 0 | CE7: 0 | CF7: 0 | CG7: 0 | CH7: 0 | CI7: 0 | CJ7: 0 | CK7: 0 | CL7: 0 | CM7: 0 | CN7: 0 | CO7: 0 | CP7: 0 | CQ7: 0 | CR7: 0 | CS7: 0 | CT7: 0 | CU7: 0 | CV7: 0 | CW7: 0 | CX7: 0 | CY7: 0 | CZ7: 0 | DB7: 0 | DC7: 0 | DD7: 0 | DE7: 0 | DF7: 0 | DG7: 0 | DH7: 0 | DI7: 0 | DJ7: 0 | DK7: 0 | DL7: 0 | DM7: 0 | DN7: 0 | DO7: 0 | DP7: 0 | DQ7: 0 | DR7: 0 | DS7: 0 | DT7: 0 | DU7: 0 | DV7: 0 | DW7: 0 | DX7: 0 | DY7: 0 | DZ7: 0 | EA7: 0 | EB7: 0 | EC7: 0 | ED7: 0 | EE7: 0 | EF7: 0
A8: 110330 | B8: HOUSE FUND - EXCHANGE | C8: D | D8: B | E8: 0 | F8: 0 | G8: 0 | H8: 0 | I8: 0 | J8: 0 | K8: 0 | L8: 0 | M8: 0 | N8: 0 | O8: 0 | P8: 0 | Q8: 0 | R8: 0 | S8: 0 | T8: 0 | U8: 0 | V8: 0 | W8: 0 | X8: 0 | Y8: 0 | Z8: 0 | AA8: 0 | AB8: 0 | AC8: 0 | AD8: 0 | AE8: 0 | AF8: 0 | AG8: 0 | AH8: 0 | AI8: 0 | AJ8: 0 | AK8: 0 | AL8: 0 | AM8: 0 | AN8: 0 | AO8: 0 | AP8: 0 | AQ8: 0 | AR8: 0 | AS8: 0 | AT8: 0 | AU8: 0 | AV8: 0 | AW8: 0 | AX8: 0 | AY8: 0 | AZ8: 0 | BA8: 0 | BB8: 0 | BC8: 0 | BD8: 0 | BE8: 0 | BF8: 0 | BG8: 0 | BH8: 0 | BI8: 0 | BJ8: 0 | BK8: 0 | BL8: 0 | BM8: 0 | BN8: 0 | BO8: 0 | BP8: 0 | BQ8: 0 | BR8: 0 | BS8: 0 | BT8: 0 | BU8: 0 | BV8: 0 | BW8: 0 | BX8: 0 | BY8: 0 | BZ8: 0 | CA8: 0 | CB8: 0 | CC8: 0 | CD8: 0 | CE8: 0 | CF8: 0 | CG8: 0 | CH8: 0 | CI8: 0 | CJ8: 0 | CK8: 0 | CL8: 0 | CM8: 0 | CN8: 0 | CO8: 0 | CP8: 0 | CQ8: 0 | CR8: 0 | CS8: 0 | CT8: 0 | CU8: 0 | CV8: 0 | CW8: 0 | CX8: 0 | CY8: 0 | CZ8: 0 | DB8: 0 | DC8: 0 | DD8: 0 | DE8: 0 | DF8: 0 | DG8: 0 | DH8: 0 | DI8: 0 | DJ8: 0 | DK8: 0 | DL8: 0 | DM8: 0 | DN8: 0 | DO8: 0 | DP8: 0 | DQ8: 0 | DR8: 0 | DS8: 0 | DT8: 0 | DU8: 0 | DV8: 0 | DW8: 0 | DX8: 0 | DY8: 0 | DZ8: 0 | EA8: 0 | EB8: 0 | EC8: 0 | ED8: 0 | EE8: 0 | EF8: 0
A9: 110340 | B9: HOUSE FUND - PURCHASING | C9: D | D9: B | E9: 0 | F9: 0 | G9: 0 | H9: 0 | I9: 0 | J9: 0 | K9: 0 | L9: 0 | M9: 0 | N9: 0 | O9: 0 | P9: 0 | Q9: 0 | R9: 0 | S9: 0 | T9: 0 | U9: 0 | V9: 0 | W9: 0 | X9: 0 | Y9: 0 | Z9: 0 | AA9: 0 | AB9: 0 | AC9: 0 | AD9: 0 | AE9: 0 | AF9: 0 | AG9: 0 | AH9: 0 | AI9: 0 | AJ9: 0 | AK9: 0 | AL9: 0 | AM9: 0 | AN9: 0 | AO9: 0 | AP9: 0 | AQ9: 0 | AR9: 0 | AS9: 0 | AT9: 0 | AU9: 0 | AV9: 0 | AW9: 0 | AX9: 0 | AY9: 0 | AZ9: 0 | BA9: 0 | BB9: 0 | BC9: 0 | BD9: 0 | BE9: 0 | BF9: 0 | BG9: 0 | BH9: 0 | BI9: 0 | BJ9: 0 | BK9: 0 | BL9: 0 | BM9: 0 | BN9: 0 | BO9: 0 | BP9: 0 | BQ9: 0 | BR9: 0 | BS9: 0 | BT9: 0 | BU9: 0 | BV9: 0 | BW9: 0 | BX9: 0 | BY9: 0 | BZ9: 0 | CA9: 0 | CB9: 0 | CC9: 0 | CD9: 0 | CE9: 0 | CF9: 0 | CG9: 0 | CH9: 0 | CI9: 0 | CJ9: 0 | CK9: 0 | CL9: 0 | CM9: 0 | CN9: 0 | CO9: 0 | CP9: 0 | CQ9: 0 | CR9: 0 | CS9: 0 | CT9: 0 | CU9: 0 | CV9: 0 | CW9: 0 | CX9: 0 | CY9: 0 | CZ9: 0 | DB9: 0 | DC9: 0 | DD9: 0 | DE9: 0 | DF9: 0 | DG9: 0 | DH9: 0 | DI9: 0 | DJ9: 0 | DK9: 0 | DL9: 0 | DM9: 0 | DN9: 0 | DO9: 0 | DP9: 0 | DQ9: 0 | DR9: 0 | DS9: 0 | DT9: 0 | DU9: 0 | DV9: 0 | DW9: 0 | DX9: 0 | DY9: 0 | DZ9: 0 | EA9: 0 | EB9: 0 | EC9: 0 | ED9: 0 | EE9: 0 | EF9: 0
A10: 110350 | B10: HOUSE FUND - SPA | C10: D | D10: B | E10: 3000 | F10: 0 | G10: 0 | H10: 0 | I10: 0 | J10: 0 | K10: 0 | L10: 0 | M10: 0 | N10: 0 | O10: 0 | P10: 0 | Q10: 0 | R10: 0 | S10: 0 | T10: 0 | U10: 0 | V10: 0 | W10: 0 | X10: 0 | Y10: 0 | Z10: 0 | AA10: 0 | AB10: 0 | AC10: 0 | AD10: 0 | AE10: 0 | AF10: 3000 | AG10: 0 | AH10: 0 | AI10: 0 | AJ10: 0 | AK10: 0 | AL10: 0 | AM10: 0 | AN10: 0 | AO10: 0 | AP10: 0 | AQ10: 0 | AR10: 0 | AS10: 0 | AT10: 0 | AU10: 0 | AV10: 0 | AW10: 0 | AX10: 0 | AY10: 0 | AZ10: 0 | BA10: 0 | BB10: 0 | BC10: 0 | BD10: 0 | BE10: 0 | BF10: 0 | BG10: 0 | BH10: 0 | BI10: 0 | BJ10: 0 | BK10: 0 | BL10: 0 | BM10: 0 | BN10: 0 | BO10: 0 | BP10: 0 | BQ10: 0 | BR10: 0 | BS10: 0 | BT10: 0 | BU10: 0 | BV10: 0 | BW10: 0 | BX10: 0 | BY10: 0 | BZ10: 0 | CA10: 0 | CB10: 0 | CC10: 0 | CD10: 0 | CE10: 0 | CF10: 0 | CG10: 0 | CH10: 0 | CI10: 0 | CJ10: 0 | CK10: 0 | CL10: 0 | CM10: 0 | CN10: 0 | CO10: 0 | CP10: 0 | CQ10: 0 | CR10: 0 | CS10: 0 | CT10: 0 | CU10: 0 | CV10: 0 | CW10: 0 | CX10: 0 | CY10: 0 | CZ10: 0 | DB10: 0 | DC10: 0 | DD10: 0 | DE10: 0 | DF10: 0 | DG10: 0 | DH10: 0 | DI10: 0 | DJ10: 0 | DK10: 0 | DL10: 0 | DM10: 0 | DN10: 0 | DO10: 0 | DP10: 0 | DQ10: 0 | DR10: 0 | DS10: 0 | DT10: 0 | DU10: 0 | DV10: 0 | DW10: 0 | DX10: 0 | DY10: 0 | DZ10: 0 | EA10: 0 | EB10: 0 | EC10: 0 | ED10: 0 | EE10: 0 | EF10: 0
A11: 110360 | B11: HOUSE FUND - S&M BANGKOK OFFICE | C11: D | D11: B | E11: 0 | F11: 0 | G11: 0 | H11: 0 | I11: 0 | J11: 0 | K11: 0 | L11: 0 | M11: 0 | N11: 0 | O11: 0 | P11: 0 | Q11: 0 | R11: 0 | S11: 0 | T11: 0 | U11: 0 | V11: 0 | W11: 0 | X11: 0 | Y11: 0 | Z11: 0 | AA11: 0 | AB11: 0 | AC11: 0 | AD11: 0 | AE11: 0 | AF11: 0 | AG11: 0 | AH11: 0 | AI11: 0 | AJ11: 0 | AK11: 0 | AL11: 0 | AM11: 0 | AN11: 0 | AO11: 0 | AP11: 0 | AQ11: 0 | AR11: 0 | AS11: 0 | AT11: 0 | AU11: 0 | AV11: 0 | AW11: 0 | AX11: 0 | AY11: 0 | AZ11: 0 | BA11: 0 | BB11: 0 | BC11: 0 | BD11: 0 | BE11: 0 | BF11: 0 | BG11: 0 | BH11: 0 | BI11: 0 | BJ11: 0 | BK11: 0 | BL11: 0 | BM11: 0 | BN11: 0 | BO11: 0 | BP11: 0 | BQ11: 0 | BR11: 0 | BS11: 0 | BT11: 0 | BU11: 0 | BV11: 0 | BW11: 0 | BX11: 0 | BY11: 0 | BZ11: 0 | CA11: 0 | CB11: 0 | CC11: 0 | CD11: 0 | CE11: 0 | CF11: 0 | CG11: 0 | CH11: 0 | CI11: 0 | CJ11: 0 | CK11: 0 | CL11: 0 | CM11: 0 | CN11: 0 | CO11: 0 | CP11: 0 | CQ11: 0 | CR11: 0 | CS11: 0 | CT11: 0 | CU11: 0 | CV11: 0 | CW11: 0 | CX11: 0 | CY11: 0 | CZ11: 0 | DB11: 0 | DC11: 0 | DD11: 0 | DE11: 0 | DF11: 0 | DG11: 0 | DH11: 0 | DI11: 0 | DJ11: 0 | DK11: 0 | DL11: 0 | DM11: 0 | DN11: 0 | DO11: 0 | DP11: 0 | DQ11: 0 | DR11: 0 | DS11: 0 | DT11: 0 | DU11: 0 | DV11: 0 | DW11: 0 | DX11: 0 | DY11: 0 | DZ11: 0 | EA11: 0 | EB11: 0 | EC11: 0 | ED11: 0 | EE11: 0 | EF11: 0
A12: 110400 | B12: CASH SALES CLEARANCE | C12: D | D12: B | E12: 370812 | F12: -351166 | G12: 169090 | H12: -99232.65 | I12: -65630.71 | J12: -17418.93 | K12: 1838.82 | L12: 2499.47 | M12: 14958.84 | N12: -25750.84 | O12: 0 | P12: 0 | Q12: 0 | R12: 0 | S12: 0 | T12: 0 | U12: 0 | V12: 0 | W12: 0 | X12: 0 | Y12: 0 | Z12: 0 | AA12: 0 | AB12: 0 | AC12: 0 | AD12: 0 | AE12: 0 | AF12: 30571 | AG12: -23437 | AH12: 7915 | AI12: -4503 | AJ12: 46104.6 | AK12: -52070.6 | AL12: 12024 | AM12: -6696 | AN12: -8428 | AO12: -405 | AP12: 10255 | AQ12: 5005.08 | AR12: 354476.92 | AS12: 0 | AT12: 0 | AU12: 0 | AV12: 0 | AW12: 0 | AX12: 0 | AY12: 0 | AZ12: 0 | BA12: 0 | BB12: 0 | BC12: 0 | BD12: 0 | BE12: 0 | BF12: 0 | BG12: 0 | BH12: 0 | BI12: 0 | BJ12: 0 | BK12: 0 | BL12: 0 | BM12: 0 | BN12: 0 | BO12: 0 | BP12: 0 | BQ12: 0 | BR12: 0 | BS12: 0 | BT12: 0 | BU12: 0 | BV12: 0 | BW12: 0 | BX12: 0 | BY12: 0 | BZ12: 0 | CA12: 0 | CB12: 0 | CC12: 0 | CD12: 0 | CE12: 0 | CF12: 0 | CG12: 0 | CH12: 0 | CI12: 0 | CJ12: 0 | CK12: 0 | CL12: 0 | CM12: 0 | CN12: 0 | CO12: 0 | CP12: 0 | CQ12: 0 | CR12: 0 | CS12: 0 | CT12: 0 | CU12: 0 | CV12: 0 | CW12: 0 | CX12: 0 | CY12: 0 | CZ12: 0 | DB12: 0 | DC12: 0 | DD12: 0 | DE12: 0 | DF12: 0 | DG12: 0 | DH12: 0 | DI12: 0 | DJ12: 0 | DK12: 0 | DL12: 0 | DM12: 0 | DN12: 0 | DO12: 0 | DP12: 0 | DQ12: 0 | DR12: 0 | DS12: 0 | DT12: 0 | DU12: 0 | DV12: 0 | DW12: 0 | DX12: 0 | DY12: 0 | DZ12: 0 | EA12: 0 | EB12: 0 | EC12: 0 | ED12: 0 | EE12: 0 | EF12: 0
A13: 110510 | B13: CHEQUE ON HAND | C13: D | D13: B | E13: 0 | F13: 0 | G13: 0 | H13: 0 | I13: 0 | J13: 0 | K13: 0 | L13: 0 | M13: 0 | N13: 0 | O13: 0 | P13: 0 | Q13: 0 | R13: 0 | S13: 0 | T13: 0 | U13: 0 | V13: 0 | W13: 0 | X13: 0 | Y13: 0 | Z13: 0 | AA13: 0 | AB13: 0 | AC13: 0 | AD13: 0 | AE13: 0 | AF13: 0 | AG13: 0 | AH13: 0 | AI13: 0 | AJ13: 0 | AK13: 0 | AL13: 0 | AM13: 0 | AN13: 0 | AO13: 0 | AP13: 0 | AQ13: 0 | AR13: 0 | AS13: 0 | AT13: 0 | AU13: 0 | AV13: 0 | AW13: 0 | AX13: 0 | AY13: 0 | AZ13: 0 | BA13: 0 | BB13: 0 | BC13: 0 | BD13: 0 | BE13: 0 | BF13: 0 | BG13: 0 | BH13: 0 | BI13: 0 | BJ13: 0 | BK13: 0 | BL13: 0 | BM13: 0 | BN13: 0 | BO13: 0 | BP13: 0 | BQ13: 0 | BR13: 0 | BS13: 0 | BT13: 0 | BU13: 0 | BV13: 0 | BW13: 0 | BX13: 0 | BY13: 0 | BZ13: 0 | CA13: 0 | CB13: 0 | CC13: 0 | CD13: 0 | CE13: 0 | CF13: 0 | CG13: 0 | CH13: 0 | CI13: 0 | CJ13: 0 | CK13: 0 | CL13: 0 | CM13: 0 | CN13: 0 | CO13: 0 | CP13: 0 | CQ13: 0 | CR13: 0 | CS13: 0 | CT13: 0 | CU13: 0 | CV13: 0 | CW13: 0 | CX13: 0 | CY13: 0 | CZ13: 0 | DB13: 0 | DC13: 0 | DD13: 0 | DE13: 0 | DF13: 0 | DG13: 0 | DH13: 0 | DI13: 0 | DJ13: 0 | DK13: 0 | DL13: 0 | DM13: 0 | DN13: 0 | DO13: 0 | DP13: 0 | DQ13: 0 | DR13: 0 | DS13: 0 | DT13: 0 | DU13: 0 | DV13: 0 | DW13: 0 | DX13: 0 | DY13: 0 | DZ13: 0 | EA13: 0 | EB13: 0 | EC13: 0 | ED13: 0 | EE13: 0 | EF13: 0
... A1384: N/A | B1384: Not Available | C1384: D | D1384: S | E1384: 0 | F1384: 0 | G1384: 0 | H1384: 0 | I1384: 0 | J1384: 0 | K1384: 0 | L1384: 0 | M1384: 0 | N1384: 0 | O1384: 0 | P1384: 0 | Q1384: 0 | R1384: 0 | S1384: 0 | T1384: 0 | U1384: 0 | V1384: 0 | W1384: 0 | X1384: 0 | Y1384: 0 | Z1384: 0 | AA1384: 0 | AB1384: 0 | AC1384: 0 | AD1384: 0 | AE1384: 0 | AF1384: 0 | AG1384: 0 | AH1384: 0 | AI1384: 0 | AJ1384: 0 | AK1384: 0 | AL1384: 0 | AM1384: 0 | AN1384: 0 | AO1384: 0 | AP1384: 0 | AQ1384: 0 | AR1384: 0 | AS1384: 0 | AT1384: 0 | AU1384: 0 | AV1384: 0 | AW1384: 0 | AX1384: 0 | AY1384: 0 | AZ1384: 0 | BA1384: 0 | BB1384: 0 | BC1384: 0 | BD1384: 0 | BE1384: 0 | BF1384: 0 | BG1384: 0 | BH1384: 0 | BI1384: 0 | BJ1384: 0 | BK1384: 0 | BL1384: 0 | BM1384: 0 | BN1384: 0 | BO1384: 0 | BP1384: 0 | BQ1384: 0 | BR1384: 0 | BS1384: 0 | BT1384: 0 | BU1384: 0 | BV1384: 0 | BW1384: 0 | BX1384: 0 | BY1384: 0 | BZ1384: 0 | CA1384: 0 | CB1384: 0 | CC1384: 0 | CD1384: 0 | CE1384: 0 | CF1384: 0 | CG1384: 0 | CH1384: 0 | CI1384: 0 | CJ1384: 0 | CK1384: 0 | CL1384: 0 | CM1384: 0 | CN1384: 0 | CO1384: 0 | CP1384: 0 | CQ1384: 0 | CR1384: 0 | CS1384: 0 | CT1384: 0 | CU1384: 0 | CV1384: 0 | CW1384: 0 | CX1384: 0 | CY1384: 0 | CZ1384: 0 | DB1384: 0 | DC1384: 0 | DD1384: 0 | DE1384: 0 | DF1384: 0 | DG1384: 0 | DH1384: 0 | DI1384: 0 | DJ1384: 0 | DK1384: 0 | DL1384: 0 | DM1384: 0 | DN1384: 0 | DO1384: 0 | DP1384: 0 | DQ1384: 0 | DR1384: 0 | DS1384: 0 | DT1384: 0 | DU1384: 0 | DV1384: 0 | DW1384: 0 | DX1384: 0 | DY1384: 0 | DZ1384: 0 | EA1384: 0 | EB1384: 0 | EC1384: 0 | ED1384: 0 | EE1384: 0 | EF1384: 0

Sheet Intro
B7: CONFIDENTAL
B10: Financial Statement Report
B11: Ramada Resort Kho Lak
B12: Profit & ( Loss ) Statement
C13: Period | D13: 6
C14: Year | D14: 2026
C15: Database | D15: ramadakhaolak
C16: Database | D16: stwasset
C17: Budget | D17: 0
D23: {=_xll.GetBusinessUnitList()} -> ramadakhaolak
D24: ramadakhaolak_training
D25: stwasset

Sheet Cover
B2: Ramada Resort Khao Lak, Phang Nga
B4: Financial Reports
B7: Table of Contents
B12: Sch
C13: Trend of Operations
B14: 00 | C14: Summary Statement of Income
B15: 00A | C15: Supplementary Statement of Income
B17: Sch | C17: Operating Departments | D17: Sch | E17: Non-Operating Departments
B18: 01 | C18: Room Division | D18: 11 | E18: Administrative and General
B19: 02 | C19: Minibar | D19: 12 | E19: Human Resources
B20: 03 | C20: Telecommunications | D20: 13 | E20: Marketing
B21: 04 | C21: Guest Laundry | D21: 14 | E21: POMEC
B22: 05 | C22: Food & Beverage Division
B23: 06 | C23: The Spa
B24: 09 | C24: Other Income

Sheet SCH00A
A2: SUPPLEMENTARY STATEMENT OF INCOME
A3: =SCH00!J3 -> For the PRD of June 2026
R4: Schedule 00A
R5: MTD ACTUAL
R6: Local currency
F8: NET REVENUE | H8: COST | I8: % | K8: PAYROLL | L8: % | N8: OTHER EXPENSE | O8: % | Q8: INCOME (LOSS) | R8: %
A10: OPERATED DEPARTMENTS
B11: Rooms | F11: =+Room_SCH01!G26 -> 2893701.6 | H11: 0 | I11: =IF(H11=0,0,(H11*100/$F$11)) -> 0 | K11: =+Room_SCH01!G33 -> 1604568.5 | L11: =IF(K11=0,0,(K11*100/$F$11)) -> 55.45038 | N11: =+Room_SCH01!G63 -> 650238.08 | O11: =IF(N11=0,0,(N11*100/$F$11)) -> 22.470807 | Q11: =F11-H11-K11-N11 -> 638894.98 | R11: =IF(Q11=0,0,(Q11*100/$F$11)) -> 22.078814 | T11: 8620349.5 | U11: =+F11-T11 -> -5726648
B12: Food & Beverage | F12: =+'SCH05'!G24 -> 4907832.8 | H12: =+'SCH05'!G31 -> 1652253.4 | I12: =IF(H12=0,0,(H12*100/$F$12)) -> 33.665642 | K12: =+'SCH05'!G36 -> 899492.44 | L12: =IF(K12=0,0,(K12*100/$F$12)) -> 18.327691 | N12: ='SCH05'!G68 -> 501612.24 | O12: =IF(N12=0,0,(N12*100/$F$12)) -> 10.220647 | Q12: =F12-H12-K12-N12 -> 1854474.7 | R12: =IF(Q12=0,0,(Q12*100/$F$12)) -> 37.78602 | T12: 4194273.9 | U12: =+F12-T12 -> 713558.89 | V12: 146165.83 | W12: =+U12+V12 -> 859724.72
B13: Telecommunications | F13: =+Tel_SCH03!I14 -> 184.22 | H13: =+Tel_SCH03!I20 -> 0 | I13: =IF(OR(H13=0,F13=0),0,(H13*100/$F$13)) -> 0 | K13: =+Tel_SCH03!I29 -> 0 | L13: =IF(K13=0,0,(K13*100/$F$13)) -> 0 | N13: =Tel_SCH03!I33 -> 0 | O13: =IF(N13=0,0,(N13*100/$F$13)) -> 0 | Q13: =F13-H13-K13-N13 -> 184.22 | R13: =IF(OR(Q13=0,F13=0),0,(Q13*100/$F$13)) -> 100
B14: Guest Laundry | F14: =+Lau_SCH04!I12 -> 9736.6 | H14: =+Lau_SCH04!I14 -> 2372.8 | I14: =IF(H14=0,0,(H14*100/$F$14)) -> 24.369903 | K14: =+Lau_SCH04!I21 -> 0 | L14: =IF(K14=0,0,(K14*100/$F$14)) -> 0 | N14: =Lau_SCH04!I33 -> 0 | O14: =IF(N14=0,0,(N14*100/$F$14)) -> 0 | Q14: =F14-H14-K14-N14 -> 7363.8 | R14: =IF(Q14=0,0,(Q14*100/$F$14)) -> 75.630097
B15: The Spa | F15: =+Spa_SCH06!I13 -> 208086.72 | H15: =+Spa_SCH06!I15 -> 10930.9 | I15: =IF(H15=0,0,(H15*100/$F$15)) -> 5.2530503 | K15: =+Spa_SCH06!I22 -> 198894.12 | L15: =IF(K15=0,0,(K15*100/$F$15)) -> 95.582323 | N15: =Spa_SCH06!I49 -> 19523.58 | O15: =IF(N15=0,0,(N15*100/$F$15)) -> 9.3824248 | Q15: =F15-H15-K15-N15 -> -21261.88 | R15: =IF(Q15=0,0,(Q15*100/$F$15)) -> -10.217798
B16: Other Operated Departments | F16: ='Mini Bar_SCH02'!I14 -> 19329 | H16: ='Mini Bar_SCH02'!I17 -> 2998.46 | I16: =IF(H16=0,0,(H16*100/$F$16)) -> 15.512753 | K16: 0 | L16: =IF(K16=0,0,(K16*100/$F$16)) -> 0 | N16: ='Mini Bar_SCH02'!I35 -> 0 | O16: =IF(N16=0,0,(N16*100/$F$16)) -> 0 | Q16: =F16-H16-K16-N16 -> 16330.54 | R16: =IF(Q16=0,0,(Q16*100/$F$16)) -> 84.487247
B17: Rentals & Other Income | F17: =Other_SCH09!J17 -> 322055.52 | H17: =Other_SCH09!J24 -> 196079.24 | I17: =IF(H17=0,0,(H17*100/$F$17)) -> 60.883676 | K17: 0 | L17: =IF(K17=0,0,(K17*100/$F$17)) -> 0 | N17: 0 | O17: =IF(N17=0,0,(N17*100/$F$17)) -> 0 | Q17: =F17-H17-K17-N17 -> 125976.28 | R17: =IF(Q17=0,0,(Q17*100/$F$17)) -> 39.116324 | T17: 216907.13 | U17: =SUM(F13:F17)-T17 -> 342484.93
B18: Extraordinary items | F18: =+Room_SCH01!G27 -> 0 | H18: 0 | I18: =IF(H18=0,0,(H18*100/$F$18)) -> 0 | K18: 0 | L18: =IF(K18=0,0,(K18*100/$F$18)) -> 0 | N18: 0 | O18: =IF(N18=0,0,(N18*100/$F$18)) -> 0 | Q18: =F18-H18-K18-N18 -> 0 | R18: =IF(Q18=0,0,(Q18*100/$F$18)) -> 0
B19: Total Operated Departments | F19: =SUM(F11:F18) -> 8360926.4 | H19: =SUM(H11:H18) -> 1864634.8 | I19: =IF(H19=0,0,(H19*100/$F$19)) -> 22.301773 | K19: =SUM(K11:K18) -> 2702955.1 | L19: =IF(K19=0,0,(K19*100/$F$19)) -> 32.328416 | N19: =SUM(N11:N18) -> 1171373.9 | O19: =IF(N19=0,0,(N19*100/$F$19)) -> 14.010097 | Q19: =SUM(Q11:Q18) -> 2621962.6 | R19: =IF(Q19=0,0,(Q19*100/$F$19)) -> 31.359714 | T19: =SUM(T11:T18) -> 13031531 | U19: =SUM(U11:U18) -> -4670604.1 | V19: =+F19-T19-U19 -> 0
A21: UNDISTRIBUTED OPERATING EXPENSES
B22: Administrative & General | K22: =+AG_SCH11!I13 -> 1345878.1 | L22: =IF(K22=0,0,(K22*100/$F$19)) -> 16.097236 | N22: =AG_SCH11!I56 -> 1776195.2 | O22: =IF(N22=0,0,(N22*100/$F$19)) -> 21.244 | Q22: =K22+N22 -> 3122073.2 | R22: =IF(Q22=0,0,(Q22*100/$F$19)) -> 37.341236
B23: Human Resources | K23: =+HR_SCH12!I12 -> 297905.08 | L23: =IF(K23=0,0,(K23*100/$F$19)) -> 3.5630631 | N23: =HR_SCH12!I35 -> 65874.38 | O23: =IF(N23=0,0,(N23*100/$F$19)) -> 0.78788375 | Q23: =K23+N23 -> 363779.46 | R23: =IF(Q23=0,0,(Q23*100/$F$19)) -> 4.3509468
B24: Marketing | K24: =+SM_SCH13!I19 -> 475536.84 | L24: =IF(K24=0,0,(K24*100/$F$19)) -> 5.6876095 | N24: =SM_SCH13!I55+SM_SCH13!I13 -> 812205.5 | O24: =IF(N24=0,0,(N24*100/$F$19)) -> 9.7143003 | Q24: =K24+N24 -> 1287742.3 | R24: =IF(Q24=0,0,(Q24*100/$F$19)) -> 15.40191
B25: Energy | L25: =IF(K25=0,0,(K25*100/$F$19)) -> 0 | N25: =RM_SCH14!I21 -> 1074147.8 | O25: =IF(N25=0,0,(N25*100/$F$19)) -> 12.847234 | Q25: =K25+N25 -> 1074147.8 | R25: =IF(Q25=0,0,(Q25*100/$F$19)) -> 12.847234
B26: Repair & Maintenance | K26: =+RM_SCH14!I26 -> 743919.6 | L26: =IF(K26=0,0,(K26*100/$F$19)) -> 8.8975739 | N26: =RM_SCH14!I67 -> 863867.36 | O26: =IF(N26=0,0,(N26*100/$F$19)) -> 10.332197 | Q26: =K26+N26 -> 1607787 | R26: =IF(Q26=0,0,(Q26*100/$F$19)) -> 19.229771
B27: Total Undistributed Operating Expenses | K27: =SUM(K22:K26) -> 2863239.6 | L27: =IF(K27=0,0,(K27*100/$F$19)) -> 34.245483 | N27: =SUM(N22:N26) -> 4592290.2 | O27: =IF(N27=0,0,(N27*100/$F$19)) -> 54.925614 | Q27: =SUM(Q22:Q26) -> 7455529.8 | R27: =IF(Q27=0,0,(Q27*100/$F$19)) -> 89.171097
A29: TOTALS | F29: =F19 -> 8360926.4 | H29: =H19 -> 1864634.8 | K29: =K19+K27 -> 5566194.7 | N29: =N19+N27 -> 5763664.1
A31: GROSS OPERATING PROFIT | Q31: =Q19-Q27 -> -4833567.1 | R31: =IF(Q31=0,0,(Q31*100/$F$19)) -> -57.811383
B33: Other Income | Q33: =SCH00!A56 -> 816951.68 | R33: =IF(Q33=0,0,(Q33*100/$F$19)) -> 9.7710665
B34: less:
B35: Management Fee - Incentive | N35: =SCH00!A59 -> 0
B36: Rent Property Taxes and Insurance | N36: 0
B37: Interest Expense | N37: =SCH00!A64 -> 0
B38: Depreciation and Amortisation | N38: =SCH00!A58 -> 2647017.5
B39: Other Additions/Deductions | N39: =SCH00!A60 -> 6281885
Q40: =SUM(N35:N39) -> 8928902.5
A42: PROFIT BEFORE INCOME TAX | Q42: =Q31-Q40 -> -13762470
B44: less : Income Taxes | Q44: 0
B45: Royalty to Main Office | Q45: 0
A47: NET PROFIT (NET LOSS) | Q47: =Q42-Q44-Q45 -> -13762470 | R47: =IF(Q47=0,0,(Q47*100/$F$19)) -> -164.6046

Sheet SCH00
J1: =Cover!B2 -> Ramada Resort Khao Lak, Phang Nga | Q1: =+BS!J1 -> 6
E2: SUMMARY STATEMENT OF INCOME | P2: Schedule 00
J3: ="For the PRD of"&" "&TEXT(DATE(YR, PRD, 1), "[$-409]mmmm yyyy") -> For the PRD of June 2026 | P3: Local Currency
A5: CURRENT MONTH | J5: DESCRIPTION | L5: YEAR TO DATE | S5: THIS MONTH | U5: Y-T-D | X5: LAST MONTH
A6: Actual | C6: vs Plan | E6: vs Last Year | G6: vs BRM | L6: Actual | N6: vs Plan | P6: vs Last Year | S6: Budget This monthPlan | T6: Actual Last Year | U6: Budge YTD Plan | V6: Actual Last Year | X6: Actual | Y6: Plan | Z6: Last Year
C7: Better / (Worse) | N7: Better / (Worse)
J9: OPERATED DEPARTMENTS
J10: INCOME
A11: =+Room_SCH01!G26 -> 2893701.6 | C11: =+A11-S11 -> 2893701.6 | E11: =+A11-T11 -> 1614090.2 | G11: 20175813 | J11: Rooms | L11: =+Room_SCH01!J26 -> 83040602 | N11: =+L11-U11 -> 83040602 | P11: =+L11-V11 -> 5286513.3 | S11: =+Room_SCH01!Q26 -> 0 | T11: =+Room_SCH01!R26 -> 1279611.4 | U11: =+Room_SCH01!S26 -> 0 | V11: =+Room_SCH01!T26 -> 77754089 | X11: =+Room_SCH01!V26 -> 77754089 | Y11: =+Room_SCH01!W26 -> 0 | Z11: =+Room_SCH01!X26 -> 70530593
A12: =+'SCH05'!G24 -> 4907832.8 | C12: =+A12-S12 -> 4907832.8 | E12: =+A12-T12 -> 2461271.3 | G12: 13423812 | J12: Food & Beverage | L12: =+'SCH05'!J24 -> 26933045 | N12: =+L12-U12 -> 26933045 | P12: =+L12-V12 -> 2636572.7 | S12: =+'SCH05'!Q24 -> 0 | T12: =+'SCH05'!R24 -> 2446561.4 | U12: =+'SCH05'!S24 -> 0 | V12: =+'SCH05'!T24 -> 24296473 | X12: =+'SCH05'!V24 -> 24296473 | Y12: =+'SCH05'!W24 -> 0 | Z12: =+'SCH05'!X24 -> 24772181
A13: =+Lau_SCH04!I12+Spa_SCH06!I13+'Mini Bar_SCH02'!I14+Tel_SCH03!I14 -> 237336.54 | C13: =+A13-S13 -> 237336.54 | E13: =+A13-T13 -> 95445.7 | J13: Other Operated Departments (OOD ) | L13: =Lau_SCH04!L12+Spa_SCH06!L13+'Mini Bar_SCH02'!L14+Tel_SCH03!L14 -> 2034561.3 | N13: =+L13-U13 -> 2034561.3 | P13: =+L13-V13 -> 625508.35 | S13: =+Lau_SCH04!S12+Spa_SCH06!S13+'Mini Bar_SCH02'!S14+Tel_SCH03!S14 -> 0 | T13: =+Lau_SCH04!T12+Spa_SCH06!T13+'Mini Bar_SCH02'!T14+Tel_SCH03!T14 -> 141890.84 | U13: =Lau_SCH04!U12+Spa_SCH06!U13+'Mini Bar_SCH02'!U14+Tel_SCH03!U14 -> 0 | V13: =+Lau_SCH04!V12+Spa_SCH06!V13+'Mini Bar_SCH02'!V14+Tel_SCH03!V14 -> 1409052.9 | X13: =+Lau_SCH04!X12+Spa_SCH06!X13+'Mini Bar_SCH02'!X14+Tel_SCH03!X14 -> 1967199.7 | Y13: =+Lau_SCH04!Y12+Spa_SCH06!Y13+'Mini Bar_SCH02'!Y14+Tel_SCH03!Y14 -> 0 | Z13: =+Lau_SCH04!Z12+Spa_SCH06!Z13+'Mini Bar_SCH02'!Z14++Tel_SCH03!Z14 -> 1327434.7
A14: =+Other_SCH09!J17 -> 322055.52 | C14: =+A14-S14 -> 322055.52 | E14: =+A14-T14 -> 199216.02 | G14: 611386.81 | J14: Other Income | L14: =+Other_SCH09!M17 -> 1635266.3 | N14: =+L14-U14 -> 1635266.3 | P14: =+L14-V14 -> -188339.68 | S14: =+Other_SCH09!T17 -> 0 | T14: =+Other_SCH09!U17 -> 122839.5 | U14: =+Other_SCH09!V17 -> 0 | V14: =+Other_SCH09!W17 -> 1823605.9 | X14: =+Other_SCH09!Y17 -> 1823605.9 | Y14: =+Other_SCH09!Z17 -> 0 | Z14: =+Other_SCH09!AA17 -> 2013707.2
A15: =+Room_SCH01!G27 -> 0 | C15: =+A15-S15 -> 0 | E15: =+A15-T15 -> 0 | J15: Extraordinary items | L15: =+Room_SCH01!J27 -> 0 | N15: =+L15-U15 -> 0 | P15: =+L15-V15 -> 0 | S15: =+Room_SCH01!Q27 -> 0 | T15: =+Room_SCH01!R27 -> 0 | U15: =+Room_SCH01!S27 -> 0 | V15: =+Room_SCH01!T27 -> 0 | X15: =+Room_SCH01!V27 -> 0 | Y15: =+Room_SCH01!W27 -> 0 | Z15: =+Room_SCH01!X27 -> 0
A16: =SUM(A11:A15) -> 8360926.4 | C16: =SUM(C11:C15) -> 8360926.4 | E16: =SUM(E11:E15) -> 4370023.3 | J16: Total Income | L16: =SUM(L11:L15) -> 1.1364348e+08 | N16: =SUM(N11:N15) -> 1.1364348e+08 | P16: =SUM(P11:P15) -> 8360254.6 | S16: =SUM(S11:S15) -> 0 | T16: =SUM(T11:T15) -> 3990903.1 | U16: =SUM(U11:U15) -> 0 | V16: =SUM(V11:V15) -> 1.0528322e+08 | X16: =SUM(X11:X15) -> 1.0584137e+08 | Y16: =SUM(Y11:Y15) -> 0 | Z16: =SUM(Z11:Z15) -> 98643916
J18: COST OF SALES
A19: =+'SCH05'!G27 -> 1259305.8 | C19: =+A19-S19 -> 1259305.8 | E19: =+A19-T19 -> 652524.25 | G19: -2377556.3 | J19: Food | L19: =+'SCH05'!J27 -> 5823021 | N19: =+L19-U19 -> 5823021 | P19: =+L19-V19 -> 355455.87 | S19: =+'SCH05'!Q27 -> 0 | T19: =+'SCH05'!R27 -> 606781.59 | U19: =+'SCH05'!S27 -> 0 | V19: =+'SCH05'!T27 -> 5467565.1 | X19: =+'SCH05'!V27 -> 5467565.1 | Y19: =+'SCH05'!W27 -> 0 | Z19: =+'SCH05'!X27 -> 5512254.8
A20: =+'SCH05'!G28 -> 390456.68 | C20: =+A20-S20 -> 390456.68 | E20: =+A20-T20 -> 161648.14 | G20: -1551714.5 | J20: Beverage | L20: =+'SCH05'!J28 -> 2278435.5 | N20: =+L20-U20 -> 2278435.5 | P20: =+L20-V20 -> 278209.06 | S20: =+'SCH05'!Q28 -> 0 | T20: =+'SCH05'!R28 -> 228808.54 | U20: =+'SCH05'!S28 -> 0 | V20: =+'SCH05'!T28 -> 2000226.5 | X20: =+'SCH05'!V28 -> 2000226.5 | Y20: =+'SCH05'!W28 -> 0 | Z20: =+'SCH05'!X28 -> 2038291.4
A21: =+'SCH05'!G30+'SCH05'!G29 -> 2490.88 | C21: =+A21-S21 -> 2490.88 | E21: =+A21-T21 -> 1790.88 | G21: -1551714.5 | J21: Cigar & Cigarette | L21: =+'SCH05'!J30+'SCH05'!J29 -> 51539.28 | N21: =+L21-U21 -> 51539.28 | P21: =+L21-V21 -> -20113.27 | S21: =+'SCH05'!Q30+'SCH05'!Q29 -> 0 | T21: =+'SCH05'!R30+'SCH05'!R29 -> 700 | U21: =+'SCH05'!S30+'SCH05'!S29 -> 0 | V21: =+'SCH05'!T30+'SCH05'!T29 -> 71652.55 | X21: =+'SCH05'!V30+'SCH05'!V29 -> 71652.55 | Y21: =+'SCH05'!W30+'SCH05'!W29 -> 0 | Z21: =+'SCH05'!X30+'SCH05'!X29 -> 119122.83
A22: =+Other_SCH09!J24+Lau_SCH04!I14+Spa_SCH06!I15+'Mini Bar_SCH02'!I18+Tel_SCH03!I20 -> 212381.4 | C22: =+A22-S22 -> 212381.4 | E22: =+A22-T22 -> 125657.95 | J22: Other Operated Departments (OOD ) | L22: =+Other_SCH09!M24+Lau_SCH04!L14+Spa_SCH06!L15+'Mini Bar_SCH02'!L18+Tel_SCH03!L20 -> 1008730.8 | N22: =+L22-U22 -> 1008730.8 | P22: =+L22-V22 -> 97218.03 | S22: =+Other_SCH09!T24+Lau_SCH04!S14+Spa_SCH06!S15+'Mini Bar_SCH02'!S18+Tel_SCH03!S20 -> 0 | T22: =+Other_SCH09!U24+Lau_SCH04!T14+Spa_SCH06!T15+'Mini Bar_SCH02'!T18++Tel_SCH03!T20 -> 86723.45 | U22: =+Other_SCH09!V24+Lau_SCH04!U14+Spa_SCH06!U15+'Mini Bar_SCH02'!U18++Tel_SCH03!U20 -> 0 | V22: =+Other_SCH09!W24+Lau_SCH04!V14+Spa_SCH06!V15+'Mini Bar_SCH02'!V18++Tel_SCH03!V20 -> 911512.73 | X22: =+Other_SCH09!Y24+Lau_SCH04!X14+Spa_SCH06!X15+'Mini Bar_SCH02'!X18++Tel_SCH03!X20 -> 992672.82 | Y22: =+Other_SCH09!Z24+Lau_SCH04!Y14+Spa_SCH06!Y15+'Mini Bar_SCH02'!Y18++Tel_SCH03!Y20 -> 0 | Z22: =+Other_SCH09!AA24+Lau_SCH04!Z14+Spa_SCH06!Z15+'Mini Bar_SCH02'!Z18++Tel_SCH03!Z20 -> 1138329.9
A23: =SUM(A19:A22) -> 1864634.8 | C23: =SUM(C19:C22) -> 1864634.8 | E23: =SUM(E19:E22) -> 941621.22 | J23: Total Cost of Sales | L23: =SUM(L19:L22) -> 9161726.6 | N23: =+L23-U23 -> 9161726.6 | P23: =+L23-V23 -> 710769.69 | S23: =SUM(S19:S22) -> 0 | T23: =SUM(T19:T22) -> 923013.58 | U23: =SUM(U19:U22) -> 0 | V23: =SUM(V19:V22) -> 8450956.9 | X23: =SUM(X19:X22) -> 8532116.9 | Y23: =SUM(Y19:Y22) -> 0 | Z23: =SUM(Z19:Z22) -> 8807999
J25: PAYROLL
A26: =+Room_SCH01!G33 -> 1604568.5 | C26: =+A26-S26 -> 1604568.5 | E26: =+A26-T26 -> 845313.05 | G26: -1331611.2 | J26: Rooms | L26: =+Room_SCH01!J33 -> 8930942.2 | N26: =+L26-U26 -> 8930942.2 | P26: =+L26-V26 -> 3401653.9 | S26: =+Room_SCH01!Q33 -> 0 | T26: =+Room_SCH01!R33 -> 759255.45 | U26: =+Room_SCH01!S33 -> 0 | V26: =+Room_SCH01!T33 -> 5529288.3 | X26: =+Room_SCH01!V33 -> 5529288.3 | Y26: =+Room_SCH01!W33 -> 0 | Z26: =+Room_SCH01!X33 -> 3628145.2
A27: =+'SCH05'!G36 -> 899492.44 | C27: =+A27-S27 -> 899492.44 | E27: =+A27-T27 -> 555030.75 | G27: -2474920.3 | J27: Food & Beverage | L27: =+'SCH05'!J36 -> 4631688.3 | N27: =+L27-U27 -> 4631688.3 | P27: =+L27-V27 -> 2157872.6 | S27: =+'SCH05'!Q36 -> 0 | T27: =+'SCH05'!R36 -> 344461.69 | U27: =+'SCH05'!S36 -> 0 | V27: =+'SCH05'!T36 -> 2473815.7 | X27: =+'SCH05'!V36 -> 2473815.7 | Y27: =+'SCH05'!W36 -> 0 | Z27: =+'SCH05'!X36 -> 2485772
A28: =+Other_SCH09!J31+Lau_SCH04!I21+Spa_SCH06!I22 -> 198894.12 | C28: =+A28-S28 -> 198894.12 | E28: =+A28-T28 -> 76585.41 | J28: Other Operated Departments (OOD ) | L28: =+Other_SCH09!M31+Lau_SCH04!L21+Spa_SCH06!L22 -> 938741.12 | N28: =+L28-U28 -> 938741.12 | P28: =+L28-V28 -> 211565.37 | S28: =+Other_SCH09!T31+Lau_SCH04!S21+Spa_SCH06!S22 -> 0 | T28: =+Other_SCH09!U31+Lau_SCH04!T21+Spa_SCH06!T22 -> 122308.71 | U28: =+Other_SCH09!V31+Lau_SCH04!U21+Spa_SCH06!U22 -> 0 | V28: =+Other_SCH09!W31+Lau_SCH04!V21+Spa_SCH06!V22 -> 727175.75 | X28: =+Other_SCH09!Y31+Lau_SCH04!X21+Spa_SCH06!X22 -> 727175.75 | Y28: =+Other_SCH09!Z31+Lau_SCH04!Y21+Spa_SCH06!Y22 -> 0 | Z28: =+Other_SCH09!AA31+Lau_SCH04!Z21+Spa_SCH06!Z22 -> 491000.9
A29: =SUM(A26:A28) -> 2702955.1 | C29: =SUM(C26:C28) -> 2702955.1 | E29: =SUM(E26:E28) -> 1476929.2 | J29: Total Payroll | L29: =SUM(L26:L28) -> 14501372 | N29: =SUM(N26:N28) -> 14501372 | P29: =SUM(P26:P28) -> 5771091.9 | S29: =SUM(S26:S28) -> 0 | T29: =SUM(T26:T28) -> 1226025.8 | U29: =SUM(U26:U28) -> 0 | V29: =SUM(V26:V28) -> 8730279.8 | X29: =SUM(X26:X28) -> 8730279.8 | Y29: =SUM(Y26:Y28) -> 0 | Z29: =SUM(Z26:Z28) -> 6604918.1
J31: OTHER EXPENSES
A32: =+Room_SCH01!G63 -> 650238.08 | C32: =+A32-S32 -> 650238.08 | E32: =+A32-T32 -> 294751.29 | G32: -1272560.5 | J32: Rooms | L32: =+Room_SCH01!J63 -> 6823040.2 | N32: =+L32-U32 -> 6823040.2 | P32: =+L32-V32 -> 852316.77 | S32: =+Room_SCH01!Q63 -> 0 | T32: =+Room_SCH01!R63 -> 355486.79 | U32: =+Room_SCH01!S63 -> 0 | V32: =+Room_SCH01!T63 -> 5970723.5 | X32: =+Room_SCH01!V63 -> 5970723.5 | Y32: =+Room_SCH01!W63 -> 0 | Z32: =+Room_SCH01!X63 -> 6101740.6
A33: =+'SCH05'!G68 -> 501612.24 | C33: =+A33-S33 -> 501612.24 | E33: =+A33-T33 -> 357652.44 | G33: -1195673.2 | J33: Food & Beverage | L33: =+'SCH05'!J68 -> 2050878.5 | N33: =+L33-U33 -> 2050878.5 | P33: =+L33-V33 -> 560347.56 | S33: =+'SCH05'!Q68 -> 0 | T33: =+'SCH05'!R68 -> 143959.8 | U33: =+'SCH05'!S68 -> 0 | V33: =+'SCH05'!T68 -> 1490531 | X33: =+'SCH05'!V68 -> 1490531 | Y33: =+'SCH05'!W68 -> 0 | Z33: =+'SCH05'!X68 -> 1652793.3
A34: =+Lau_SCH04!I33+Spa_SCH06!I49+'Mini Bar_SCH02'!I33+Tel_SCH03!I34 -> 19523.58 | C34: =+A34-S34 -> 19523.58 | E34: =+A34-T34 -> 4302.71 | J34: Other Operated Departments (OOD ) | L34: =+Lau_SCH04!L33+Spa_SCH06!L49+'Mini Bar_SCH02'!L33+Tel_SCH03!L34 -> 79845.43 | N34: =+L34-U34 -> 79845.43 | P34: =+L34-V34 -> -74069.16 | S34: =+'Mini Bar_SCH02'!S35+Tel_SCH03!S34+Lau_SCH04!S33+Spa_SCH06!S49 -> 0 | T34: =+'Mini Bar_SCH02'!T35+Tel_SCH03!T34+Lau_SCH04!T33+Spa_SCH06!T49 -> 15220.87 | U34: =+'Mini Bar_SCH02'!U35+Tel_SCH03!U34+Lau_SCH04!U33+Spa_SCH06!U49 -> 0 | V34: =+'Mini Bar_SCH02'!V35+Tel_SCH03!V34+Lau_SCH04!V33+Spa_SCH06!V49 -> 153914.59 | X34: =+'Mini Bar_SCH02'!X35+Tel_SCH03!X34+Lau_SCH04!X33+Spa_SCH06!X49 -> 153897.22 | Y34: =+'Mini Bar_SCH02'!Y35+Tel_SCH03!Y34+Lau_SCH04!Y33+Spa_SCH06!Y49 -> 0 | Z34: =+'Mini Bar_SCH02'!Z35+Tel_SCH03!Z34+Lau_SCH04!Z33+Spa_SCH06!Z49 -> 80657.3
A35: =SUM(A32:A34) -> 1171373.9 | C35: =SUM(C32:C34) -> 1171373.9 | E35: =SUM(E32:E34) -> 656706.44 | J35: Total Other Expenses | L35: =SUM(L32:L34) -> 8953764.2 | N35: =SUM(N32:N34) -> 8953764.2 | P35: =SUM(P32:P34) -> 1338595.2 | S35: =SUM(S32:S34) -> 0 | T35: =SUM(T32:T34) -> 514667.46 | U35: =SUM(U32:U34) -> 0 | V35: =SUM(V32:V34) -> 7615169 | X35: =SUM(X32:X34) -> 7615151.7 | Y35: =SUM(Y32:Y34) -> 0 | Z35: =SUM(Z32:Z34) -> 7835191.2
J37: OPERATING DEPT. PROFIT
A38: =+A11+A15-A26-A32 -> 638894.98 | C38: =+A38-S38 -> 638894.98 | E38: =+A38-T38 -> 474025.85 | G38: 17571642 | J38: Rooms | L38: =+L11+L15-L26-L32 -> 67286620 | N38: =+N11-N26-N32 -> 67286620 | P38: =+P11-P26-P32 -> 1032542.6 | S38: =+S11-S26-S32 -> 0 | T38: =+T11-T26-T32 -> 164869.13 | U38: =+U11-U26-U32 -> 0 | V38: =+V11-V26-V32 -> 66254077 | X38: =+X11-X26-X32 -> 66254077 | Y38: =+Y11-Y26-Y32 -> 0 | Z38: =+Z11-Z26-Z32 -> 60800707
A39: =+A12-A19-A20-A27-A33-A21 -> 1854474.7 | C39: =+A39-S39 -> 1854474.7 | E39: =+A39-T39 -> 732624.89 | G39: 5823947.9 | J39: Food & Beverage | L39: =+L12-L19-L20-L27-L33-L21 -> 12097483 | N39: =+N12-N19-N20-N27-N33-N21 -> 12097483 | P39: =+P12-P19-P20-P27-P33-P21 -> -695199.2 | S39: =+S12-S19-S20-S27-S33-S21 -> 0 | T39: =+T12-T19-T20-T27-T33-T21 -> 1121849.8 | U39: =+U12-U19-U20-U27-U33-U21 -> 0 | V39: =+V12-V19-V20-V27-V33-V21 -> 12792682 | X39: =+X12-X19-X20-X27-X33-X21 -> 12792682 | Y39: =+Y12-Y19-Y20-Y27-Y33-Y21 -> 0 | Z39: =+Z12-Z19-Z20-Z27-Z33-Z21 -> 12963947
A40: =+A13-A22-A28-A34 -> -193462.56 | C40: =+A40-S40 -> -193462.56 | E40: =+A40-T40 -> -111100.37 | J40: Other Operated Departments (OOD ) | L40: =+L13-L22-L28-L34 -> 7243.96 | N40: =+L40-U40 -> 7243.96 | P40: =+L40-V40 -> 390794.11 | S40: =+S13-S22-S28-S34 -> 0 | T40: =+T13-T22-T28-T34 -> -82362.19 | U40: =+U13-U22-U28-U34 -> 0 | V40: =+V13-V22-V28-V34 -> -383550.15 | X40: =+X13-X22-X28-X34 -> 93453.9 | Y40: =+Y13-Y22-Y28-Y34 -> 0 | Z40: =+Z13-Z22-Z28-Z34 -> -382553.34
A41: =+A14 -> 322055.52 | C41: =+A41-S41 -> 322055.52 | E41: =+A41-T41 -> 199216.02 | G41: 611386.81 | L41: =+L14 -> 1635266.3 | N41: =+L41-U41 -> 1635266.3 | P41: =+L41-V41 -> -188339.68 | S41: =+S14 -> 0 | T41: =+T14 -> 122839.5 | U41: =+U14 -> 0 | V41: =+V14 -> 1823605.9 | X41: =+X14 -> 1823605.9 | Y41: =+Y14 -> 0 | Z41: =+Z14 -> 2013707.2
A42: =SUM(A38:A41) -> 2621962.6 | C42: =SUM(C38:C41) -> 2621962.6 | E42: =SUM(E38:E41) -> 1294766.4 | J42: Total Op. Dept. Profit | L42: =SUM(L38:L41) -> 81026613 | N42: =+L42-U42 -> 81026613 | P42: =+L42-V42 -> 539797.87 | S42: =SUM(S38:S41) -> 0 | T42: =SUM(T38:T41) -> 1327196.2 | U42: =SUM(U38:U41) -> 0 | V42: =SUM(V38:V41) -> 80486815 | X42: =SUM(X38:X41) -> 80963819 | Y42: =SUM(Y38:Y41) -> 0 | Z42: =SUM(Z38:Z41) -> 75395808
I44: Op. Dept. Profit b/f
J46: NON-OPERATED DEPTS.
A47: =+AG_SCH11!I58 -> 3122073.2 | C47: =+A47-S47 -> 3122073.2 | E47: =+A47-T47 -> 1712858.4 | G47: -1860798 | J47: Hotel Administration | L47: =+AG_SCH11!L58 -> 11867446 | N47: =+L47-U47 -> 11867446 | P47: =+L47-V47 -> 1160677.2 | S47: =+AG_SCH11!S58 -> 0 | T47: =+AG_SCH11!T58 -> 1409214.8 | U47: =+AG_SCH11!U58 -> 0 | V47: =+AG_SCH11!V58 -> 10706769 | X47: =+AG_SCH11!X58 -> 11867446 | Y47: =+AG_SCH11!Y58 -> 0 | Z47: =+AG_SCH11!Z58 -> 10706769
A48: =+HR_SCH12!I37 -> 363779.46 | C48: =+A48-S48 -> 363779.46 | E48: =+A48-T48 -> 169839.26 | G48: -453630.28 | J48: Human Resources | L48: =+HR_SCH12!L37 -> 1635471 | N48: =+L48-U48 -> 1635471 | P48: =+L48-V48 -> 426835.75 | S48: =+HR_SCH12!S37 -> 0 | T48: =+HR_SCH12!T37 -> 193940.2 | U48: =+HR_SCH12!U37 -> 0 | V48: =+HR_SCH12!V37 -> 1208635.2 | X48: =+HR_SCH12!X37 -> 1208635.2 | Y48: =+HR_SCH12!Y37 -> 0 | Z48: =+HR_SCH12!Z37 -> 933468.52
...

Sheet Room_SCH01
A2: =Cover!B2 -> Ramada Resort Khao Lak, Phang Nga
A3: Room Division | B3: Income Statement | O3: Schedule 01 | P3: =+BS!J1 -> 6 | BA3: Mapping Area
A4: =SCH00!J3 -> For the PRD of June 2026 | O4: Local Currency : Thai Baht | BA4: *Department Code | BG4: *Account Code | CB4: Dimension
BA5: Dept 1 | BB5: Dept 2 | BC5: Dept 3 | BD5: Dept 4 | BE5: Dept 5 | BG5: 1st Range | BI5: 2nd Range | BK5: 3rd Range | BM5: 4rd Range | BO5: 5rd Range | BQ5: 6rd Range | BS5: 7rd Range | BU5: 8rd Range | BW5: 9rd Range | BY5: 10th Range
A6: Current Month | I6: Description | J6: Year To Date | Q6: THIS MONTH | S6: Y-T-D | V6: LAST Y-T-D | AC6: MTD | AG6: YTD | BG6: From | BH6: To | BI6: From | BJ6: To | BK6: From | BL6: To | BM6: From | BN6: To | BO6: From | BP6: To | BQ6: From | BR6: To | BS6: From | BT6: To | BU6: From | BV6: To | BW6: From | BX6: To | BY6: From | BZ6: To | CB6: A/O | CC6: Field Name | CD6: Operator | CE6: Value
A7: vs Last Year | B7: % | C7: vs Last Month | D7: % | E7: vs Plan | F7: % | G7: Actual | H7: % | J7: Actual | K7: % | L7: vs Plan | M7: % | N7: vs Last Year | O7: % | Q7: Plan | R7: Last Year | S7: Plan | T7: Last Year | V7: Actual | W7: Plan | X7: Last Year | Z7: Actual Last Month | AA7: Plan | AC7: Plan | AD7: Last Year | AE7: Actual Last Month | AG7: Plan | AH7: Last Year
A8: Better/(worse) | L8: Better/(worse)
I9: REVENUE
A10: =+G10-R10 -> 1367474.6 | B10: =IF(G10=0,0,(A10*100/G10)) -> 100 | C10: =G10-Z10 -> 1367474.6 | D10: =IF(G10=0,0,(C10*100/G10)) -> 100 | E10: =+G10-Q10 -> 1367474.6 | F10: =IF(G10=0,0,(E10*100/G10)) -> 100 | G10: =IFERROR(_xll.AC_BU(_xll.ArrayBU(DB),_xll.ArrayDPT($BA10:$BE10),_xll.ArrayCOA($BG10:$BZ10),YR,PRD,_xll.ArrayDIM($CB10:$CE10)),0) -> 1367474.6 | H10: =G10/G$21*100 -> 43.851476 | I10: Rooms Revenue - Incentive | J10: =IFERROR(_xll.ACC_BU(_xll.ArrayBU(DB),_xll.ArrayDPT($BA10:$BE10),_xll.ArrayCOA($BG10:$BZ10),YR,PRD,_xll.ArrayDIM($CB10:$CE10)),0) -> 1367474.6 | K10: =J10/J$21*100 -> 1.6406136 | L10: =+J10-S10 -> 1367474.6 | M10: =IF(S10<>0,L10/S10*100,0) -> 0 | N10: =+J10-T10 -> 1367474.6 | O10: =IF(T10<>0,N10/T10*100,0) -> 0 | Q10: =IFERROR(_xll.BC_BU(_xll.ArrayBU(DB),_xll.ArrayDPT($BA10:$BE10),_xll.ArrayCOA($BG10:$BZ10),YR,PRD,RV,_xll.ArrayDIM($CB10:$CE10)),0) -> 0 | R10: =IFERROR(_xll.AC_BU(_xll.ArrayBU(DB),_xll.ArrayDPT($BA10:$BE10),_xll.ArrayCOA($BG10:$BZ10),YR-1,PRD,_xll.ArrayDIM($CB10:$CE10)),0) -> 0 | S10: =IFERROR(_xll.BCC_BU(_xll.ArrayBU(DB),_xll.ArrayDPT($BA10:$BE10),_xll.ArrayCOA($BG10:$BZ10),YR,PRD,RV,_xll.ArrayDIM($CB10:$CE10)),0) -> 0 | T10: =IFERROR(_xll.ACC_BU(_xll.ArrayBU(DB),_xll.ArrayDPT($BA10:$BE10),_xll.ArrayCOA($BG10:$BZ10),YR-1,PRD,_xll.ArrayDIM($CB10:$CE10)),0) -> 0 | V10: =IFERROR(_xll.ACC_BU(_xll.ArrayBU(DB),_xll.ArrayDPT($BA10:$BE10),_xll.ArrayCOA($BG10:$BZ10),YR-1,PRD,_xll.ArrayDIM($CB10:$CE10)),0) -> 0 | W10: =IFERROR(_xll.BCC_BU(_xll.ArrayBU(DB),_xll.ArrayDPT($BA10:$BE10),_xll.ArrayCOA($BG10:$BZ10),YR-1,PRD,RV,_xll.ArrayDIM($CB10:$CE10)),0) -> 0 | X10: =IFERROR(_xll.ACC_BU(_xll.ArrayBU(DB),_xll.ArrayDPT($BA10:$BE10),_xll.ArrayCOA($BG10:$BZ10),YR-1-1,PRD,_xll.ArrayDIM($CB10:$CE10)),0) -> 0 | Z10: =IFERROR(_xll.AC_BU(_xll.ArrayBU(DB),_xll.ArrayDPT($BA10:$BE10),_xll.ArrayCOA($BG10:$BZ10),YR,PRD-1,_xll.ArrayDIM($CB10:$CE10)),0) -> 0 | AA10: =IFERROR(_xll.BC_BU(_xll.ArrayBU(DB),_xll.ArrayDPT($BA10:$BE10),_xll.ArrayCOA($BG10:$BZ10),YR,PRD-1,RV,_xll.ArrayDIM($CB10:$CE10)),0) -> 0 | AC10: =Q10/Q$21*100 -> #DIV/0! | AD10: =R10/R$21*100 -> 0 | AE10: =Z10/Z$21*100 -> 0 | AG10: =S10/S$21*100 -> #DIV/0! | AH10: =T10/T$21*100 -> 0 | BG10: 414010
A11: =+G11-R11 -> -121195.4 | B11: =IF(G11=0,0,(A11*100/G11)) -> -15.528787 | C11: =G11-Z11 -> -1082007.6 | D11: =IF(G11=0,0,(C11*100/G11)) -> -138.63781 | E11: =+G11-Q11 -> 780456.34 | F11: =IF(G11=0,0,(E11*100/G11)) -> 100 | G11: =IFERROR(_xll.AC_BU(_xll.ArrayBU(DB),_xll.ArrayDPT($BA11:$BE11),_xll.ArrayCOA($BG11:$BZ11),YR,PRD,_xll.ArrayDIM($CB11:$CE11)),0) -> 780456.34 | H11: =G11/G$21*100 -> 25.027275 | I11: Rooms Revenue - Travel Agent | J11: =IFERROR(_xll.ACC_BU(_xll.ArrayBU(DB),_xll.ArrayDPT($BA11:$BE11),_xll.ArrayCOA($BG11:$BZ11),YR,PRD,_xll.ArrayDIM($CB11:$CE11)),0) -> 58539037 | K11: =J11/J$21*100 -> 70.231609 | L11: =+J11-S11 -> 58539037 | M11: =IF(S11<>0,L11/S11*100,0) -> 0 | N11: =+J11-T11 -> -2561240.9 | O11: =IF(T11<>0,N11/T11*100,0) -> -4.1918647 | Q11: =IFERROR(_xll.BC_BU(_xll.ArrayBU(DB),_xll.ArrayDPT($BA11:$BE11),_xll.ArrayCOA($BG11:$BZ11),YR,PRD,RV,_xll.ArrayDIM($CB11:$CE11)),0) -> 0 | R11: =IFERROR(_xll.AC_BU(_xll.ArrayBU(DB),_xll.ArrayDPT($BA11:$BE11),_xll.ArrayCOA($BG11:$BZ11),YR-1,PRD,_xll.ArrayDIM($CB11:$CE11)),0) -> 901651.74 | S11: =IFERROR(_xll.BCC_BU(_xll.ArrayBU(DB),_xll.ArrayDPT($BA11:$BE11),_xll.ArrayCOA($BG11:$BZ11),YR,PRD,RV,_xll.ArrayDIM($CB11:$CE11)),0) -> 0 | T11: =IFERROR(_xll.ACC_BU(_xll.ArrayBU(DB),_xll.ArrayDPT($BA11:$BE11),_xll.ArrayCOA($BG11:$BZ11),YR-1,PRD,_xll.ArrayDIM($CB11:$CE11)),0) -> 61100278 | V11: =IFERROR(_xll.ACC_BU(_xll.ArrayBU(DB),_xll.ArrayDPT($BA11:$BE11),_xll.ArrayCOA($BG11:$BZ11),YR-1,PRD,_xll.ArrayDIM($CB11:$CE11)),0) -> 61100278 | W11: =IFERROR(_xll.BCC_BU(_xll.ArrayBU(DB),_xll.ArrayDPT($BA11:$BE11),_xll.ArrayCOA($BG11:$BZ11),YR-1,PRD,RV,_xll.ArrayDIM($CB11:$CE11)),0) -> 0 | X11: =IFERROR(_xll.ACC_BU(_xll.ArrayBU(DB),_xll.ArrayDPT($BA11:$BE11),_xll.ArrayCOA($BG11:$BZ11),YR-1-1,PRD,_xll.ArrayDIM($CB11:$CE11)),0) -> 65023901 | Z11: =IFERROR(_xll.AC_BU(_xll.ArrayBU(DB),_xll.ArrayDPT($BA11:$BE11),_xll.ArrayCOA($BG11:$BZ11),YR,PRD-1,_xll.ArrayDIM($CB11:$CE11)),0) -> 1862463.9 | AA11: =IFERROR(_xll.BC_BU(_xll.ArrayBU(DB),_xll.ArrayDPT($BA11:$BE11),_xll.ArrayCOA($BG11:$BZ11),YR,PRD-1,RV,_xll.ArrayDIM($CB11:$CE11)),0) -> 0 | AC11: =Q11/Q$21*100 -> #DIV/0! | AD11: =R11/R$21*100 -> 70.301911 | AE11: =Z11/Z$21*100 -> 64.818164 | AG11: =S11/S$21*100 -> #DIV/0! | AH11: =T11/T$21*100 -> 78.494214 | BG11: 414020
A12: =+G12-R12 -> 337526.12 | B12: =IF(G12=0,0,(A12*100/G12)) -> 53.08748 | C12: =G12-Z12 -> -277076.78 | D12: =IF(G12=0,0,(C12*100/G12)) -> -43.579762 | E12: =+G12-Q12 -> 635792.32 | F12: =IF(G12=0,0,(E12*100/G12)) -> 100 | G12: =IFERROR(_xll.AC_BU(_xll.ArrayBU(DB),_xll.ArrayDPT($BA12:$BE12),_xll.ArrayCOA($BG12:$BZ12),YR,PRD,_xll.ArrayDIM($CB12:$CE12)),0) -> 635792.32 | H12: =G12/G$21*100 -> 20.388263 | I12: Rooms Revenue - Web Site (OTA) | J12: =IFERROR(_xll.ACC_BU(_xll.ArrayBU(DB),_xll.ArrayDPT($BA12:$BE12),_xll.ArrayCOA($BG12:$BZ12),YR,PRD,_xll.ArrayDIM($CB12:$CE12)),0) -> 22047965 | K12: =J12/J$21*100 -> 26.45182 | L12: =+J12-S12 -> 22047965 | M12: =IF(S12<>0,L12/S12*100,0) -> 0 | N12: =+J12-T12 -> 7109145.5 | O12: =IF(T12<>0,N12/T12*100,0) -> 47.588402 | Q12: =IFERROR(_xll.BC_BU(_xll.ArrayBU(DB),_xll.ArrayDPT($BA12:$BE12),_xll.ArrayCOA($BG12:$BZ12),YR,PRD,RV,_xll.ArrayDIM($CB12:$CE12)),0) -> 0 | R12: =IFERROR(_xll.AC_BU(_xll.ArrayBU(DB),_xll.ArrayDPT($BA12:$BE12),_xll.ArrayCOA($BG12:$BZ12),YR-1,PRD,_xll.ArrayDIM($CB12:$CE12)),0) -> 298266.2 | S12: =IFERROR(_xll.BCC_BU(_xll.ArrayBU(DB),_xll.ArrayDPT($BA12:$BE12),_xll.ArrayCOA($BG12:$BZ12),YR,PRD,RV,_xll.ArrayDIM($CB12:$CE12)),0) -> 0 | T12: =IFERROR(_xll.ACC_BU(_xll.ArrayBU(DB),_xll.ArrayDPT($BA12:$BE12),_xll.ArrayCOA($BG12:$BZ12),YR-1,PRD,_xll.ArrayDIM($CB12:$CE12)),0) -> 14938820 | V12: =IFERROR(_xll.ACC_BU(_xll.ArrayBU(DB),_xll.ArrayDPT($BA12:$BE12),_xll.ArrayCOA($BG12:$BZ12),YR-1,PRD,_xll.ArrayDIM($CB12:$CE12)),0) -> 14938820 | W12: =IFERROR(_xll.BCC_BU(_xll.ArrayBU(DB),_xll.ArrayDPT($BA12:$BE12),_xll.ArrayCOA($BG12:$BZ12),YR-1,PRD,RV,_xll.ArrayDIM($CB12:$CE12)),0) -> 0 | X12: =IFERROR(_xll.ACC_BU(_xll.ArrayBU(DB),_xll.ArrayDPT($BA12:$BE12),_xll.ArrayCOA($BG12:$BZ12),YR-1-1,PRD,_xll.ArrayDIM($CB12:$CE12)),0) -> 3956920.1 | Z12: =IFERROR(_xll.AC_BU(_xll.ArrayBU(DB),_xll.ArrayDPT($BA12:$BE12),_xll.ArrayCOA($BG12:$BZ12),YR,PRD-1,_xll.ArrayDIM($CB12:$CE12)),0) -> 912869.1 | AA12: =IFERROR(_xll.BC_BU(_xll.ArrayBU(DB),_xll.ArrayDPT($BA12:$BE12),_xll.ArrayCOA($BG12:$BZ12),YR,PRD-1,RV,_xll.ArrayDIM($CB12:$CE12)),0) -> 0 | AC12: =Q12/Q$21*100 -> #DIV/0! | AD12: =R12/R$21*100 -> 23.255857 | AE12: =Z12/Z$21*100 -> 31.770011 | AG12: =S12/S$21*100 -> #DIV/0! | AH12: =T12/T$21*100 -> 19.191581 | BG12: 414030
A13: =+G13-R13 -> 0 | B13: =IF(G13=0,0,(A13*100/G13)) -> 0 | C13: =G13-Z13 -> 0 | D13: =IF(G13=0,0,(C13*100/G13)) -> 0 | E13: =+G13-Q13 -> 0 | F13: =IF(G13=0,0,(E13*100/G13)) -> 0 | G13: =IFERROR(_xll.AC_BU(_xll.ArrayBU(DB),_xll.ArrayDPT($BA13:$BE13),_xll.ArrayCOA($BG13:$BZ13),YR,PRD,_xll.ArrayDIM($CB13:$CE13)),0) -> 0 | H13: =G13/G$21*100 -> 0 | I13: Rooms Revenue - Airline/Hotelier | J13: =IFERROR(_xll.ACC_BU(_xll.ArrayBU(DB),_xll.ArrayDPT($BA13:$BE13),_xll.ArrayCOA($BG13:$BZ13),YR,PRD,_xll.ArrayDIM($CB13:$CE13)),0) -> 0 | K13: =J13/J$21*100 -> 0 | L13: =+J13-S13 -> 0 | M13: =IF(S13<>0,L13/S13*100,0) -> 0 | N13: =+J13-T13 -> 0 | O13: =IF(T13<>0,N13/T13*100,0) -> 0 | Q13: =IFERROR(_xll.BC_BU(_xll.ArrayBU(DB),_xll.ArrayDPT($BA13:$BE13),_xll.ArrayCOA($BG13:$BZ13),YR,PRD,RV,_xll.ArrayDIM($CB13:$CE13)),0) -> 0 | R13: =IFERROR(_xll.AC_BU(_xll.ArrayBU(DB),_xll.ArrayDPT($BA13:$BE13),_xll.ArrayCOA($BG13:$BZ13),YR-1,PRD,_xll.ArrayDIM($CB13:$CE13)),0) -> 0 | S13: =IFERROR(_xll.BCC_BU(_xll.ArrayBU(DB),_xll.ArrayDPT($BA13:$BE13),_xll.ArrayCOA($BG13:$BZ13),YR,PRD,RV,_xll.ArrayDIM($CB13:$CE13)),0) -> 0 | T13: =IFERROR(_xll.ACC_BU(_xll.ArrayBU(DB),_xll.ArrayDPT($BA13:$BE13),_xll.ArrayCOA($BG13:$BZ13),YR-1,PRD,_xll.ArrayDIM($CB13:$CE13)),0) -> 0 | V13: =IFERROR(_xll.ACC_BU(_xll.ArrayBU(DB),_xll.ArrayDPT($BA13:$BE13),_xll.ArrayCOA($BG13:$BZ13),YR-1,PRD,_xll.ArrayDIM($CB13:$CE13)),0) -> 0 | W13: =IFERROR(_xll.BCC_BU(_xll.ArrayBU(DB),_xll.ArrayDPT($BA13:$BE13),_xll.ArrayCOA($BG13:$BZ13),YR-1,PRD,RV,_xll.ArrayDIM($CB13:$CE13)),0) -> 0 | X13: =IFERROR(_xll.ACC_BU(_xll.ArrayBU(DB),_xll.ArrayDPT($BA13:$BE13),_xll.ArrayCOA($BG13:$BZ13),YR-1-1,PRD,_xll.ArrayDIM($CB13:$CE13)),0) -> 0 | Z13: =IFERROR(_xll.AC_BU(_xll.ArrayBU(DB),_xll.ArrayDPT($BA13:$BE13),_xll.ArrayCOA($BG13:$BZ13),YR,PRD-1,_xll.ArrayDIM($CB13:$CE13)),0) -> 0 | AA13: =IFERROR(_xll.BC_BU(_xll.ArrayBU(DB),_xll.ArrayDPT($BA13:$BE13),_xll.ArrayCOA($BG13:$BZ13),YR,PRD-1,RV,_xll.ArrayDIM($CB13:$CE13)),0) -> 0 | AC13: =Q13/Q$21*100 -> #DIV/0! | AD13: =R13/R$21*100 -> 0 | AE13: =Z13/Z$21*100 -> 0 | AG13: =S13/S$21*100 -> #DIV/0! | AH13: =T13/T$21*100 -> 0 | BG13: 414040
A14: =+G14-R14 -> 0 | B14: =IF(G14=0,0,(A14*100/G14)) -> 0 | C14: =G14-Z14 -> 0 | D14: =IF(G14=0,0,(C14*100/G14)) -> 0 | E14: =+G14-Q14 -> 0 | F14: =IF(G14=0,0,(E14*100/G14)) -> 0 | G14: =IFERROR(_xll.AC_BU(_xll.ArrayBU(DB),_xll.ArrayDPT($BA14:$BE14),_xll.ArrayCOA($BG14:$BZ14),YR,PRD,_xll.ArrayDIM($CB14:$CE14)),0) -> 0 | H14: =G14/G$21*100 -> 0 | I14: Rooms Revenue - Direct Booking | J14: =IFERROR(_xll.ACC_BU(_xll.ArrayBU(DB),_xll.ArrayDPT($BA14:$BE14),_xll.ArrayCOA($BG14:$BZ14),YR,PRD,_xll.ArrayDIM($CB14:$CE14)),0) -> 0 | K14: =J14/J$21*100 -> 0 | L14: =+J14-S14 -> 0 | M14: =IF(S14<>0,L14/S14*100,0) -> 0 | N14: =+J14-T14 -> 0 | O14: =IF(T14<>0,N14/T14*100,0) -> 0 | Q14: =IFERROR(_xll.BC_BU(_xll.ArrayBU(DB),_xll.ArrayDPT($BA14:$BE14),_xll.ArrayCOA($BG14:$BZ14),YR,PRD,RV,_xll.ArrayDIM($CB14:$CE14)),0) -> 0 | R14: =IFERROR(_xll.AC_BU(_xll.ArrayBU(DB),_xll.ArrayDPT($BA14:$BE14),_xll.ArrayCOA($BG14:$BZ14),YR-1,PRD,_xll.ArrayDIM($CB14:$CE14)),0) -> 0 | S14: =IFERROR(_xll.BCC_BU(_xll.ArrayBU(DB),_xll.ArrayDPT($BA14:$BE14),_xll.ArrayCOA($BG14:$BZ14),YR,PRD,RV,_xll.ArrayDIM($CB14:$CE14)),0) -> 0 | T14: =IFERROR(_xll.ACC_BU(_xll.ArrayBU(DB),_xll.ArrayDPT($BA14:$BE14),_xll.ArrayCOA($BG14:$BZ14),YR-1,PRD,_xll.ArrayDIM($CB14:$CE14)),0) -> 0 | V14: =IFERROR(_xll.ACC_BU(_xll.ArrayBU(DB),_xll.ArrayDPT($BA14:$BE14),_xll.ArrayCOA($BG14:$BZ14),YR-1,PRD,_xll.ArrayDIM($CB14:$CE14)),0) -> 0 | W14: =IFERROR(_xll.BCC_BU(_xll.ArrayBU(DB),_xll.ArrayDPT($BA14:$BE14),_xll.ArrayCOA($BG14:$BZ14),YR-1,PRD,RV,_xll.ArrayDIM($CB14:$CE14)),0) -> 0 | X14: =IFERROR(_xll.ACC_BU(_xll.ArrayBU(DB),_xll.ArrayDPT($BA14:$BE14),_xll.ArrayCOA($BG14:$BZ14),YR-1-1,PRD,_xll.ArrayDIM($CB14:$CE14)),0) -> 359360.96 | Z14: =IFERROR(_xll.AC_BU(_xll.ArrayBU(DB),_xll.ArrayDPT($BA14:$BE14),_xll.ArrayCOA($BG14:$BZ14),YR,PRD-1,_xll.ArrayDIM($CB14:$CE14)),0) -> 0 | AA14: =IFERROR(_xll.BC_BU(_xll.ArrayBU(DB),_xll.ArrayDPT($BA14:$BE14),_xll.ArrayCOA($BG14:$BZ14),YR,PRD-1,RV,_xll.ArrayDIM($CB14:$CE14)),0) -> 0 | AC14: =Q14/Q$21*100 -> #DIV/0! | AD14: =R14/R$21*100 -> 0 | AE14: =Z14/Z$21*100 -> 0 | AG14: =S14/S$21*100 -> #DIV/0! | AH14: =T14/T$21*100 -> 0 | BG14: 414050
A15: =+G15-R15 -> 0 | B15: =IF(G15=0,0,(A15*100/G15)) -> 0 | C15: =G15-Z15 -> 0 | D15: =IF(G15=0,0,(C15*100/G15)) -> 0 | E15: =+G15-Q15 -> 0 | F15: =IF(G15=0,0,(E15*100/G15)) -> 0 | G15: =IFERROR(_xll.AC_BU(_xll.ArrayBU(DB),_xll.ArrayDPT($BA15:$BE15),_xll.ArrayCOA($BG15:$BZ15),YR,PRD,_xll.ArrayDIM($CB15:$CE15)),0) -> 0 | H15: =G15/G$21*100 -> 0 | I15: Rooms Revenue - Walk In | J15: =IFERROR(_xll.ACC_BU(_xll.ArrayBU(DB),_xll.ArrayDPT($BA15:$BE15),_xll.ArrayCOA($BG15:$BZ15),YR,PRD,_xll.ArrayDIM($CB15:$CE15)),0) -> 0 | K15: =J15/J$21*100 -> 0 | L15: =+J15-S15 -> 0 | M15: =IF(S15<>0,L15/S15*100,0) -> 0 | N15: =+J15-T15 -> 0 | O15: =IF(T15<>0,N15/T15*100,0) -> 0 | Q15: =IFERROR(_xll.BC_BU(_xll.ArrayBU(DB),_xll.ArrayDPT($BA15:$BE15),_xll.ArrayCOA($BG15:$BZ15),YR,PRD,RV,_xll.ArrayDIM($CB15:$CE15)),0) -> 0 | R15: =IFERROR(_xll.AC_BU(_xll.ArrayBU(DB),_xll.ArrayDPT($BA15:$BE15),_xll.ArrayCOA($BG15:$BZ15),YR-1,PRD,_xll.ArrayDIM($CB15:$CE15)),0) -> 0 | S15: =IFERROR(_xll.BCC_BU(_xll.ArrayBU(DB),_xll.ArrayDPT($BA15:$BE15),_xll.ArrayCOA($BG15:$BZ15),YR,PRD,RV,_xll.ArrayDIM($CB15:$CE15)),0) -> 0 | T15: =IFERROR(_xll.ACC_BU(_xll.ArrayBU(DB),_xll.ArrayDPT($BA15:$BE15),_xll.ArrayCOA($BG15:$BZ15),YR-1,PRD,_xll.ArrayDIM($CB15:$CE15)),0) -> 0 | V15: =IFERROR(_xll.ACC_BU(_xll.ArrayBU(DB),_xll.ArrayDPT($BA15:$BE15),_xll.ArrayCOA($BG15:$BZ15),YR-1,PRD,_xll.ArrayDIM($CB15:$CE15)),0) -> 0 | W15: =IFERROR(_xll.BCC_BU(_xll.ArrayBU(DB),_xll.ArrayDPT($BA15:$BE15),_xll.ArrayCOA($BG15:$BZ15),YR-1,PRD,RV,_xll.ArrayDIM($CB15:$CE15)),0) -> 0 | X15: =IFERROR(_xll.ACC_BU(_xll.ArrayBU(DB),_xll.ArrayDPT($BA15:$BE15),_xll.ArrayCOA($BG15:$BZ15),YR-1-1,PRD,_xll.ArrayDIM($CB15:$CE15)),0) -> 0 | Z15: =IFERROR(_xll.AC_BU(_xll.ArrayBU(DB),_xll.ArrayDPT($BA15:$BE15),_xll.ArrayCOA($BG15:$BZ15),YR,PRD-1,_xll.ArrayDIM($CB15:$CE15)),0) -> 0 | AA15: =IFERROR(_xll.BC_BU(_xll.ArrayBU(DB),_xll.ArrayDPT($BA15:$BE15),_xll.ArrayCOA($BG15:$BZ15),YR,PRD-1,RV,_xll.ArrayDIM($CB15:$CE15)),0) -> 0 | AC15: =Q15/Q$21*100 -> #DIV/0! | AD15: =R15/R$21*100 -> 0 | AE15: =Z15/Z$21*100 -> 0 | AG15: =S15/S$21*100 -> #DIV/0! | AH15: =T15/T$21*100 -> 0 | BG15: 414060
A16: =+G16-R16 -> 0 | B16: =IF(G16=0,0,(A16*100/G16)) -> 0 | C16: =G16-Z16 -> 0 | D16: =IF(G16=0,0,(C16*100/G16)) -> 0 | E16: =+G16-Q16 -> 0 | F16: =IF(G16=0,0,(E16*100/G16)) -> 0 | G16: =IFERROR(_xll.AC_BU(_xll.ArrayBU(DB),_xll.ArrayDPT($BA16:$BE16),_xll.ArrayCOA($BG16:$BZ16),YR,PRD,_xll.ArrayDIM($CB16:$CE16)),0) -> 0 | H16: =G16/G$21*100 -> 0 | I16: Rooms Revenue - Website RKL | J16: =IFERROR(_xll.ACC_BU(_xll.ArrayBU(DB),_xll.ArrayDPT($BA16:$BE16),_xll.ArrayCOA($BG16:$BZ16),YR,PRD,_xll.ArrayDIM($CB16:$CE16)),0) -> 0 | K16: =J16/J$21*100 -> 0 | L16: =+J16-S16 -> 0 | M16: =IF(S16<>0,L16/S16*100,0) -> 0 | N16: =+J16-T16 -> 0 | O16: =IF(T16<>0,N16/T16*100,0) -> 0 | Q16: =IFERROR(_xll.BC_BU(_xll.ArrayBU(DB),_xll.ArrayDPT($BA16:$BE16),_xll.ArrayCOA($BG16:$BZ16),YR,PRD,RV,_xll.ArrayDIM($CB16:$CE16)),0) -> 0 | R16: =IFERROR(_xll.AC_BU(_xll.ArrayBU(DB),_xll.ArrayDPT($BA16:$BE16),_xll.ArrayCOA($BG16:$BZ16),YR-1,PRD,_xll.ArrayDIM($CB16:$CE16)),0) -> 0 | S16: =IFERROR(_xll.BCC_BU(_xll.ArrayBU(DB),_xll.ArrayDPT($BA16:$BE16),_xll.ArrayCOA($BG16:$BZ16),YR,PRD,RV,_xll.ArrayDIM($CB16:$CE16)),0) -> 0 | T16: =IFERROR(_xll.ACC_BU(_xll.ArrayBU(DB),_xll.ArrayDPT($BA16:$BE16),_xll.ArrayCOA($BG16:$BZ16),YR-1,PRD,_xll.ArrayDIM($CB16:$CE16)),0) -> 0 | V16: =IFERROR(_xll.ACC_BU(_xll.ArrayBU(DB),_xll.ArrayDPT($BA16:$BE16),_xll.ArrayCOA($BG16:$BZ16),YR-1,PRD,_xll.ArrayDIM($CB16:$CE16)),0) -> 0 | W16: =IFERROR(_xll.BCC_BU(_xll.ArrayBU(DB),_xll.ArrayDPT($BA16:$BE16),_xll.ArrayCOA($BG16:$BZ16),YR-1,PRD,RV,_xll.ArrayDIM($CB16:$CE16)),0) -> 0 | X16: =IFERROR(_xll.ACC_BU(_xll.ArrayBU(DB),_xll.ArrayDPT($BA16:$BE16),_xll.ArrayCOA($BG16:$BZ16),YR-1-1,PRD,_xll.ArrayDIM($CB16:$CE16)),0) -> 212003.28 | Z16: =IFERROR(_xll.AC_BU(_xll.ArrayBU(DB),_xll.ArrayDPT($BA16:$BE16),_xll.ArrayCOA($BG16:$BZ16),YR,PRD-1,_xll.ArrayDIM($CB16:$CE16)),0) -> 0 | AA16: =IFERROR(_xll.BC_BU(_xll.ArrayBU(DB),_xll.ArrayDPT($BA16:$BE16),_xll.ArrayCOA($BG16:$BZ16),YR,PRD-1,RV,_xll.ArrayDIM($CB16:$CE16)),0) -> 0 | AC16: =Q16/Q$21*100 -> #DIV/0! | AD16: =R16/R$21*100 -> 0 | AE16: =Z16/Z$21*100 -> 0 | AG16: =S16/S$21*100 -> #DIV/0! | AH16: =T16/T$21*100 -> 0 | BG16: 414070
A17: =+G17-R17 -> 0 | B17: =IF(G17=0,0,(A17*100/G17)) -> 0 | C17: =G17-Z17 -> 0 | D17: =IF(G17=0,0,(C17*100/G17)) -> 0 | E17: =+G17-Q17 -> 0 | F17: =IF(G17=0,0,(E17*100/G17)) -> 0 | G17: =IFERROR(_xll.AC_BU(_xll.ArrayBU(DB),_xll.ArrayDPT($BA17:$BE17),_xll.ArrayCOA($BG17:$BZ17),YR,PRD,_xll.ArrayDIM($CB17:$CE17)),0) -> 0 | H17: =G17/G$21*100 -> 0 | I17: Rooms Revenue - Special Package | J17: =IFERROR(_xll.ACC_BU(_xll.ArrayBU(DB),_xll.ArrayDPT($BA17:$BE17),_xll.ArrayCOA($BG17:$BZ17),YR,PRD,_xll.ArrayDIM($CB17:$CE17)),0) -> 0 | K17: =J17/J$21*100 -> 0 | L17: =+J17-S17 -> 0 | M17: =IF(S17<>0,L17/S17*100,0) -> 0 | N17: =+J17-T17 -> 0 | O17: =IF(T17<>0,N17/T17*100,0) -> 0 | Q17: =IFERROR(_xll.BC_BU(_xll.ArrayBU(DB),_xll.ArrayDPT($BA17:$BE17),_xll.ArrayCOA($BG17:$BZ17),YR,PRD,RV,_xll.ArrayDIM($CB17:$CE17)),0) -> 0 | R17: =IFERROR(_xll.AC_BU(_xll.ArrayBU(DB),_xll.ArrayDPT($BA17:$BE17),_xll.ArrayCOA($BG17:$BZ17),YR-1,PRD,_xll.ArrayDIM($CB17:$CE17)),0) -> 0 | S17: =IFERROR(_xll.BCC_BU(_xll.ArrayBU(DB),_xll.ArrayDPT($BA17:$BE17),_xll.ArrayCOA($BG17:$BZ17),YR,PRD,RV,_xll.ArrayDIM($CB17:$CE17)),0) -> 0 | T17: =IFERROR(_xll.ACC_BU(_xll.ArrayBU(DB),_xll.ArrayDPT($BA17:$BE17),_xll.ArrayCOA($BG17:$BZ17),YR-1,PRD,_xll.ArrayDIM($CB17:$CE17)),0) -> 0 | V17: =IFERROR(_xll.ACC_BU(_xll.ArrayBU(DB),_xll.ArrayDPT($BA17:$BE17),_xll.ArrayCOA($BG17:$BZ17),YR-1,PRD,_xll.ArrayDIM($CB17:$CE17)),0) -> 0 | W17: =IFERROR(_xll.BCC_BU(_xll.ArrayBU(DB),_xll.ArrayDPT($BA17:$BE17),_xll.ArrayCOA($BG17:$BZ17),YR-1,PRD,RV,_xll.ArrayDIM($CB17:$CE17)),0) -> 0 | X17: =IFERROR(_xll.ACC_BU(_xll.ArrayBU(DB),_xll.ArrayDPT($BA17:$BE17),_xll.ArrayCOA($BG17:$BZ17),YR-1-1,PRD,_xll.ArrayDIM($CB17:$CE17)),0) -> 0 | Z17: =IFERROR(_xll.AC_BU(_xll.ArrayBU(DB),_xll.ArrayDPT($BA17:$BE17),_xll.ArrayCOA($BG17:$BZ17),YR,PRD-1,_xll.ArrayDIM($CB17:$CE17)),0) -> 0 | AA17: =IFERROR(_xll.BC_BU(_xll.ArrayBU(DB),_xll.ArrayDPT($BA17:$BE17),_xll.ArrayCOA($BG17:$BZ17),YR,PRD-1,RV,_xll.ArrayDIM($CB17:$CE17)),0) -> 0 | AC17: =Q17/Q$21*100 -> #DIV/0! | AD17: =R17/R$21*100 -> 0 | AE17: =Z17/Z$21*100 -> 0 | AG17: =S17/S$21*100 -> #DIV/0! | AH17: =T17/T$21*100 -> 0 | BG17: 414080
