Workbook
Name _Fill: #REF!
Name _Fill: #REF!
Name _Key1: '[1]Land (2)'!#REF!
Name _Key1: '[1]Land (2)'!#REF!
Name _Key2: #REF!
Name _Key2: #REF!
Name _Key3: #REF!
Name _Key3: #REF!
Name _Order1: 255
Name _Order2: 255
Name _Sort: '[1]Land (2)'!#REF!
Name _Sort: '[1]Land (2)'!#REF!
Name APR: '[2]Carmen Parameter'!$J$5
Name APR: 'Carmen Parameter'!$J$5
Name AS2DocOpenMode: "AS2DocumentEdit"
Name AS2NamedRange: 4
Name AUG: 'Carmen Parameter'!$J$9
Name DB: Intro!$H$21
Name DD: Intro!$H$18
Name DEC: 'Carmen Parameter'!$J$13
Name DME_BeforeCloseCompleted: "False"
Name DME_Dirty: "False"
Name DME_LocalFile: "True"
Name FEB: '[2]Carmen Parameter'!$J$3
Name FEB: 'Carmen Parameter'!$J$3
Name fr: {"Summary_Green",#N/A,FALSE,"YTD Owned";"Summary_White",#N/A,FALSE,"YTD Owned"}
Name fr: {"Summary_Green",#N/A,FALSE,"YTD Owned";"Summary_White",#N/A,FALSE,"YTD Owned"}
Name HName: Intro!$B$16
Name JAN: '[2]Carmen Parameter'!$J$2
Name JAN: 'Carmen Parameter'!$J$2
Name JUL: 'Carmen Parameter'!$J$8
Name JUN: '[2]Carmen Parameter'!$J$7
Name JUN: 'Carmen Parameter'!$J$7
Name MAR: '[2]Carmen Parameter'!$J$4
Name MAR: 'Carmen Parameter'!$J$4
Name MAY: '[2]Carmen Parameter'!$J$6
Name MAY: 'Carmen Parameter'!$J$6
Name NOV: 'Carmen Parameter'!$J$12
Name OCT: 'Carmen Parameter'!$J$11
Name PRD: Intro!$H$19
Name RV: Intro!$H$22
Name SEP: 'Carmen Parameter'!$J$10
Name ss: {"CF SUMMARY",#N/A,FALSE,"Cash Flow"}
Name ss: {"CF SUMMARY",#N/A,FALSE,"Cash Flow"}
Name TextRefCopyRangeCount: 14
Name wrn.BSDA_Report.: {"Summary_Green",#N/A,FALSE,"YTD Owned";"Summary_White",#N/A,FALSE,"YTD Owned"}
Name wrn.BSDA_Report.: {"Summary_Green",#N/A,FALSE,"YTD Owned";"Summary_White",#N/A,FALSE,"YTD Owned"}
Name wrn.Summary.: {"CF SUMMARY",#N/A,FALSE,"Cash Flow"}
Name wrn.Summary.: {"CF SUMMARY",#N/A,FALSE,"Cash Flow"}
Name YR: Intro!$H$20

Sheet MyConnect
A8: WebService : | B8: http://localhost/carmenservice/FinanceService.svc

Sheet Intro
B7: CONFIDENTAL
B9: Distribution | D9: [ ] | J9: [ ]
D10: [ ] | J10: [ ]
D11: [ ] | J11: [ ]
D12: [ ] | J12: [ ]
B15: =DB -> homm
B16: Example
B17: Profit & ( Loss ) Statement | N17: 2025
G18: Day | N18: 03
G19: Period | H19: 1 | N19: =DD -> 0
G20: Year | H20: 2026 | N20: =DB -> homm
G21: Database | H21: homm | N21: =RV -> 0
G22: Budget | H22: 0 | N22: =HName -> Example
B24: Conductions
C26: Balance Sheet
C27: Balance Sheet - Supporting
C28: Profit & ( Loss ) Statement
D29: Profit & Loss Summary
D30: Room Department
D31: Food & Beverage Summary
D32: Other Operated Department
D33: Administrative & General
D34: Sales & Marketing
D35: Summary Of Payroll And Employee Relations
D36: Property Operation, Main, Energy Cost

Sheet BS
A2: HOMM SUKHUMVIT34 BANGKOK | J2: Period | K2: =PRD -> 1
A3: BALANCE SHEET
H4: EXHIBIT - A | AA4: Mapping Area
AA5: *Department Code | AG5: *Account Code | BB5: Dimension
A6: REPORT DESCRIPTION | C6: AT THE END OF | E6: AT THE BEGINNING | G6: INCREASE | I6: % | AA6: Dept 1 | AB6: Dept 2 | AC6: Dept 3 | AD6: Dept 4 | AE6: Dept 5 | AG6: 1st Range | AI6: 2nd Range | AK6: 3rd Range | AM6: 4rd Range | AO6: 5rd Range | AQ6: 6rd Range | AS6: 7rd Range | AU6: 8rd Range | AW6: 9rd Range | AY6: 10th Range
C7: THIS MONTH | E7: OF FISCAL PERIOD | G7: (DECREASE) | AG7: From | AH7: To | AI7: From | AJ7: To | AK7: From | AL7: To | AM7: From | AN7: To | AO7: From | AP7: To | AQ7: From | AR7: To | AS7: From | AT7: To | AU7: From | AV7: To | AW7: From | AX7: To | AY7: From | AZ7: To | BB7: A/O | BC7: Field Name | BD7: Operator | BE7: Value
A8: ASSETS
A9: CURRENT ASSETS
A10: CASH ON HAND-HOUSE FUND
B11: Cash House Fund ( SCHEDULE A-1A ) | C11: ='BS-Support'!C18 -> -50351.07 | E11: ='BS-Support'!E18 -> -50351.07 | G11: =C11-E11 -> 0 | I11: =IF(G11=0,0,(G11*100/$G$13)) -> 0
B12: Cash At Bank ( SCHEDULE A-1B ) | C12: ='BS-Support'!C30 -> -3.09147e+08 | E12: ='BS-Support'!E30 -> -3.0293885e+08 | G12: =C12-E12 -> -6208145.9 | I12: =IF(G12=0,0,(G12*100/$G$13)) -> 100
B13: TOTAL CASH | C13: =SUM(C10:C12) -> -3.0919735e+08 | E13: =SUM(E10:E12) -> -3.029892e+08 | G13: =C13-E13 -> -6208145.9 | I13: =IF(G13=0,0,(G13*100/$G$13)) -> 100
A14: RECEIVABLES
B15: Acct. Receivable - Trade ( SCHEDULE A-2A ) | C15: ='BS-Support'!C40 -> -17038581 | E15: ='BS-Support'!E40 -> -19824339 | G15: =C15-E15 -> 2785758.2 | I15: =IF(G15=0,0,(G15*100/$G$20)) -> 24.428933
B16: Less:Allowance for Doubtful Accounts | C16: ='BS-Support'!C42 -> 0 | E16: ='BS-Support'!E42 -> 0 | G16: =C16-E16 -> 0 | I16: =IF(G16=0,0,(G16*100/$G$20)) -> 0
B17: Net Acct. Receivable - Trade | C17: =SUM(C15:C16) -> -17038581 | E17: =SUM(E15:E16) -> -19824339 | G17: =C17-E17 -> 2785758.2 | I17: =IF(G17=0,0,(G17*100/$G$20)) -> 24.428933
B18: Loans To Subsidiaries And Associated | C18: ='BS-Support'!C43 -> 0 | E18: ='BS-Support'!E43 -> 0 | G18: =C18-E18 -> 0 | I18: =IF(G18=0,0,(G18*100/$G$20)) -> 0
B19: Other Receivable ( SCHEDULE A-2B ) | C19: ='BS-Support'!C62 -> 3.6635173e+08 | E19: ='BS-Support'!E62 -> 3.5773397e+08 | G19: =C19-E19 -> 8617761.4 | I19: =IF(G19=0,0,(G19*100/$G$20)) -> 75.571067
B20: TOTAL RECEIVABLES | C20: =SUM(C17:C19) -> 3.4931315e+08 | E20: =SUM(E17:E19) -> 3.3790963e+08 | G20: =C20-E20 -> 11403520 | I20: =IF(G20=0,0,(G20*100/$G$20)) -> 100
A21: INVENTORIES
B22: Saleable Merchandise ( SCHEDULE A-3A ) | C22: ='BS-Support'!C84 -> 0 | E22: ='BS-Support'!E84 -> 0 | G22: =C22-E22 -> 0 | I22: =IF(G22=0,0,(G22*100/$G$25)) -> 0
B23: Operating Supplies ( SCHEDULE A-3B ) | C23: ='BS-Support'!C96 -> 5787.85 | E23: ='BS-Support'!E96 -> 5787.85 | G23: =C23-E23 -> 0 | I23: =IF(G23=0,0,(G23*100/$G$25)) -> 0
B24: Operating Equipment Operation ( SCHEDULE A-3C ) | C24: ='BS-Support'!C112 -> 795054.33 | E24: ='BS-Support'!E112 -> 694006.33 | G24: =C24-E24 -> 101048 | I24: =IF(G24=0,0,(G24*100/$G$25)) -> 100
B25: TOTAL INVENTORIES | C25: =SUM(C22:C24) -> 800842.18 | E25: =SUM(E22:E24) -> 699794.18 | G25: =C25-E25 -> 101048 | I25: =IF(G25=0,0,(G25*100/$G$25)) -> 100
A26: OTHER CURRENT ASSETS
B27: Other Prepaid Expenses (SCHEDULE A-4A ) | C27: ='BS-Support'!C127 -> 1967594 | E27: ='BS-Support'!E127 -> 1934000 | G27: =C27-E27 -> 33594 | I27: =IF(G27=0,0,(G27*100/$G$29)) -> -123.16322
B28: Other current Assets (SCHEDULE A-4B ) | C28: ='BS-Support'!C137 -> 82086 | E28: ='BS-Support'!E137 -> 142956 | G28: =C28-E28 -> -60870 | I28: =IF(G28=0,0,(G28*100/$G$29)) -> 223.16322
B29: TOTAL OTHER CURRENT ASSETS | C29: =SUM(C27:C28) -> 2049680 | E29: =SUM(E27:E28) -> 2076956 | G29: =C29-E29 -> -27276 | I29: =IF(G29=0,0,(G29*100/$G$29)) -> 100
B31: TOTAL CURRENT ASSETS | C31: =+C13+C20+C25+C29 -> 42966322 | E31: =+E13+E20+E25+E29 -> 37697177 | G31: =C31-E31 -> 5269145.6 | I31: =IF(G31=0,0,(G31*100/$G$31)) -> 100
A32: FIXED ASSETS
B33: PROPERTY, PLANT AND EQUIPMENT (SCHEDULE A-5A) | C33: ='BS-Support'!C202 -> 3041574.7 | E33: ='BS-Support'!E202 -> 2911351.8 | G33: =C33-E33 -> 130222.99 | I33: =IF(G33=0,0,(G33*100/$G$29)) -> -477.42701
B34: Less : Accumulated Depreciation | C34: ='BS-Support'!C203 -> 0 | E34: ='BS-Support'!E203 -> 0 | G34: =C34-E34 -> 0 | I34: =IF(G34=0,0,(G34*100/#REF!)) -> 0
B35: TOTAL PROPERTY, PLANT AND EQUIPMENT | C35: =C33-C34 -> 3041574.7 | E35: =E33-E34 -> 2911351.8 | G35: =C35-E35 -> 130222.99 | I35: =IF(G35=0,0,(G35*100/$G$35)) -> 100
B37: TOTAL ASSETS | C37: =C31+C35 -> 46007897 | E37: =E31+E35 -> 40608528 | G37: =C37-E37 -> 5399368.6 | I37: =IF(G37=0,0,(G37*100/$G$37)) -> 100
A40: LIABILITIES & SHAREHOLDERS' EQUPTY
A41: CURRENT LIABILITIES
B42: Accounts Payable ( SCHEDULE A-7A ) | C42: ='BS-Support'!C215 -> -2985829.8 | E42: ='BS-Support'!E215 -> -2914867.5 | G42: =C42-E42 -> -70962.28 | I42: =IF(G42=0,0,(G42*100/$G$48)) -> -5.7633723
B43: Guest Deposit | C43: ='BS-Support'!C217 -> 0 | E43: ='BS-Support'!E217 -> 0 | G43: =C43-E43 -> 0 | I43: =IF(G43=0,0,(G43*100/$G$48)) -> 0
B44: Other Current Liab. ( SCHEDULE A-7B ) | C44: ='BS-Support'!C226 -> 568.06 | E44: ='BS-Support'!E226 -> 568.06 | G44: =C44-E44 -> 0 | I44: =IF(G44=0,0,(G44*100/$G$48)) -> 0
B45: Accrued Taxes ( SCHEDULE A-7C ) | C45: ='BS-Support'!C242 -> 12217800 | E45: ='BS-Support'!E242 -> 11684956 | G45: =C45-E45 -> 532843.83 | I45: =IF(G45=0,0,(G45*100/$G$48)) -> 43.276193
...

Sheet BS-Support
A2: HOMM SUKHUMVIT34 BANGKOK | J2: Period | K2: =PRD -> 1
A3: BALANCE SHEET SUPPORTING
G4: EXHIBIT - B1 - B4 | BA4: Mapping Area
BA5: *Department Code | BL5: *Account Code | CG5: Dimension
A6: REPORT DESCRIPTION | C6: AT THE END OF | E6: AT THE BEGINNING | G6: INCREASE | I6: % | BA6: Dept 1 | BC6: Dept 2 | BE6: Dept 3 | BG6: Dept 4 | BI6: Dept 5 | BL6: 1st Range | BN6: 2nd Range | BP6: 3rd Range | BR6: 4rd Range | BT6: 5rd Range | BV6: 6rd Range | BX6: 7rd Range | BZ6: 8rd Range | CB6: 9rd Range | CD6: 10th Range
C7: THIS MONTH | E7: OF FISCAL PERIOD | G7: (DECREASE) | BA7: From | BB7: to | BC7: From | BD7: to | BE7: From | BF7: to | BG7: From | BH7: to | BI7: From | BJ7: to | BL7: From | BM7: To | BN7: From | BO7: To | BP7: From | BQ7: To | BR7: From | BS7: To | BT7: From | BU7: To | BV7: From | BW7: To | BX7: From | BY7: To | BZ7: From | CA7: To | CB7: From | CC7: To | CD7: From | CE7: To | CG7: A/O | CH7: Field Name | CI7: Operator | CJ7: Value
A8: ASSET
A9: CURRENT ASSET
B10: CASH ON HAND-HOUSE FUND ( Schedule A-1A )
B11: - CASH ON HAND | C11: =_xll.ACC(DB,_xll.ArrayDPT($BA11:$BJ11),_xll.ArrayCOA($BL11:$CE11),YR,PRD,_xll.ArrayDIM($CG11:$CJ11)) -> 0 | E11: =_xll.ACC(DB,_xll.ArrayDPT($BA11:$BJ11),_xll.ArrayCOA($BL11:$CE11),YR,PRD-1,_xll.ArrayDIM($CG11:$CJ11)) -> 0 | G11: =C11-E11 -> 0 | I11: =IF(G11=0,0,(G11*100/$G$18)) -> 0 | BL11: 71110 | BM11: 71110
B12: - PETTY CASH - FRONT OFFICE | C12: =_xll.ACC(DB,_xll.ArrayDPT($BA12:$BJ12),_xll.ArrayCOA($BL12:$CE12),YR,PRD,_xll.ArrayDIM($CG12:$CJ12)) -> 0 | E12: =_xll.ACC(DB,_xll.ArrayDPT($BA12:$BJ12),_xll.ArrayCOA($BL12:$CE12),YR,PRD-1,_xll.ArrayDIM($CG12:$CJ12)) -> 0 | G12: =C12-E12 -> 0 | I12: =IF(G12=0,0,(G12*100/$G$18)) -> 0
B13: - PETTY CASH - GENERAL CASHIER | C13: =_xll.ACC(DB,_xll.ArrayDPT($BA13:$BJ13),_xll.ArrayCOA($BL13:$CE13),YR,PRD,_xll.ArrayDIM($CG13:$CJ13)) -> -85808.57 | E13: =_xll.ACC(DB,_xll.ArrayDPT($BA13:$BJ13),_xll.ArrayCOA($BL13:$CE13),YR,PRD-1,_xll.ArrayDIM($CG13:$CJ13)) -> -85808.57 | G13: =C13-E13 -> 0 | I13: =IF(G13=0,0,(G13*100/$G$18)) -> 0 | BL13: 71120 | BM13: 71120
B14: - CASH FLOATS -FRONT CASHIER | C14: =_xll.ACC(DB,_xll.ArrayDPT($BA14:$BJ14),_xll.ArrayCOA($BL14:$CE14),YR,PRD,_xll.ArrayDIM($CG14:$CJ14)) -> 35657.5 | E14: =_xll.ACC(DB,_xll.ArrayDPT($BA14:$BJ14),_xll.ArrayCOA($BL14:$CE14),YR,PRD-1,_xll.ArrayDIM($CG14:$CJ14)) -> 35657.5 | G14: =C14-E14 -> 0 | I14: =IF(G14=0,0,(G14*100/$G$18)) -> 0 | BL14: 71130 | BM14: 71130
B15: - CASH FLOATS - FOOD & BEVERAGE | C15: =_xll.ACC(DB,_xll.ArrayDPT($BA15:$BJ15),_xll.ArrayCOA($BL15:$CE15),YR,PRD,_xll.ArrayDIM($CG15:$CJ15)) -> 0 | E15: =_xll.ACC(DB,_xll.ArrayDPT($BA15:$BJ15),_xll.ArrayCOA($BL15:$CE15),YR,PRD-1,_xll.ArrayDIM($CG15:$CJ15)) -> 0 | G15: =C15-E15 -> 0 | I15: =IF(G15=0,0,(G15*100/$G$18)) -> 0
B16: - HOUSE FUNDS - GENERAL CASHIER | C16: =_xll.ACC(DB,_xll.ArrayDPT($BA16:$BJ16),_xll.ArrayCOA($BL16:$CE16),YR,PRD,_xll.ArrayDIM($CG16:$CJ16)) -> -200 | E16: =_xll.ACC(DB,_xll.ArrayDPT($BA16:$BJ16),_xll.ArrayCOA($BL16:$CE16),YR,PRD-1,_xll.ArrayDIM($CG16:$CJ16)) -> -200 | G16: =C16-E16 -> 0 | I16: =IF(G16=0,0,(G16*100/$G$18)) -> 0 | BL16: 71125 | BM16: 71125
B17: - HOUSE FUNDS - FRONT OFFICE | C17: =_xll.ACC(DB,_xll.ArrayDPT($BA17:$BJ17),_xll.ArrayCOA($BL17:$CE17),YR,PRD,_xll.ArrayDIM($CG17:$CJ17)) -> 0 | E17: =_xll.ACC(DB,_xll.ArrayDPT($BA17:$BJ17),_xll.ArrayCOA($BL17:$CE17),YR,PRD-1,_xll.ArrayDIM($CG17:$CJ17)) -> 0 | G17: =C17-E17 -> 0 | I17: =IF(G17=0,0,(G17*100/$G$18)) -> 0
B18: TOTAL CASH ON HAND-HOUSE FUND | C18: =SUM(C11:C17) -> -50351.07 | E18: =SUM(E11:E17) -> -50351.07 | G18: =C18-E18 -> 0 | I18: =IF(G18=0,0,(G18*100/$G$18)) -> 0
B20: CASH IN BANK ( Schedule A-1B )
B21: - BANK - BBL SA # 175-4-23258-3 | C21: =_xll.ACC(DB,_xll.ArrayDPT($BA21:$BJ21),_xll.ArrayCOA($BL21:$CE21),YR,PRD,_xll.ArrayDIM($CG21:$CJ21)) -> -31923562 | E21: =_xll.ACC(DB,_xll.ArrayDPT($BA21:$BJ21),_xll.ArrayCOA($BL21:$CE21),YR,PRD-1,_xll.ArrayDIM($CG21:$CJ21)) -> -31923562 | G21: =C21-E21 -> 0 | I21: =IF(G21=0,0,(G21*100/$G$30)) -> 0 | BL21: 71140 | BM21: 71140
B22: - BANK - SCB SA # 096-2-47077-3 | C22: =_xll.ACC(DB,_xll.ArrayDPT($BA22:$BJ22),_xll.ArrayCOA($BL22:$CE22),YR,PRD,_xll.ArrayDIM($CG22:$CJ22)) -> -92019685 | E22: =_xll.ACC(DB,_xll.ArrayDPT($BA22:$BJ22),_xll.ArrayCOA($BL22:$CE22),YR,PRD-1,_xll.ArrayDIM($CG22:$CJ22)) -> -90307956 | G22: =C22-E22 -> -1711728.6 | I22: =IF(G22=0,0,(G22*100/$G$30)) -> 27.572299 | BL22: 71155 | BM22: 71155
B23: - BANK - SCB CA # 096-3-02678-9 | C23: =_xll.ACC(DB,_xll.ArrayDPT($BA23:$BJ23),_xll.ArrayCOA($BL23:$CE23),YR,PRD,_xll.ArrayDIM($CG23:$CJ23)) -> -50590106 | E23: =_xll.ACC(DB,_xll.ArrayDPT($BA23:$BJ23),_xll.ArrayCOA($BL23:$CE23),YR,PRD-1,_xll.ArrayDIM($CG23:$CJ23)) -> -54538739 | G23: =C23-E23 -> 3948632.6 | I23: =IF(G23=0,0,(G23*100/$G$30)) -> -63.604056 | BL23: 71160 | BM23: 71160
B24: - BANK - BBL SA # 175-4-23258-3 | C24: =_xll.ACC(DB,_xll.ArrayDPT($BA24:$BJ24),_xll.ArrayCOA($BL24:$CE24),YR,PRD,_xll.ArrayDIM($CG24:$CJ24)) -> -42042211 | E24: =_xll.ACC(DB,_xll.ArrayDPT($BA24:$BJ24),_xll.ArrayCOA($BL24:$CE24),YR,PRD-1,_xll.ArrayDIM($CG24:$CJ24)) -> -32837161 | G24: =C24-E24 -> -9205050 | I24: =IF(G24=0,0,(G24*100/$G$30)) -> 148.27374 | BL24: 71165 | BM24: 71165
B25: - BANK - TTB CA # 917-1-00149-9 | C25: =_xll.ACC(DB,_xll.ArrayDPT($BA25:$BJ25),_xll.ArrayCOA($BL25:$CE25),YR,PRD,_xll.ArrayDIM($CG25:$CJ25)) -> -92571935 | E25: =_xll.ACC(DB,_xll.ArrayDPT($BA25:$BJ25),_xll.ArrayCOA($BL25:$CE25),YR,PRD-1,_xll.ArrayDIM($CG25:$CJ25)) -> -93331935 | G25: =C25-E25 -> 760000 | I25: =IF(G25=0,0,(G25*100/$G$30)) -> -12.24198 | BL25: 71145 | BM25: 71145
B26: - BANK - KTB SA # 660-0-44804-4 | C26: =_xll.ACC(DB,_xll.ArrayDPT($BA26:$BJ26),_xll.ArrayCOA($BL26:$CE26),YR,PRD,_xll.ArrayDIM($CG26:$CJ26)) -> 500 | E26: =_xll.ACC(DB,_xll.ArrayDPT($BA26:$BJ26),_xll.ArrayCOA($BL26:$CE26),YR,PRD-1,_xll.ArrayDIM($CG26:$CJ26)) -> 500 | G26: =C26-E26 -> 0 | I26: =IF(G26=0,0,(G26*100/$G$30)) -> 0 | BL26: 71175 | BM26: 71175
B27: - BANK - UOB SA # | C27: =_xll.ACC(DB,_xll.ArrayDPT($BA27:$BJ27),_xll.ArrayCOA($BL27:$CE27),YR,PRD,_xll.ArrayDIM($CG27:$CJ27)) -> 0 | E27: =_xll.ACC(DB,_xll.ArrayDPT($BA27:$BJ27),_xll.ArrayCOA($BL27:$CE27),YR,PRD-1,_xll.ArrayDIM($CG27:$CJ27)) -> 0 | G27: =C27-E27 -> 0 | I27: =IF(G27=0,0,(G27*100/$G$30)) -> 0
B28: - BANK - KBAND SA # | C28: =_xll.ACC(DB,_xll.ArrayDPT($BA28:$BJ28),_xll.ArrayCOA($BL28:$CE28),YR,PRD,_xll.ArrayDIM($CG28:$CJ28)) -> 0 | E28: =_xll.ACC(DB,_xll.ArrayDPT($BA28:$BJ28),_xll.ArrayCOA($BL28:$CE28),YR,PRD-1,_xll.ArrayDIM($CG28:$CJ28)) -> 0 | G28: =C28-E28 -> 0 | I28: =IF(G28=0,0,(G28*100/$G$30)) -> 0
B29: - BANK - FIXED # | C29: =_xll.ACC(DB,_xll.ArrayDPT($BA29:$BJ29),_xll.ArrayCOA($BL29:$CE29),YR,PRD,_xll.ArrayDIM($CG29:$CJ29)) -> 0 | E29: =_xll.ACC(DB,_xll.ArrayDPT($BA29:$BJ29),_xll.ArrayCOA($BL29:$CE29),YR,PRD-1,_xll.ArrayDIM($CG29:$CJ29)) -> 0 | G29: =C29-E29 -> 0 | I29: =IF(G29=0,0,(G29*100/$G$30)) -> 0
B30: TOTAL CASH IN BANK | C30: =SUM(C21:C29) -> -3.09147e+08 | E30: =SUM(E21:E29) -> -3.0293885e+08 | G30: =C30-E30 -> -6208145.9 | I30: =IF(G30=0,0,(G30*100/$G$30)) -> 100
A31: TOTAL CURRENT ASSET | C31: =+C30+C18 -> -3.0919735e+08 | E31: =+E30+E18 -> -3.029892e+08 | G31: =C31-E31 -> -6208145.9 | I31: =IF(G31=0,0,(G31*100/$G$31)) -> 100
A33: ACCOUNT RECEIVABLE - TRADE ( SCHEDULE A - 2A )
B34: - A/R TRADE - GUEST LEDGER | C34: =_xll.ACC(DB,_xll.ArrayDPT($BA34:$BJ34),_xll.ArrayCOA($BL34:$CE34),YR,PRD,_xll.ArrayDIM($CG34:$CJ34)) -> -17038581 | E34: =_xll.ACC(DB,_xll.ArrayDPT($BA34:$BJ34),_xll.ArrayCOA($BL34:$CE34),YR,PRD-1,_xll.ArrayDIM($CG34:$CJ34)) -> -19824339 | G34: =C34-E34 -> 2785758.2 | I34: =IF(G34=0,0,(G34*100/$G$44)) -> 100 | BL34: 71185 | BM34: 71185
B35: - A/R TRADE - CITY LEDGER | C35: =_xll.ACC(DB,_xll.ArrayDPT($BA35:$BJ35),_xll.ArrayCOA($BL35:$CE35),YR,PRD,_xll.ArrayDIM($CG35:$CJ35)) -> 0 | E35: =_xll.ACC(DB,_xll.ArrayDPT($BA35:$BJ35),_xll.ArrayCOA($BL35:$CE35),YR,PRD-1,_xll.ArrayDIM($CG35:$CJ35)) -> 0 | G35: =C35-E35 -> 0 | I35: =IF(G35=0,0,(G35*100/$G$44)) -> 0 | BL35: 71190 | BM35: 71190
B36: - A/R CREDIT CARD | C36: =_xll.ACC(DB,_xll.ArrayDPT($BA36:$BJ36),_xll.ArrayCOA($BL36:$CE36),YR,PRD,_xll.ArrayDIM($CG36:$CJ36)) -> 0 | E36: =_xll.ACC(DB,_xll.ArrayDPT($BA36:$BJ36),_xll.ArrayCOA($BL36:$CE36),YR,PRD-1,_xll.ArrayDIM($CG36:$CJ36)) -> 0 | G36: =C36-E36 -> 0 | I36: =IF(G36=0,0,(G36*100/$G$44)) -> 0 | BL36: 71195 | BM36: 71195 | BN36: 71200 | BO36: 71200 | BP36: 71205 | BQ36: 71205 | BR36: 71210 | BS36: 71210 | BT36: 71215 | BU36: 71215
B37: - ADVANCE CHEQUES | C37: =_xll.ACC(DB,_xll.ArrayDPT($BA37:$BJ37),_xll.ArrayCOA($BL37:$CE37),YR,PRD,_xll.ArrayDIM($CG37:$CJ37)) -> 0 | E37: =_xll.ACC(DB,_xll.ArrayDPT($BA37:$BJ37),_xll.ArrayCOA($BL37:$CE37),YR,PRD-1,_xll.ArrayDIM($CG37:$CJ37)) -> 0 | G37: =C37-E37 -> 0 | I37: =IF(G37=0,0,(G37*100/$G$44)) -> 0
B38: - A/R TRADE BARTER AGREEMENT | C38: =_xll.ACC(DB,_xll.ArrayDPT($BA38:$BJ38),_xll.ArrayCOA($BL38:$CE38),YR,PRD,_xll.ArrayDIM($CG38:$CJ38)) -> 0 | E38: =_xll.ACC(DB,_xll.ArrayDPT($BA38:$BJ38),_xll.ArrayCOA($BL38:$CE38),YR,PRD-1,_xll.ArrayDIM($CG38:$CJ38)) -> 0 | G38: =C38-E38 -> 0 | I38: =IF(G38=0,0,(G38*100/$G$44)) -> 0
B39: - A/R OTHER | C39: =_xll.ACC(DB,_xll.ArrayDPT($BA39:$BJ39),_xll.ArrayCOA($BL39:$CE39),YR,PRD,_xll.ArrayDIM($CG39:$CJ39)) -> 0 | E39: =_xll.ACC(DB,_xll.ArrayDPT($BA39:$BJ39),_xll.ArrayCOA($BL39:$CE39),YR,PRD-1,_xll.ArrayDIM($CG39:$CJ39)) -> 0 | G39: =C39-E39 -> 0 | I39: =IF(G39=0,0,(G39*100/$G$44)) -> 0 | BL39: 71220 | BM39: 71220 | BN39: 71225 | BO39: 71225 | BP39: 71230 | BQ39: 71230 | BR39: 71235 | BS39: 71235
B40: TOTAL ACCOUNT RECEIVABLE - TRADE | C40: =SUM(C34:C39) -> -17038581 | E40: =SUM(E34:E39) -> -19824339 | G40: =C40-E40 -> 2785758.2 | I40: =IF(G40=0,0,(G40*100/$G$44)) -> 100
B42: LESS : Allowance For Doubtful Account | C42: =_xll.ACC(DB,_xll.ArrayDPT($BA42:$BJ42),_xll.ArrayCOA($BL42:$CE42),YR,PRD,_xll.ArrayDIM($CG42:$CJ42)) -> 0 | E42: =_xll.ACC(DB,_xll.ArrayDPT($BA42:$BJ42),_xll.ArrayCOA($BL42:$CE42),YR-1,PRD,_xll.ArrayDIM($CG42:$CJ42)) -> 0 | G42: =C42-E42 -> 0 | I42: =IF(G42=0,0,(G42*100/$G$44)) -> 0
B43: Loans To Subsidiaries And Associated | C43: =_xll.ACC(DB,_xll.ArrayDPT($BA43:$BJ43),_xll.ArrayCOA($BL43:$CE43),YR,PRD,_xll.ArrayDIM($CG43:$CJ43)) -> 0 | E43: =_xll.ACC(DB,_xll.ArrayDPT($BA43:$BJ43),_xll.ArrayCOA($BL43:$CE43),YR-1,PRD,_xll.ArrayDIM($CG43:$CJ43)) -> 0 | G43: =C43-E43 -> 0 | I43: =IF(G43=0,0,(G43*100/$G$44)) -> 0
A44: NET - ACCOUNT RECEIVABLE - TRADE | C44: =C40+C42+C43 -> -17038581 | E44: =E40+E42+E43 -> -19824339 | G44: =C44-E44 -> 2785758.2 | I44: =IF(G44=0,0,(G44*100/$G$44)) -> 100 | J44: =C44-BS!C17 -> 0 | L44: =E44-BS!E17 -> 0
...

Sheet PL-Sum
A2: HOMM SUKHUMVIT34 BANGKOK | T2: Period | U2: =PRD -> 1
J3: Profit & Loss Summary | Q3: SCHEDULE - A | AA3: Mapping Area
A4: CURRENT MONTH | L4: YEAR TO DATE | AA4: *Department Code | AG4: *Account Code | BT4: Dimension
A5: LAST YEAR | C5: VARIANCE | E5: BUDGET | G5: ACTUAL | J5: DESCRIPTION | L5: ACTUAL | N5: BUDGET | P5: VARIANCE | R5: LAST YEAR | AA5: Dept 1 | AB5: Dept 2 | AC5: Dept 3 | AD5: Dept 4 | AE5: Dept 5 | AG5: 1st Range | AI5: 2nd Range | AK5: 3rd Range | AM5: 4rd Range | AO5: 5rd Range | AQ5: 6rd Range | AS5: 7rd Range | AU5: 8rd Range | AW5: 9rd Range | AY5: 10rd Range | BA5: 11rd Range | BC5: 12rd Range | BE5: 13rd Range | BG5: 14rd Range | BI5: 15rd Range | BK5: 16rd Range | BM5: 17rd Range | BO5: 18th Range | BQ5: 19th Range
A6: BHT | B6: % | C6: BHT | D6: % | E6: BHT | F6: % | G6: BHT | H6: % | L6: BHT | M6: % | N6: BHT | O6: % | P6: BHT | Q6: % | R6: BHT | S6: % | AG6: From | AH6: To | AI6: From | AJ6: To | AK6: From | AL6: To | AM6: From | AN6: To | AO6: From | AP6: To | AQ6: From | AR6: To | AS6: From | AT6: To | AU6: From | AV6: To | AW6: From | AX6: To | AY6: From | AZ6: To | BA6: From | BB6: To | BC6: From | BD6: To | BE6: From | BF6: To | BG6: From | BH6: To | BI6: From | BJ6: To | BK6: From | BL6: To | BM6: From | BN6: To | BO6: From | BP6: To | BQ6: From | BR6: To | BT6: A/O | BU6: Field Name | BV6: Operator | BW6: Value
A7: ='Sum Room'!A78 -> 4588 | C7: =G7-E7 -> 4588 | E7: ='Sum Room'!E78 -> 0 | G7: ='Sum Room'!G78 -> 4588 | J7: Total Roon In Hotel | L7: ='Sum Room'!L78 -> 4588 | N7: ='Sum Room'!N78 -> 0 | P7: ='Sum Room'!P78 -> -4588 | R7: ='Sum Room'!R78 -> 4588
A8: ='Sum Room'!A80 -> 3209 | C8: =G8-E8 -> 3442 | E8: ='Sum Room'!E80 -> 0 | G8: ='Sum Room'!G80 -> 3442 | J8: Room Occupied | L8: =Front!L80 -> 3442 | N8: =Front!N80 -> 0 | P8: =Front!P80 -> -3442 | R8: =Front!R80 -> 3209
A9: =A8/A7 -> 0.6994333 | C9: =C8/C7 -> 0.75021796 | E9: =E8/E7 -> #DIV/0! | G9: =G8/G7 -> 0.75021796 | J9: % Of Occupancy | L9: =L8/L7 -> 0.75021796 | N9: =N8/N7 -> #DIV/0! | P9: =P8/P7 -> 0.75021796 | R9: =R8/R7 -> 0.6994333
A10: 0 | C10: 0 | E10: 0 | G10: 0 | J10: Double Occupancy | L10: 0 | N10: 0 | P10: 0 | R10: 0
A11: ='Sum Room'!A81 -> 2254.4789 | C11: =G11-E11 -> #DIV/0! | E11: ='Sum Room'!E81 -> #DIV/0! | G11: ='Sum Room'!G81 -> 2294.0267 | J11: Average Room Rate | L11: ='Sum Room'!L81 -> 2294.0267 | N11: ='Sum Room'!N81 -> #DIV/0! | P11: ='Sum Room'!P81 -> 2294.0267 | R11: ='Sum Room'!R81 -> 2254.4789
A12: ='Sum Room'!A82 -> 6310 | C12: =G12-E12 -> 6408 | E12: ='Sum Room'!E82 -> 0 | G12: ='Sum Room'!G82 -> 6408 | J12: Number Of Guest | L12: ='Sum Room'!L82 -> 6408 | N12: ='Sum Room'!N82 -> 0 | P12: ='Sum Room'!P82 -> -6408 | R12: ='Sum Room'!R82 -> 6310
J14: R E V E N U E
A15: =Front!A14 -> 7249519.3 | B15: =IF(A15=0,0,(A15*100/A$19)) -> 87.066434 | C15: =Front!C14 -> -7921831 | D15: =IF(C15=0,0,(C15*100/C$19)) -> 91.476967 | E15: =Front!E14 -> 0 | F15: =IF(E15=0,0,(E15*100/E$19)) -> 0 | G15: ='Sum Room'!G14 -> 7921831 | H15: =IF(G15=0,0,(G15*100/G$19)) -> 91.476967 | J15: Rooms | L15: ='Sum Room'!L14 -> 7921831 | M15: =IF(L15=0,0,(L15*100/L$19)) -> 77.459648 | N15: =Front!N14 -> 0 | O15: =IF(N15=0,0,(N15*100/N$19)) -> 0 | P15: =Front!P14 -> -7921831 | Q15: =IF(P15=0,0,(P15*100/P$19)) -> 77.459648 | R15: =Front!R14 -> 7249519.3 | S15: =IF(R15=0,0,(R15*100/R$19)) -> 73.654521
A16: ='F&B'!A14 -> 809758.45 | B16: =IF(A16=0,0,(A16*100/A$19)) -> 9.7251663 | C16: ='F&B'!C14 -> -513215.19 | D16: =IF(C16=0,0,(C16*100/C$19)) -> 5.926328 | E16: ='F&B'!E14 -> 0 | F16: =IF(E16=0,0,(E16*100/E$19)) -> 0 | G16: ='F&B'!G14 -> 513215.19 | H16: =IF(G16=0,0,(G16*100/G$19)) -> 5.926328 | J16: Food & Beverage | L16: ='F&B'!L14 -> 2080338.7 | M16: =IF(L16=0,0,(L16*100/L$19)) -> 20.341548 | N16: ='F&B'!N14 -> 0 | O16: =IF(N16=0,0,(N16*100/N$19)) -> 0 | P16: ='F&B'!P14 -> -2080338.7 | Q16: =IF(P16=0,0,(P16*100/P$19)) -> 20.341548 | R16: ='F&B'!R14 -> 2325935 | S16: =IF(R16=0,0,(R16*100/R$19)) -> 23.631309
A17: ='Spa & Fitness'!A17 -> 59532.76 | B17: =IF(A17=0,0,(A17*100/A$19)) -> 0.71498605 | C17: ='Spa & Fitness'!C17 -> -424.81 | D17: =IF(C17=0,0,(C17*100/C$19)) -> 0.0049054733 | E17: ='Spa & Fitness'!E17 -> 0 | F17: =IF(E17=0,0,(E17*100/E$19)) -> 0 | G17: ='Spa & Fitness'!G17 -> 424.81 | H17: =IF(G17=0,0,(G17*100/G$19)) -> 0.0049054733 | J17: Spa & Fitness Center | L17: ='Spa & Fitness'!L17 -> 424.81 | M17: =IF(L17=0,0,(L17*100/L$19)) -> 0.0041537914 | N17: ='Spa & Fitness'!N17 -> 0 | O17: =IF(N17=0,0,(N17*100/N$19)) -> 0 | P17: ='Spa & Fitness'!P17 -> -424.81 | Q17: =IF(P17=0,0,(P17*100/P$19)) -> 0.0041537914 | R17: ='Spa & Fitness'!R17 -> 59532.76 | S17: =IF(R17=0,0,(R17*100/R$19)) -> 0.60484796
A18: =OOD!A19 -> 207612.13 | B18: =IF(A18=0,0,(A18*100/A$19)) -> 2.4934133 | C18: =OOD!C19 -> -224447.74 | D18: =IF(C18=0,0,(C18*100/C$19)) -> 2.5917996 | E18: =OOD!E19 -> 0 | F18: =IF(E18=0,0,(E18*100/E$19)) -> 0 | G18: =OOD!G19 -> 224447.74 | H18: =IF(G18=0,0,(G18*100/G$19)) -> 2.5917996 | J18: Other Operated Departments | L18: =OOD!L19 -> 224447.74 | M18: =IF(L18=0,0,(L18*100/L$19)) -> 2.1946496 | N18: =OOD!N19 -> 0 | O18: =IF(N18=0,0,(N18*100/N$19)) -> 0 | P18: =OOD!P19 -> -224447.74 | Q18: =IF(P18=0,0,(P18*100/P$19)) -> 2.1946496 | R18: =OOD!R19 -> 207612.13 | S18: =IF(R18=0,0,(R18*100/R$19)) -> 2.1093222
A19: =SUM(A15:A18) -> 8326422.6 | B19: =IF(A19=0,0,(A19*100/A$19)) -> 100 | C19: =SUM(C15:C18) -> -8659918.7 | D19: =IF(C19=0,0,(C19*100/C$19)) -> 100 | E19: =SUM(E15:E18) -> 0 | F19: =IF(E19=0,0,(E19*100/E$19)) -> 0 | G19: =SUM(G15:G18) -> 8659918.7 | H19: =IF(G19=0,0,(G19*100/G$19)) -> 100 | J19: TOTAL REVENUE | L19: =SUM(L15:L18) -> 10227042 | M19: =IF(L19=0,0,(L19*100/L$19)) -> 100 | N19: =SUM(N15:N18) -> 0 | O19: =IF(N19=0,0,(N19*100/N$19)) -> 0 | P19: =SUM(P15:P18) -> -10227042 | Q19: =IF(P19=0,0,(P19*100/P$19)) -> 100 | R19: =SUM(R15:R18) -> 9842599.2 | S19: =IF(R19=0,0,(R19*100/R$19)) -> 100
J20: C O S T O F S A L E
A21: ='F&B'!A23 -> 263952.68 | B21: =IF(A21=0,0,(A21*100/A$19)) -> 3.170061 | C21: ='F&B'!C23 -> -153250.75 | D21: =IF(C21=0,0,(C21*100/C$19)) -> 1.7696558 | E21: ='F&B'!E23 -> 0 | F21: =IF(E21=0,0,(E21*100/E$19)) -> 0 | G21: ='F&B'!G23 -> 153250.75 | H21: =IF(G21=0,0,(G21*100/G$16)) -> 29.860915 | J21: Food & Beverage | L21: ='F&B'!L23 -> 153250.75 | M21: =IF(L21=0,0,(L21*100/L$16)) -> 7.3666248 | N21: ='F&B'!N23 -> 0 | O21: =IF(N21=0,0,(N21*100/N$19)) -> 0 | P21: ='F&B'!P23 -> -153250.75 | Q21: =IF(P21=0,0,(P21*100/P$19)) -> 1.4984855 | R21: ='F&B'!R23 -> 263952.68 | S21: =IF(R21=0,0,(R21*100/R$19)) -> 2.6817376
A22: ='Spa & Fitness'!A27 -> 27684.35 | B22: =IF(A22=0,0,(A22*100/A$19)) -> 0.33248793 | C22: ='Spa & Fitness'!C27 -> 0 | D22: =IF(C22=0,0,(C22*100/C$19)) -> 0 | E22: ='Spa & Fitness'!E27 -> 0 | F22: =IF(E22=0,0,(E22*100/E$19)) -> 0 | G22: ='Spa & Fitness'!G27 -> 0 | H22: =IF(G22=0,0,(G22*100/G$17)) -> 0 | J22: Spa & Fitness Center | L22: ='Spa & Fitness'!L27 -> 0 | M22: =IF(L22=0,0,(L22*100/L$17)) -> 0 | N22: ='Spa & Fitness'!N27 -> 0 | O22: =IF(N22=0,0,(N22*100/N$19)) -> 0 | P22: ='Spa & Fitness'!P27 -> 0 | Q22: =IF(P22=0,0,(P22*100/P$19)) -> 0 | R22: ='Spa & Fitness'!R27 -> 27684.35 | S22: =IF(R22=0,0,(R22*100/R$19)) -> 0.28127072
A23: =OOD!A31 -> 12536.48 | B23: =IF(A23=0,0,(A23*100/A$19)) -> 0.15056262 | C23: =OOD!C31 -> -52136.89 | D23: =IF(C23=0,0,(C23*100/C$19)) -> 0.60204826 | E23: =OOD!E31 -> 0 | F23: =IF(E23=0,0,(E23*100/E$19)) -> 0 | G23: =OOD!G31 -> 52136.89 | H23: =IF(G23=0,0,(G23*100/G$18)) -> 23.228966 | J23: Other Operated Departments | L23: =OOD!L31 -> 52136.89 | M23: =IF(L23=0,0,(L23*100/L$18)) -> 23.228966 | N23: =OOD!N31 -> 0 | O23: =IF(N23=0,0,(N23*100/N$19)) -> 0 | P23: =OOD!P31 -> -52136.89 | Q23: =IF(P23=0,0,(P23*100/P$19)) -> 0.50979441 | R23: =OOD!R31 -> 12536.48 | S23: =IF(R23=0,0,(R23*100/R$19)) -> 0.12736961
A24: =SUM(A20:A23) -> 304173.51 | B24: =IF(A24=0,0,(A24*100/A$19)) -> 3.6531116 | C24: =SUM(C20:C23) -> -205387.64 | D24: =IF(C24=0,0,(C24*100/C$19)) -> 2.371704 | E24: =SUM(E20:E23) -> 0 | F24: =IF(E24=0,0,(E24*100/E$19)) -> 0 | G24: =SUM(G20:G23) -> 205387.64 | H24: =IF(G24=0,0,(G24*100/G$19)) -> 2.371704 | J24: TOTAL COST OF SALES | L24: =SUM(L20:L23) -> 205387.64 | M24: =IF(L24=0,0,(L24*100/L$19)) -> 2.00828 | N24: =SUM(N20:N23) -> 0 | O24: =IF(N24=0,0,(N24*100/N$19)) -> 0 | P24: =SUM(P20:P23) -> -205387.64 | Q24: =IF(P24=0,0,(P24*100/P$19)) -> 2.00828 | R24: =SUM(R20:R23) -> 304173.51 | S24: =IF(R24=0,0,(R24*100/R$19)) -> 3.0903779
J25: PAYROLL & EMPLOYEE RELATION
A26: =Front!A26 -> 133133.34 | B26: =IF(A26=0,0,(A26*100/A$19)) -> 1.598926 | C26: =Front!C26 -> -137465.61 | D26: =IF(C26=0,0,(C26*100/C$19)) -> 1.5873776 | E26: =Front!E26 -> 0 | F26: =IF(E26=0,0,(E26*100/E$19)) -> 0 | G26: ='Sum Room'!G26 -> 289005.28 | H26: =IF(G26=0,0,(G26*100/G$19)) -> 3.3372747 | J26: Rooms | L26: =Front!L26 -> 137465.61 | M26: =IF(L26=0,0,(L26*100/L$19)) -> 1.3441385 | N26: =Front!N26 -> 0 | O26: =IF(N26=0,0,(N26*100/N$19)) -> 0 | P26: =Front!P26 -> -137465.61 | Q26: =IF(P26=0,0,(P26*100/P$19)) -> 1.3441385 | R26: =Front!R26 -> 133133.34 | S26: =IF(R26=0,0,(R26*100/R$19)) -> 1.3526238
A27: ='F&B'!A34 -> 104000 | B27: =IF(A27=0,0,(A27*100/A$19)) -> 1.2490358 | C27: ='F&B'!C34 -> -116934.33 | D27: =IF(C27=0,0,(C27*100/C$19)) -> 1.3502936 | E27: ='F&B'!E34 -> 0 | F27: =IF(E27=0,0,(E27*100/E$19)) -> 0 | G27: ='F&B'!G34 -> 116934.33 | H27: =IF(G27=0,0,(G27*100/G$19)) -> 1.3502936 | J27: Food & Beverage | L27: ='F&B'!L34 -> 116934.33 | M27: =IF(L27=0,0,(L27*100/L$19)) -> 1.1433837 | N27: ='F&B'!N34 -> 0 | O27: =IF(N27=0,0,(N27*100/N$19)) -> 0 | P27: ='F&B'!P34 -> -116934.33 | Q27: =IF(P27=0,0,(P27*100/P$19)) -> 1.1433837 | R27: ='F&B'!R34 -> 104000 | S27: =IF(R27=0,0,(R27*100/R$19)) -> 1.0566315
A28: ='Spa & Fitness'!A34 -> 0 | B28: =IF(A28=0,0,(A28*100/A$19)) -> 0 | C28: ='Spa & Fitness'!C34 -> 0 | D28: =IF(C28=0,0,(C28*100/C$19)) -> 0 | E28: ='Spa & Fitness'!E34 -> 0 | F28: =IF(E28=0,0,(E28*100/E$19)) -> 0 | G28: =+'Spa & Fitness'!G34 -> 0 | H28: =IF(G28=0,0,(G28*100/G$19)) -> 0 | J28: Spa & Fitness Center | L28: ='Spa & Fitness'!L34 -> 0 | M28: =IF(L28=0,0,(L28*100/L$19)) -> 0 | N28: ='Spa & Fitness'!N34 -> 0 | O28: =IF(N28=0,0,(N28*100/N$19)) -> 0 | P28: ='Spa & Fitness'!P34 -> 0 | Q28: =IF(P28=0,0,(P28*100/P$19)) -> 0 | R28: ='Spa & Fitness'!R34 -> 0 | S28: =IF(R28=0,0,(R28*100/R$19)) -> 0
A29: =OOD!A38 -> 0 | B29: =IF(A29=0,0,(A29*100/A$19)) -> 0 | C29: =OOD!C38 -> 0 | D29: =IF(C29=0,0,(C29*100/C$19)) -> 0 | E29: =OOD!E38 -> 0 | F29: =IF(E29=0,0,(E29*100/E$19)) -> 0 | G29: =OOD!G38 -> 0 | H29: =IF(G29=0,0,(G29*100/G$19)) -> 0 | J29: Other Operated Departments | L29: =OOD!L38 -> 0 | M29: =IF(L29=0,0,(L29*100/L$19)) -> 0 | N29: =OOD!N38 -> 0 | O29: =IF(N29=0,0,(N29*100/N$19)) -> 0 | P29: =OOD!P38 -> 0 | Q29: =IF(P29=0,0,(P29*100/P$19)) -> 0 | R29: =OOD!R38 -> 0 | S29: =IF(R29=0,0,(R29*100/R$19)) -> 0
A30: =SUM(A26:A29) -> 237133.34 | B30: =IF(A30=0,0,(A30*100/A$19)) -> 2.8479618 | C30: =SUM(C26:C29) -> -254399.94 | D30: =IF(C30=0,0,(C30*100/C$19)) -> 2.9376712 | E30: =SUM(E26:E29) -> 0 | F30: =IF(E30=0,0,(E30*100/E$19)) -> 0 | G30: =SUM(G26:G29) -> 405939.61 | H30: =IF(G30=0,0,(G30*100/G$19)) -> 4.6875684 | J30: TOTAL PAYROLL & EMP. REL. | L30: =SUM(L26:L29) -> 254399.94 | M30: =IF(L30=0,0,(L30*100/L$19)) -> 2.4875221 | N30: =SUM(N26:N29) -> 0 | O30: =IF(N30=0,0,(N30*100/N$19)) -> 0 | P30: =SUM(P26:P29) -> -254399.94 | Q30: =IF(P30=0,0,(P30*100/P$19)) -> 2.4875221 | R30: =SUM(R26:R29) -> 237133.34 | S30: =IF(R30=0,0,(R30*100/R$19)) -> 2.4092553
J31: O T H E R E X P E N S E S
A32: =Front!A72 -> 227068.56 | B32: =IF(A32=0,0,(A32*100/A$19)) -> 2.7270842 | C32: =Front!C72 -> -30605.31 | D32: =IF(C32=0,0,(C32*100/C$19)) -> 0.35341336 | E32: =Front!E72 -> 0 | F32: =IF(E32=0,0,(E32*100/E$19)) -> 0 | G32: ='Sum Room'!G72 -> 1005211.1 | H32: =IF(G32=0,0,(G32*100/G$19)) -> 11.607628 | J32: Rooms | L32: =Front!L72 -> 30605.31 | M32: =IF(L32=0,0,(L32*100/L$19)) -> 0.29925866 | N32: =Front!N72 -> 0 | O32: =IF(N32=0,0,(N32*100/N$19)) -> 0 | P32: =Front!P72 -> -30605.31 | Q32: =IF(P32=0,0,(P32*100/P$19)) -> 0.29925866 | R32: =Front!R72 -> 227068.56 | S32: =IF(R32=0,0,(R32*100/R$19)) -> 2.3069979
A33: ='F&B'!A77 -> 29066.17 | B33: =IF(A33=0,0,(A33*100/A$19)) -> 0.34908353 | C33: ='F&B'!C77 -> -73088.92 | D33: =IF(C33=0,0,(C33*100/C$19)) -> 0.84399083 | E33: ='F&B'!E77 -> 0 | F33: =IF(E33=0,0,(E33*100/E$19)) -> 0 | G33: ='F&B'!G77 -> 73088.92 | H33: =IF(G33=0,0,(G33*100/G$19)) -> 0.84399083 | J33: Food & Beverage | L33: ='F&B'!L77 -> 73088.92 | M33: =IF(L33=0,0,(L33*100/L$19)) -> 0.71466332 | N33: ='F&B'!N77 -> 0 | O33: =IF(N33=0,0,(N33*100/N$19)) -> 0 | P33: ='F&B'!P77 -> -73088.92 | Q33: =IF(P33=0,0,(P33*100/P$19)) -> 0.71466332 | R33: ='F&B'!R77 -> 29066.17 | S33: =IF(R33=0,0,(R33*100/R$19)) -> 0.2953099
A34: ='Spa & Fitness'!A60 -> 0 | B34: =IF(A34=0,0,(A34*100/A$19)) -> 0 | C34: ='Spa & Fitness'!C60 -> 0 | D34: =IF(C34=0,0,(C34*100/C$19)) -> 0 | E34: ='Spa & Fitness'!E60 -> 0 | F34: =IF(E34=0,0,(E34*100/E$19)) -> 0 | G34: ='Spa & Fitness'!G60 -> 0 | H34: =IF(G34=0,0,(G34*100/G$19)) -> 0 | J34: Spa & Fitness Center | L34: ='Spa & Fitness'!L60 -> 0 | M34: =IF(L34=0,0,(L34*100/L$19)) -> 0 | N34: ='Spa & Fitness'!N60 -> 0 | O34: =IF(N34=0,0,(N34*100/N$19)) -> 0 | P34: ='Spa & Fitness'!P60 -> 0 | Q34: =IF(P34=0,0,(P34*100/P$19)) -> 0 | R34: ='Spa & Fitness'!R60 -> 0 | S34: =IF(R34=0,0,(R34*100/R$19)) -> 0
A35: =OOD!A58 -> 0 | B35: =IF(A35=0,0,(A35*100/A$19)) -> 0 | C35: =OOD!C58 -> 0 | D35: =IF(C35=0,0,(C35*100/C$19)) -> 0 | E35: =OOD!E58 -> 0 | F35: =IF(E35=0,0,(E35*100/E$19)) -> 0 | G35: =OOD!G58 -> 0 | H35: =IF(G35=0,0,(G35*100/G$19)) -> 0 | J35: Other Operated Departments | L35: =OOD!L58 -> 0 | M35: =IF(L35=0,0,(L35*100/L$19)) -> 0 | N35: =OOD!N58 -> 0 | O35: =IF(N35=0,0,(N35*100/N$19)) -> 0 | P35: =OOD!P58 -> 0 | Q35: =IF(P35=0,0,(P35*100/P$19)) -> 0 | R35: =OOD!R58 -> 0 | S35: =IF(R35=0,0,(R35*100/R$19)) -> 0
A36: =SUM(A32:A35) -> 256134.73 | B36: =IF(A36=0,0,(A36*100/A$19)) -> 3.0761678 | C36: =SUM(C32:C35) -> -103694.23 | D36: =IF(C36=0,0,(C36*100/C$19)) -> 1.1974042 | E36: =SUM(E32:E35) -> 0 | F36: =IF(E36=0,0,(E36*100/E$19)) -> 0 | G36: =SUM(G32:G35) -> 1078300 | H36: =IF(G36=0,0,(G36*100/G$19)) -> 12.451618 | J36: TOTALOTHER EXPENSES | L36: =SUM(L32:L35) -> 103694.23 | M36: =IF(L36=0,0,(L36*100/L$19)) -> 1.013922 | N36: =SUM(N32:N35) -> 0 | O36: =IF(N36=0,0,(N36*100/N$19)) -> 0 | P36: =SUM(P32:P35) -> -103694.23 | Q36: =IF(P36=0,0,(P36*100/P$19)) -> 1.013922 | R36: =SUM(R32:R35) -> 256134.73 | S36: =IF(R36=0,0,(R36*100/R$19)) -> 2.6023078
A37: =+A24+A30+A36 -> 797441.58 | B37: =IF(A37=0,0,(A37*100/A$19)) -> 9.5772412 | C37: =+C24+C30+C36 -> -563481.81 | D37: =IF(C37=0,0,(C37*100/C$19)) -> 6.5067794 | E37: =+E24+E30+E36 -> 0 | F37: =IF(E37=0,0,(E37*100/E$19)) -> 0 | G37: =+G24+G30+G36 -> 1689627.3 | H37: =IF(G37=0,0,(G37*100/G$19)) -> 19.510891 | J37: TOTAL DEPARTMENT EXPENSES | L37: =+L24+L30+L36 -> 563481.81 | M37: =IF(L37=0,0,(L37*100/L$19)) -> 5.5097241 | N37: =+N24+N30+N36 -> 0 | O37: =IF(N37=0,0,(N37*100/N$19)) -> 0 | P37: =+P24+P30+P36 -> -563481.81 | Q37: =IF(P37=0,0,(P37*100/P$19)) -> 5.5097241 | R37: =+L37-P37 -> 1126963.6 | S37: =IF(R37=0,0,(R37*100/R$19)) -> 11.449858
J38: DEPARTMENT PROFIT (LOSS)
A39: =+A15-A26-A32 -> 6889317.4 | B39: =IF(A39=0,0,(A39*100/A$19)) -> 82.740424 | C39: =+C15-C26-C32 -> -7753760.1 | D39: =IF(C39=0,0,(C39*100/C$19)) -> 89.536176 | E39: =+E15-E26-E32 -> 0 | F39: =IF(E39=0,0,(E39*100/E$19)) -> 0 | G39: =+G15-G26-G32 -> 6627614.6 | H39: =IF(G39=0,0,(G39*100/G$19)) -> 76.532065 | J39: Rooms | L39: =+L15-L26-L32 -> 7753760.1 | M39: =IF(L39=0,0,(L39*100/L$19)) -> 75.816251 | N39: =+N15-N26-N32 -> 0 | O39: =IF(N39=0,0,(N39*100/N$19)) -> 0 | P39: =+P15-P26-P32 -> -7753760.1 | Q39: =IF(P39=0,0,(P39*100/P$19)) -> 75.816251 | R39: =+R15-R26-R32 -> 6889317.4 | S39: =IF(R39=0,0,(R39*100/R$19)) -> 69.9949
A40: =+A16-A21-A27-A33 -> 412739.6 | B40: =IF(A40=0,0,(A40*100/A$19)) -> 4.9569859 | C40: =+C16-C21-C27-C33 -> -169941.19 | D40: =IF(C40=0,0,(C40*100/C$19)) -> 1.9623878 | E40: =+E16-E21-E27-E33 -> 0 | F40: =IF(E40=0,0,(E40*100/E$19)) -> 0 | G40: =+G16-G21-G27-G33 -> 169941.19 | H40: =IF(G40=0,0,(G40*100/G$19)) -> 1.9623878 | J40: Food & Beverage | L40: =+L16-L21-L27-L33 -> 1737064.7 | M40: =IF(L40=0,0,(L40*100/L$19)) -> 16.985016 | N40: =+N16-N21-N27-N33 -> 0 | O40: =IF(N40=0,0,(N40*100/N$19)) -> 0 | P40: =+P16-P21-P27-P33 -> -1737064.7 | Q40: =IF(P40=0,0,(P40*100/P$19)) -> 16.985016 | R40: =+R16-R21-R27-R33 -> 1928916.1 | S40: =IF(R40=0,0,(R40*100/R$19)) -> 19.59763
A41: =+A17-A22-A28-A34 -> 31848.41 | B41: =IF(A41=0,0,(A41*100/A$19)) -> 0.38249812 | C41: =+C17-C22-C28-C34 -> -424.81 | D41: =IF(C41=0,0,(C41*100/C$19)) -> 0.0049054733 | E41: =+E17-E22-E28-E34 -> 0 | F41: =IF(E41=0,0,(E41*100/E$19)) -> 0 | G41: =+G17-G22-G28-G34 -> 424.81 | H41: =IF(G41=0,0,(G41*100/G$19)) -> 0.0049054733 | J41: Spa & Fitness Center | L41: =+L17-L22-L28-L34 -> 424.81 | M41: =IF(L41=0,0,(L41*100/L$19)) -> 0.0041537914 | N41: =+N17-N22-N28-N34 -> 0 | O41: =IF(N41=0,0,(N41*100/N$19)) -> 0 | P41: =+P17-P22-P28-P34 -> -424.81 | Q41: =IF(P41=0,0,(P41*100/P$19)) -> 0.0041537914 | R41: =+R17-R22-R28-R34 -> 31848.41 | S41: =IF(R41=0,0,(R41*100/R$19)) -> 0.32357723
A42: =+A18-A23-A29-A35 -> 195075.65 | B42: =IF(A42=0,0,(A42*100/A$19)) -> 2.3428507 | C42: =+C18-C23-C29-C35 -> -172310.85 | D42: =IF(C42=0,0,(C42*100/C$19)) -> 1.9897513 | E42: =+E18-E23-E29-E35 -> 0 | F42: =IF(E42=0,0,(E42*100/E$19)) -> 0 | G42: =+G18-G23-G29-G35 -> 172310.85 | H42: =IF(G42=0,0,(G42*100/G$19)) -> 1.9897513 | J42: Other Operated Departments | L42: =+L18-L23-L29-L35 -> 172310.85 | M42: =IF(L42=0,0,(L42*100/L$19)) -> 1.6848552 | N42: =+N18-N23-N29-N35 -> 0 | O42: =IF(N42=0,0,(N42*100/N$19)) -> 0 | P42: =+P18-P23-P29-P35 -> -172310.85 | Q42: =IF(P42=0,0,(P42*100/P$19)) -> 1.6848552 | R42: =+R18-R23-R29-R35 -> 195075.65 | S42: =IF(R42=0,0,(R42*100/R$19)) -> 1.9819526
...

Sheet Sum Room
A2: HOMM SUKHUMVIT34 BANGKOK | T2: Period | U2: =PRD -> 1
J3: Room Department | Q3: SCHEDULE - B | AA3: Mapping Area
A4: CURRENT MONTH | L4: YEAR TO DATE | AA4: *Department Code | AG4: *Account Code | BB4: Dimension | BF4: Dimension
A5: LAST YEAR | C5: VARIANCE | E5: BUDGET | G5: ACTUAL | J5: DESCRIPTION | L5: ACTUAL | N5: BUDGET | P5: VARIANCE | R5: LAST YEAR | AA5: Dept 1 | AB5: Dept 2 | AC5: Dept 3 | AD5: Dept 4 | AE5: Dept 5 | AG5: 1st Range | AI5: 2nd Range | AK5: 3rd Range | AM5: 4rd Range | AO5: 5rd Range | AQ5: 6rd Range | AS5: 7rd Range | AU5: 8rd Range | AW5: 9rd Range | AY5: 10th Range
A6: BHT | B6: % | C6: BHT | D6: % | E6: BHT | F6: % | G6: BHT | H6: % | L6: BHT | M6: % | N6: BHT | O6: % | P6: BHT | Q6: % | R6: BHT | S6: % | AG6: From | AH6: To | AI6: From | AJ6: To | AK6: From | AL6: To | AM6: From | AN6: To | AO6: From | AP6: To | AQ6: From | AR6: To | AS6: From | AT6: To | AU6: From | AV6: To | AW6: From | AX6: To | AY6: From | AZ6: To | BB6: A/O | BC6: Field Name | BD6: Operator | BE6: Value | BF6: A/O | BG6: Field Name | BH6: Operator | BI6: Value
J7: REVENUE | BB7: A | BC7: Matket1 | BD7: in | BE7: OTA,FIT | BF7: A | BG7: Matket2 | BH7: in | BI7: OTA1,FIT1
A8: {=_xll.AC(DB,_xll.ArrayDPT($AA8:$AE8),_xll.ArrayCOA($AG8:$AZ8),YR-1,PRD,_xll.ArrayDIM($BB8:$BE8))} -> 7234622.9 | B8: =IF(A8=0,0,(A8*100/A$14)) -> 99.794519 | C8: =+E8-G8 -> -7896040 | D8: =IF(C8=0,0,(C8*100/C$14)) -> 99.674431 | E8: {=_xll.BC(DB,_xll.ArrayDPT($AA8:$AE8),_xll.ArrayCOA($AG8:$AZ8),YR,PRD,RV,_xll.ArrayDIM($BB8:$BE8))} -> 0 | F8: =IF(E8=0,0,(E8*100/E$14)) -> 0 | G8: =_xll.AC(DB,_xll.ArrayDPT($AA8:$AE8),_xll.ArrayCOA($AG8:$AZ8),YR,PRD,_xll.ArrayDIM($BB8:$BE8)) -> 7896040 | H8: =IF(G8=0,0,(G8*100/G$14)) -> 99.674431 | J8: ROOM REVENUE | L8: =_xll.ACC(DB,_xll.ArrayDPT($AA8:$AE8),_xll.ArrayCOA($AG8:$AZ8),YR,PRD,_xll.ArrayDIM($BB8:$BE8)) -> 7896040 | M8: =IF(L8=0,0,(L8*100/L$14)) -> 99.674431 | N8: {=_xll.BCC(DB,_xll.ArrayDPT($AA8:$AE8),_xll.ArrayCOA($AG8:$AZ8),YR,PRD,RV,_xll.ArrayDIM($BB8:$BE8))} -> 0 | O8: =IF(N8=0,0,(N8*100/N$14)) -> 0 | P8: =+N8-L8 -> -7896040 | Q8: =IF(P8=0,0,(P8*100/P$14)) -> 99.674431 | R8: {=_xll.ACC(DB,_xll.ArrayDPT($AA8:$AE8),_xll.ArrayCOA($AG8:$AZ8),YR-1,PRD,_xll.ArrayDIM($BB8:$BE8))} -> 7234622.9 | S8: =IF(R8=0,0,(R8*100/R$14)) -> 99.794519 | AA8: 101 | AG8: 11100 | AH8: 11100
A9: {=_xll.AC(DB,_xll.ArrayDPT($AA9:$AE9),_xll.ArrayCOA($AG9:$AZ9),YR-1,PRD,_xll.ArrayDIM($BB9:$BE9))} -> 0 | B9: =IF(A9=0,0,(A9*100/A$14)) -> 0 | C9: =+E9-G9 -> 0 | D9: =IF(C9=0,0,(C9*100/C$14)) -> 0 | E9: {=_xll.BC(DB,_xll.ArrayDPT($AA9:$AE9),_xll.ArrayCOA($AG9:$AZ9),YR,PRD,RV,_xll.ArrayDIM($BB9:$BE9))} -> 0 | F9: =IF(E9=0,0,(E9*100/E$14)) -> 0 | G9: {=_xll.AC(DB,_xll.ArrayDPT($AA9:$AE9),_xll.ArrayCOA($AG9:$AZ9),YR,PRD,_xll.ArrayDIM($BB9:$BE9))} -> 0 | H9: =IF(G9=0,0,(G9*100/G$14)) -> 0 | J9: SERVICECHARGE - ROOM REVENUE | L9: {=_xll.ACC(DB,_xll.ArrayDPT($AA9:$AE9),_xll.ArrayCOA($AG9:$AZ9),YR,PRD,_xll.ArrayDIM($BB9:$BE9))} -> 0 | M9: =IF(L9=0,0,(L9*100/L$14)) -> 0 | N9: {=_xll.BCC(DB,_xll.ArrayDPT($AA9:$AE9),_xll.ArrayCOA($AG9:$AZ9),YR,PRD,RV,_xll.ArrayDIM($BB9:$BE9))} -> 0 | O9: =IF(N9=0,0,(N9*100/N$14)) -> 0 | P9: =+N9-L9 -> 0 | Q9: =IF(P9=0,0,(P9*100/P$14)) -> 0 | R9: {=_xll.ACC(DB,_xll.ArrayDPT($AA9:$AE9),_xll.ArrayCOA($AG9:$AZ9),YR-1,PRD,_xll.ArrayDIM($BB9:$BE9))} -> 0 | S9: =IF(R9=0,0,(R9*100/R$14)) -> 0
A10: {=_xll.AC(DB,_xll.ArrayDPT($AA10:$AE10),_xll.ArrayCOA($AG10:$AZ10),YR-1,PRD,_xll.ArrayDIM($BB10:$BE10))} -> 36402.76 | B10: =IF(A10=0,0,(A10*100/A$14)) -> 0.50214033 | C10: =+E10-G10 -> -38913.08 | D10: =IF(C10=0,0,(C10*100/C$14)) -> 0.49121321 | E10: {=_xll.BC(DB,_xll.ArrayDPT($AA10:$AE10),_xll.ArrayCOA($AG10:$AZ10),YR,PRD,RV,_xll.ArrayDIM($BB10:$BE10))} -> 0 | F10: =IF(E10=0,0,(E10*100/E$14)) -> 0 | G10: {=_xll.AC(DB,_xll.ArrayDPT($AA10:$AE10),_xll.ArrayCOA($AG10:$AZ10),YR,PRD,_xll.ArrayDIM($BB10:$BE10))} -> 38913.08 | H10: =IF(G10=0,0,(G10*100/G$14)) -> 0.49121321 | J10: ROOM REVENUE - OTHER | L10: {=_xll.ACC(DB,_xll.ArrayDPT($AA10:$AE10),_xll.ArrayCOA($AG10:$AZ10),YR,PRD,_xll.ArrayDIM($BB10:$BE10))} -> 38913.08 | M10: =IF(L10=0,0,(L10*100/L$14)) -> 0.49121321 | N10: {=_xll.BCC(DB,_xll.ArrayDPT($AA10:$AE10),_xll.ArrayCOA($AG10:$AZ10),YR,PRD,RV,_xll.ArrayDIM($BB10:$BE10))} -> 0 | O10: =IF(N10=0,0,(N10*100/N$14)) -> 0 | P10: =+N10-L10 -> -38913.08 | Q10: =IF(P10=0,0,(P10*100/P$14)) -> 0.49121321 | R10: {=_xll.ACC(DB,_xll.ArrayDPT($AA10:$AE10),_xll.ArrayCOA($AG10:$AZ10),YR-1,PRD,_xll.ArrayDIM($BB10:$BE10))} -> 36402.76 | S10: =IF(R10=0,0,(R10*100/R$14)) -> 0.50214033 | AA10: 101 | AG10: 11101 | AH10: 11101
A11: {=_xll.AC(DB,_xll.ArrayDPT($AA11:$AE11),_xll.ArrayCOA($AG11:$AZ11),YR-1,PRD,_xll.ArrayDIM($BB11:$BE11))} -> -21506.38 | B11: =IF(A11=0,0,(A11*100/A$14)) -> -0.29665939 | C11: =+E11-G11 -> 13122.06 | D11: =IF(C11=0,0,(C11*100/C$14)) -> -0.16564428 | E11: {=_xll.BC(DB,_xll.ArrayDPT($AA11:$AE11),_xll.ArrayCOA($AG11:$AZ11),YR,PRD,RV,_xll.ArrayDIM($BB11:$BE11))} -> 0 | F11: =IF(E11=0,0,(E11*100/E$14)) -> 0 | G11: {=_xll.AC(DB,_xll.ArrayDPT($AA11:$AE11),_xll.ArrayCOA($AG11:$AZ11),YR,PRD,_xll.ArrayDIM($BB11:$BE11))} -> -13122.06 | H11: =IF(G11=0,0,(G11*100/G$14)) -> -0.16564428 | J11: ALLOWANCES | L11: {=_xll.ACC(DB,_xll.ArrayDPT($AA11:$AE11),_xll.ArrayCOA($AG11:$AZ11),YR,PRD,_xll.ArrayDIM($BB11:$BE11))} -> -13122.06 | M11: =IF(L11=0,0,(L11*100/L$14)) -> -0.16564428 | N11: {=_xll.BCC(DB,_xll.ArrayDPT($AA11:$AE11),_xll.ArrayCOA($AG11:$AZ11),YR,PRD,RV,_xll.ArrayDIM($BB11:$BE11))} -> 0 | O11: =IF(N11=0,0,(N11*100/N$14)) -> 0 | P11: =+N11-L11 -> 13122.06 | Q11: =IF(P11=0,0,(P11*100/P$14)) -> -0.16564428 | R11: {=_xll.ACC(DB,_xll.ArrayDPT($AA11:$AE11),_xll.ArrayCOA($AG11:$AZ11),YR-1,PRD,_xll.ArrayDIM($BB11:$BE11))} -> -21506.38 | S11: =IF(R11=0,0,(R11*100/R$14)) -> -0.29665939 | AA11: 101 | AG11: 20005 | AH11: 20005
A12: {=_xll.AC(DB,_xll.ArrayDPT($AA12:$AE12),_xll.ArrayCOA($AG12:$AZ12),YR-1,PRD,_xll.ArrayDIM($BB12:$BE12))} -> 0 | B12: =IF(A12=0,0,(A12*100/A$14)) -> 0 | C12: =+E12-G12 -> 0 | D12: =IF(C12=0,0,(C12*100/C$14)) -> 0 | E12: {=_xll.BC(DB,_xll.ArrayDPT($AA12:$AE12),_xll.ArrayCOA($AG12:$AZ12),YR,PRD,RV,_xll.ArrayDIM($BB12:$BE12))} -> 0 | F12: =IF(E12=0,0,(E12*100/E$14)) -> 0 | G12: {=_xll.AC(DB,_xll.ArrayDPT($AA12:$AE12),_xll.ArrayCOA($AG12:$AZ12),YR,PRD,_xll.ArrayDIM($BB12:$BE12))} -> 0 | H12: =IF(G12=0,0,(G12*100/G$14)) -> 0 | J12: EXTRA ROOM REVENUE | L12: {=_xll.ACC(DB,_xll.ArrayDPT($AA12:$AE12),_xll.ArrayCOA($AG12:$AZ12),YR,PRD,_xll.ArrayDIM($BB12:$BE12))} -> 0 | M12: =IF(L12=0,0,(L12*100/L$14)) -> 0 | N12: {=_xll.BCC(DB,_xll.ArrayDPT($AA12:$AE12),_xll.ArrayCOA($AG12:$AZ12),YR,PRD,RV,_xll.ArrayDIM($BB12:$BE12))} -> 0 | O12: =IF(N12=0,0,(N12*100/N$14)) -> 0 | P12: =+N12-L12 -> 0 | Q12: =IF(P12=0,0,(P12*100/P$14)) -> 0 | R12: {=_xll.ACC(DB,_xll.ArrayDPT($AA12:$AE12),_xll.ArrayCOA($AG12:$AZ12),YR-1,PRD,_xll.ArrayDIM($BB12:$BE12))} -> 0 | S12: =IF(R12=0,0,(R12*100/R$14)) -> 0 | AA12: 101
A14: =SUM(A8:A13) -> 7249519.3 | B14: =IF(A14=0,0,(A14*100/A$14)) -> 100 | C14: =SUM(C8:C13) -> -7921831 | D14: =IF(C14=0,0,(C14*100/C$14)) -> 100 | E14: =SUM(E8:E13) -> 0 | F14: =IF(E14=0,0,(E14*100/E$14)) -> 0 | G14: =SUM(G8:G13) -> 7921831 | H14: =IF(G14=0,0,(G14*100/G$14)) -> 100 | J14: NET REVENUE | L14: =SUM(L8:L13) -> 7921831 | M14: =IF(L14=0,0,(L14*100/L$14)) -> 100 | N14: =SUM(N8:N13) -> 0 | O14: =IF(N14=0,0,(N14*100/N$14)) -> 0 | P14: =SUM(P8:P13) -> -7921831 | Q14: =IF(P14=0,0,(P14*100/P$14)) -> 100 | R14: =SUM(R8:R13) -> 7249519.3 | S14: =IF(R14=0,0,(R14*100/R$14)) -> 100
J15: PAYROLL & EMP. RELATION
A16: {=_xll.AC(DB,_xll.ArrayDPT($AA16:$AE16),_xll.ArrayCOA($AG16:$AZ16),YR-1,PRD,_xll.ArrayDIM($BB16:$BE16))} -> 0 | B16: =IF(A16=0,0,(A16*100/A$14)) -> 0 | C16: =+E16-G16 -> 0 | D16: =IF(C16=0,0,(C16*100/C$14)) -> 0 | E16: {=_xll.BC(DB,_xll.ArrayDPT($AA16:$AE16),_xll.ArrayCOA($AG16:$AZ16),YR,PRD,RV,_xll.ArrayDIM($BB16:$BE16))} -> 0 | F16: =IF(E16=0,0,(E16*100/E$14)) -> 0 | G16: =_xll.AC(DB,_xll.ArrayDPT($AA16:$AE16),_xll.ArrayCOA($AG16:$AZ16),YR,PRD,_xll.ArrayDIM($BB16:$BE16)) -> 0 | H16: =IF(G16=0,0,(G16*100/G$14)) -> 0 | J16: SALARIES & WAGES - FRONT OFFICE | L16: {=_xll.ACC(DB,_xll.ArrayDPT($AA16:$AE16),_xll.ArrayCOA($AG16:$AZ16),YR,PRD,_xll.ArrayDIM($BB16:$BE16))} -> 0 | M16: =IF(L16=0,0,(L16*100/L$14)) -> 0 | N16: {=_xll.BCC(DB,_xll.ArrayDPT($AA16:$AE16),_xll.ArrayCOA($AG16:$AZ16),YR,PRD,RV,_xll.ArrayDIM($BB16:$BE16))} -> 0 | O16: =IF(N16=0,0,(N16*100/N$14)) -> 0 | P16: =+N16-L16 -> 0 | Q16: =IF(P16=0,0,(P16*100/P$14)) -> 0 | R16: {=_xll.ACC(DB,_xll.ArrayDPT($AA16:$AE16),_xll.ArrayCOA($AG16:$AZ16),YR-1,PRD,_xll.ArrayDIM($BB16:$BE16))} -> 0 | S16: =IF(R16=0,0,(R16*100/R$14)) -> 0 | AA16: 103 | AG16: 42104 | AH16: 42104
A17: {=_xll.AC(DB,_xll.ArrayDPT($AA17:$AE17),_xll.ArrayCOA($AG17:$AZ17),YR-1,PRD,_xll.ArrayDIM($BB17:$BE17))} -> 0 | B17: =IF(A17=0,0,(A17*100/A$14)) -> 0 | C17: =+E17-G17 -> -53066.67 | D17: =IF(C17=0,0,(C17*100/C$14)) -> 0.66987884 | E17: {=_xll.BC(DB,_xll.ArrayDPT($AA17:$AE17),_xll.ArrayCOA($AG17:$AZ17),YR,PRD,RV,_xll.ArrayDIM($BB17:$BE17))} -> 0 | F17: =IF(E17=0,0,(E17*100/E$14)) -> 0 | G17: {=_xll.AC(DB,_xll.ArrayDPT($AA17:$AE17),_xll.ArrayCOA($AG17:$AZ17),YR,PRD,_xll.ArrayDIM($BB17:$BE17))} -> 53066.67 | H17: =IF(G17=0,0,(G17*100/G$14)) -> 0.66987884 | J17: SALARIES & WAGES - MANAGEMENT | L17: {=_xll.ACC(DB,_xll.ArrayDPT($AA17:$AE17),_xll.ArrayCOA($AG17:$AZ17),YR,PRD,_xll.ArrayDIM($BB17:$BE17))} -> 53066.67 | M17: =IF(L17=0,0,(L17*100/L$14)) -> 0.66987884 | N17: {=_xll.BCC(DB,_xll.ArrayDPT($AA17:$AE17),_xll.ArrayCOA($AG17:$AZ17),YR,PRD,RV,_xll.ArrayDIM($BB17:$BE17))} -> 0 | O17: =IF(N17=0,0,(N17*100/N$14)) -> 0 | P17: =+N17-L17 -> -53066.67 | Q17: =IF(P17=0,0,(P17*100/P$14)) -> 0.66987884 | R17: {=_xll.ACC(DB,_xll.ArrayDPT($AA17:$AE17),_xll.ArrayCOA($AG17:$AZ17),YR-1,PRD,_xll.ArrayDIM($BB17:$BE17))} -> 0 | S17: =IF(R17=0,0,(R17*100/R$14)) -> 0 | AA17: 103 | AB17: 104 | AG17: 42006 | AH17: 42006
A18: {=_xll.AC(DB,_xll.ArrayDPT($AA18:$AE18),_xll.ArrayCOA($AG18:$AZ18),YR-1,PRD,_xll.ArrayDIM($BB18:$BE18))} -> 273833.34 | B18: =IF(A18=0,0,(A18*100/A$14)) -> 3.777262 | C18: =+E18-G18 -> -219666.67 | D18: =IF(C18=0,0,(C18*100/C$14)) -> 2.772928 | E18: {=_xll.BC(DB,_xll.ArrayDPT($AA18:$AE18),_xll.ArrayCOA($AG18:$AZ18),YR,PRD,RV,_xll.ArrayDIM($BB18:$BE18))} -> 0 | F18: =IF(E18=0,0,(E18*100/E$14)) -> 0 | G18: {=_xll.AC(DB,_xll.ArrayDPT($AA18:$AE18),_xll.ArrayCOA($AG18:$AZ18),YR,PRD,_xll.ArrayDIM($BB18:$BE18))} -> 219666.67 | H18: =IF(G18=0,0,(G18*100/G$14)) -> 2.772928 | J18: SALARIES & WAGES_NON MANAGEMENT | L18: {=_xll.ACC(DB,_xll.ArrayDPT($AA18:$AE18),_xll.ArrayCOA($AG18:$AZ18),YR,PRD,_xll.ArrayDIM($BB18:$BE18))} -> 219666.67 | M18: =IF(L18=0,0,(L18*100/L$14)) -> 2.772928 | N18: {=_xll.BCC(DB,_xll.ArrayDPT($AA18:$AE18),_xll.ArrayCOA($AG18:$AZ18),YR,PRD,RV,_xll.ArrayDIM($BB18:$BE18))} -> 0 | O18: =IF(N18=0,0,(N18*100/N$14)) -> 0 | P18: =+N18-L18 -> -219666.67 | Q18: =IF(P18=0,0,(P18*100/P$14)) -> 2.772928 | R18: {=_xll.ACC(DB,_xll.ArrayDPT($AA18:$AE18),_xll.ArrayCOA($AG18:$AZ18),YR-1,PRD,_xll.ArrayDIM($BB18:$BE18))} -> 273833.34 | S18: =IF(R18=0,0,(R18*100/R$14)) -> 3.777262 | AA18: 103 | AB18: 104 | AC18: 107 | AG18: 42005 | AH18: 42005
A19: {=_xll.AC(DB,_xll.ArrayDPT($AA19:$AE19),_xll.ArrayCOA($AG19:$AZ19),YR-1,PRD,_xll.ArrayDIM($BB19:$BE19))} -> 0 | B19: =IF(A19=0,0,(A19*100/A$14)) -> 0 | C19: =+E19-G19 -> 0 | D19: =IF(C19=0,0,(C19*100/C$14)) -> 0 | E19: {=_xll.BC(DB,_xll.ArrayDPT($AA19:$AE19),_xll.ArrayCOA($AG19:$AZ19),YR,PRD,RV,_xll.ArrayDIM($BB19:$BE19))} -> 0 | F19: =IF(E19=0,0,(E19*100/E$14)) -> 0 | G19: =_xll.AC(DB,_xll.ArrayDPT($AA19:$AE19),_xll.ArrayCOA($AG19:$AZ19),YR,PRD,_xll.ArrayDIM($BB19:$BE19)) -> 0 | H19: =IF(G19=0,0,(G19*100/G$14)) -> 0 | J19: SALARIES & WAGES - RESERVATION | L19: {=_xll.ACC(DB,_xll.ArrayDPT($AA19:$AE19),_xll.ArrayCOA($AG19:$AZ19),YR,PRD,_xll.ArrayDIM($BB19:$BE19))} -> 0 | M19: =IF(L19=0,0,(L19*100/L$14)) -> 0 | N19: {=_xll.BCC(DB,_xll.ArrayDPT($AA19:$AE19),_xll.ArrayCOA($AG19:$AZ19),YR,PRD,RV,_xll.ArrayDIM($BB19:$BE19))} -> 0 | O19: =IF(N19=0,0,(N19*100/N$14)) -> 0 | P19: =+N19-L19 -> 0 | Q19: =IF(P19=0,0,(P19*100/P$14)) -> 0 | R19: {=_xll.ACC(DB,_xll.ArrayDPT($AA19:$AE19),_xll.ArrayCOA($AG19:$AZ19),YR-1,PRD,_xll.ArrayDIM($BB19:$BE19))} -> 0 | S19: =IF(R19=0,0,(R19*100/R$14)) -> 0 | AA19: 107 | AG19: 42105 | AH19: 42105
A20: {=_xll.AC(DB,_xll.ArrayDPT($AA20:$AE20),_xll.ArrayCOA($AG20:$AZ20),YR-1,PRD,_xll.ArrayDIM($BB20:$BE20))} -> 0 | B20: =IF(A20=0,0,(A20*100/A$14)) -> 0 | C20: =+E20-G20 -> 0 | D20: =IF(C20=0,0,(C20*100/C$14)) -> 0 | E20: {=_xll.BC(DB,_xll.ArrayDPT($AA20:$AE20),_xll.ArrayCOA($AG20:$AZ20),YR,PRD,RV,_xll.ArrayDIM($BB20:$BE20))} -> 0 | F20: =IF(E20=0,0,(E20*100/E$14)) -> 0 | G20: {=_xll.AC(DB,_xll.ArrayDPT($AA20:$AE20),_xll.ArrayCOA($AG20:$AZ20),YR,PRD,_xll.ArrayDIM($BB20:$BE20))} -> 0 | H20: =IF(G20=0,0,(G20*100/G$14)) -> 0 | J20: SALARIES & WAGES - HOUSEKEEPING | L20: {=_xll.ACC(DB,_xll.ArrayDPT($AA20:$AE20),_xll.ArrayCOA($AG20:$AZ20),YR,PRD,_xll.ArrayDIM($BB20:$BE20))} -> 0 | M20: =IF(L20=0,0,(L20*100/L$14)) -> 0 | N20: {=_xll.BCC(DB,_xll.ArrayDPT($AA20:$AE20),_xll.ArrayCOA($AG20:$AZ20),YR,PRD,RV,_xll.ArrayDIM($BB20:$BE20))} -> 0 | O20: =IF(N20=0,0,(N20*100/N$14)) -> 0 | P20: =+N20-L20 -> 0 | Q20: =IF(P20=0,0,(P20*100/P$14)) -> 0 | R20: {=_xll.ACC(DB,_xll.ArrayDPT($AA20:$AE20),_xll.ArrayCOA($AG20:$AZ20),YR-1,PRD,_xll.ArrayDIM($BB20:$BE20))} -> 0 | S20: =IF(R20=0,0,(R20*100/R$14)) -> 0 | AA20: 104 | AG20: 42101 | AH20: 42101
A21: {=_xll.AC(DB,_xll.ArrayDPT($AA21:$AE21),_xll.ArrayCOA($AG21:$AZ21),YR-1,PRD,_xll.ArrayDIM($BB21:$BE21))} -> 0 | B21: =IF(A21=0,0,(A21*100/A$14)) -> 0 | C21: =+E21-G21 -> -10436 | D21: =IF(C21=0,0,(C21*100/C$14)) -> 0.13173722 | E21: {=_xll.BC(DB,_xll.ArrayDPT($AA21:$AE21),_xll.ArrayCOA($AG21:$AZ21),YR,PRD,RV,_xll.ArrayDIM($BB21:$BE21))} -> 0 | F21: =IF(E21=0,0,(E21*100/E$14)) -> 0 | G21: {=_xll.AC(DB,_xll.ArrayDPT($AA21:$AE21),_xll.ArrayCOA($AG21:$AZ21),YR,PRD,_xll.ArrayDIM($BB21:$BE21))} -> 10436 | H21: =IF(G21=0,0,(G21*100/G$14)) -> 0.13173722 | J21: PAYROLL TAXES ON SOCIAL SECURITY CONTRIBUTION | L21: {=_xll.ACC(DB,_xll.ArrayDPT($AA21:$AE21),_xll.ArrayCOA($AG21:$AZ21),YR,PRD,_xll.ArrayDIM($BB21:$BE21))} -> 10436 | M21: =IF(L21=0,0,(L21*100/L$14)) -> 0.13173722 | N21: {=_xll.BCC(DB,_xll.ArrayDPT($AA21:$AE21),_xll.ArrayCOA($AG21:$AZ21),YR,PRD,RV,_xll.ArrayDIM($BB21:$BE21))} -> 0 | O21: =IF(N21=0,0,(N21*100/N$14)) -> 0 | P21: =+N21-L21 -> -10436 | Q21: =IF(P21=0,0,(P21*100/P$14)) -> 0.13173722 | R21: {=_xll.ACC(DB,_xll.ArrayDPT($AA21:$AE21),_xll.ArrayCOA($AG21:$AZ21),YR-1,PRD,_xll.ArrayDIM($BB21:$BE21))} -> 0 | S21: =IF(R21=0,0,(R21*100/R$14)) -> 0 | AA21: 103 | AB21: 104 | AC21: 107 | AG21: 45005 | AH21: 45005
A22: {=_xll.AC(DB,_xll.ArrayDPT($AA22:$AE22),_xll.ArrayCOA($AG22:$AZ22),YR-1,PRD,_xll.ArrayDIM($BB22:$BE22))} -> 0 | B22: =IF(A22=0,0,(A22*100/A$14)) -> 0 | C22: =+E22-G22 -> 0 | D22: =IF(C22=0,0,(C22*100/C$14)) -> 0 | E22: {=_xll.BC(DB,_xll.ArrayDPT($AA22:$AE22),_xll.ArrayCOA($AG22:$AZ22),YR,PRD,RV,_xll.ArrayDIM($BB22:$BE22))} -> 0 | F22: =IF(E22=0,0,(E22*100/E$14)) -> 0 | G22: {=_xll.AC(DB,_xll.ArrayDPT($AA22:$AE22),_xll.ArrayCOA($AG22:$AZ22),YR,PRD,_xll.ArrayDIM($BB22:$BE22))} -> 0 | H22: =IF(G22=0,0,(G22*100/G$14)) -> 0 | J22: CASUAL & DAILY HIRE | L22: {=_xll.ACC(DB,_xll.ArrayDPT($AA22:$AE22),_xll.ArrayCOA($AG22:$AZ22),YR,PRD,_xll.ArrayDIM($BB22:$BE22))} -> 0 | M22: =IF(L22=0,0,(L22*100/L$14)) -> 0 | N22: {=_xll.BCC(DB,_xll.ArrayDPT($AA22:$AE22),_xll.ArrayCOA($AG22:$AZ22),YR,PRD,RV,_xll.ArrayDIM($BB22:$BE22))} -> 0 | O22: =IF(N22=0,0,(N22*100/N$14)) -> 0 | P22: =+N22-L22 -> 0 | Q22: =IF(P22=0,0,(P22*100/P$14)) -> 0 | R22: {=_xll.ACC(DB,_xll.ArrayDPT($AA22:$AE22),_xll.ArrayCOA($AG22:$AZ22),YR-1,PRD,_xll.ArrayDIM($BB22:$BE22))} -> 0 | S22: =IF(R22=0,0,(R22*100/R$14)) -> 0 | AA22: 104 | AG22: 42015 | AH22: 42015
A23: {=_xll.AC(DB,_xll.ArrayDPT($AA23:$AE23),_xll.ArrayCOA($AG23:$AZ23),YR-1,PRD,_xll.ArrayDIM($BB23:$BE23))} -> 0 | B23: =IF(A23=0,0,(A23*100/A$14)) -> 0 | C23: =+E23-G23 -> -5835.94 | D23: =IF(C23=0,0,(C23*100/C$14)) -> 0.07366908 | E23: {=_xll.BC(DB,_xll.ArrayDPT($AA23:$AE23),_xll.ArrayCOA($AG23:$AZ23),YR,PRD,RV,_xll.ArrayDIM($BB23:$BE23))} -> 0 | F23: =IF(E23=0,0,(E23*100/E$14)) -> 0 | G23: {=_xll.AC(DB,_xll.ArrayDPT($AA23:$AE23),_xll.ArrayCOA($AG23:$AZ23),YR,PRD,_xll.ArrayDIM($BB23:$BE23))} -> 5835.94 | H23: =IF(G23=0,0,(G23*100/G$14)) -> 0.07366908 | J23: EXTRA & OVERTIME | L23: {=_xll.ACC(DB,_xll.ArrayDPT($AA23:$AE23),_xll.ArrayCOA($AG23:$AZ23),YR,PRD,_xll.ArrayDIM($BB23:$BE23))} -> 5835.94 | M23: =IF(L23=0,0,(L23*100/L$14)) -> 0.07366908 | N23: {=_xll.BCC(DB,_xll.ArrayDPT($AA23:$AE23),_xll.ArrayCOA($AG23:$AZ23),YR,PRD,RV,_xll.ArrayDIM($BB23:$BE23))} -> 0 | O23: =IF(N23=0,0,(N23*100/N$14)) -> 0 | P23: =+N23-L23 -> -5835.94 | Q23: =IF(P23=0,0,(P23*100/P$14)) -> 0.07366908 | R23: {=_xll.ACC(DB,_xll.ArrayDPT($AA23:$AE23),_xll.ArrayCOA($AG23:$AZ23),YR-1,PRD,_xll.ArrayDIM($BB23:$BE23))} -> 0 | S23: =IF(R23=0,0,(R23*100/R$14)) -> 0 | AA23: 103 | AB23: 104 | AG23: 42011 | AH23: 42011
A24: {=_xll.AC(DB,_xll.ArrayDPT($AA24:$AE24),_xll.ArrayCOA($AG24:$AZ24),YR-1,PRD,_xll.ArrayDIM($BB24:$BE24))} -> 3800 | B24: =IF(A24=0,0,(A24*100/A$14)) -> 0.052417268 | C24: =+E24-G24 -> 0 | D24: =IF(C24=0,0,(C24*100/C$14)) -> 0 | E24: {=_xll.BC(DB,_xll.ArrayDPT($AA24:$AE24),_xll.ArrayCOA($AG24:$AZ24),YR,PRD,RV,_xll.ArrayDIM($BB24:$BE24))} -> 0 | F24: =IF(E24=0,0,(E24*100/E$14)) -> 0 | G24: {=_xll.AC(DB,_xll.ArrayDPT($AA24:$AE24),_xll.ArrayCOA($AG24:$AZ24),YR,PRD,_xll.ArrayDIM($BB24:$BE24))} -> 0 | H24: =IF(G24=0,0,(G24*100/G$14)) -> 0 | J24: OTHER EMPLOYEE BENEFITS | L24: {=_xll.ACC(DB,_xll.ArrayDPT($AA24:$AE24),_xll.ArrayCOA($AG24:$AZ24),YR,PRD,_xll.ArrayDIM($BB24:$BE24))} -> 0 | M24: =IF(L24=0,0,(L24*100/L$14)) -> 0 | N24: {=_xll.BCC(DB,_xll.ArrayDPT($AA24:$AE24),_xll.ArrayCOA($AG24:$AZ24),YR,PRD,RV,_xll.ArrayDIM($BB24:$BE24))} -> 0 | O24: =IF(N24=0,0,(N24*100/N$14)) -> 0 | P24: =+N24-L24 -> 0 | Q24: =IF(P24=0,0,(P24*100/P$14)) -> 0 | R24: {=_xll.ACC(DB,_xll.ArrayDPT($AA24:$AE24),_xll.ArrayCOA($AG24:$AZ24),YR-1,PRD,_xll.ArrayDIM($BB24:$BE24))} -> 3800 | S24: =IF(R24=0,0,(R24*100/R$14)) -> 0.052417268 | AA24: 103 | AB24: 104 | AC24: 107 | AG24: 46070 | AH24: 46070
A26: =SUM(A16:A25) -> 277633.34 | B26: =IF(A26=0,0,(A26*100/A$14)) -> 3.8296793 | C26: =SUM(C16:C25) -> -289005.28 | D26: =IF(C26=0,0,(C26*100/C$14)) -> 3.6482131 | E26: =SUM(E16:E25) -> 0 | F26: =IF(E26=0,0,(E26*100/E$14)) -> 0 | G26: =SUM(G16:G25) -> 289005.28 | H26: =IF(G26=0,0,(G26*100/G$14)) -> 3.6482131 | J26: TOTAL PAYROLL & EMP. REL. | L26: =SUM(L16:L25) -> 289005.28 | M26: =IF(L26=0,0,(L26*100/L$14)) -> 3.6482131 | N26: =SUM(N16:N25) -> 0 | O26: =IF(N26=0,0,(N26*100/N$14)) -> 0 | P26: =SUM(P16:P25) -> -289005.28 | Q26: =IF(P26=0,0,(P26*100/P$14)) -> 3.6482131 | R26: =SUM(R16:R25) -> 277633.34 | S26: =IF(R26=0,0,(R26*100/R$14)) -> 3.8296793
J27: OTHER EXPENSES
A28: {=_xll.AC(DB,_xll.ArrayDPT($AA28:$AE28),_xll.ArrayCOA($AG28:$AZ28),YR-1,PRD,_xll.ArrayDIM($BB28:$BE28))} -> 254484.17 | B28: =IF(A28=0,0,(A28*100/A$14)) -> 3.5103592 | C28: =+E28-G28 -> -608078.65 | D28: =IF(C28=0,0,(C28*100/C$14)) -> 7.6759861 | E28: {=_xll.BC(DB,_xll.ArrayDPT($AA28:$AE28),_xll.ArrayCOA($AG28:$AZ28),YR,PRD,RV,_xll.ArrayDIM($BB28:$BE28))} -> 0 | F28: =IF(E28=0,0,(E28*100/E$14)) -> 0 | G28: {=_xll.AC(DB,_xll.ArrayDPT($AA28:$AE28),_xll.ArrayCOA($AG28:$AZ28),YR,PRD,_xll.ArrayDIM($BB28:$BE28))} -> 608078.65 | H28: =IF(G28=0,0,(G28*100/G$14)) -> 7.6759861 | J28: TRAVEL AGENCY COMMISSION | L28: {=_xll.ACC(DB,_xll.ArrayDPT($AA28:$AE28),_xll.ArrayCOA($AG28:$AZ28),YR,PRD,_xll.ArrayDIM($BB28:$BE28))} -> 608078.65 | M28: =IF(L28=0,0,(L28*100/L$14)) -> 7.6759861 | N28: {=_xll.BCC(DB,_xll.ArrayDPT($AA28:$AE28),_xll.ArrayCOA($AG28:$AZ28),YR,PRD,RV,_xll.ArrayDIM($BB28:$BE28))} -> 0 | O28: =IF(N28=0,0,(N28*100/N$14)) -> 0 | P28: =+N28-L28 -> -608078.65 | Q28: =IF(P28=0,0,(P28*100/P$14)) -> 7.6759861 | R28: {=_xll.ACC(DB,_xll.ArrayDPT($AA28:$AE28),_xll.ArrayCOA($AG28:$AZ28),YR-1,PRD,_xll.ArrayDIM($BB28:$BE28))} -> 254484.17 | S28: =IF(R28=0,0,(R28*100/R$14)) -> 3.5103592 | AA28: 103 | AB28: 107 | AG28: 50005 | AH28: 50005
A29: {=_xll.AC(DB,_xll.ArrayDPT($AA29:$AE29),_xll.ArrayCOA($AG29:$AZ29),YR-1,PRD,_xll.ArrayDIM($BB29:$BE29))} -> 24772.01 | B29: =IF(A29=0,0,(A29*100/A$14)) -> 0.34170555 | C29: =+E29-G29 -> -9435.8 | D29: =IF(C29=0,0,(C29*100/C$14)) -> 0.11911135 | E29: {=_xll.BC(DB,_xll.ArrayDPT($AA29:$AE29),_xll.ArrayCOA($AG29:$AZ29),YR,PRD,RV,_xll.ArrayDIM($BB29:$BE29))} -> 0 | F29: =IF(E29=0,0,(E29*100/E$14)) -> 0 | G29: {=_xll.AC(DB,_xll.ArrayDPT($AA29:$AE29),_xll.ArrayCOA($AG29:$AZ29),YR,PRD,_xll.ArrayDIM($BB29:$BE29))} -> 9435.8 | H29: =IF(G29=0,0,(G29*100/G$14)) -> 0.11911135 | J29: INCENTIVES INCENTIVES | L29: {=_xll.ACC(DB,_xll.ArrayDPT($AA29:$AE29),_xll.ArrayCOA($AG29:$AZ29),YR,PRD,_xll.ArrayDIM($BB29:$BE29))} -> 9435.8 | M29: =IF(L29=0,0,(L29*100/L$14)) -> 0.11911135 | N29: {=_xll.BCC(DB,_xll.ArrayDPT($AA29:$AE29),_xll.ArrayCOA($AG29:$AZ29),YR,PRD,RV,_xll.ArrayDIM($BB29:$BE29))} -> 0 | O29: =IF(N29=0,0,(N29*100/N$14)) -> 0 | P29: =+N29-L29 -> -9435.8 | Q29: =IF(P29=0,0,(P29*100/P$14)) -> 0.11911135 | R29: {=_xll.ACC(DB,_xll.ArrayDPT($AA29:$AE29),_xll.ArrayCOA($AG29:$AZ29),YR-1,PRD,_xll.ArrayDIM($BB29:$BE29))} -> 24772.01 | S29: =IF(R29=0,0,(R29*100/R$14)) -> 0.34170555 | AA29: 103 | AG29: 42025 | AH29: 42025
A30: {=_xll.AC(DB,_xll.ArrayDPT($AA30:$AE30),_xll.ArrayCOA($AG30:$AZ30),YR-1,PRD,_xll.ArrayDIM($BB30:$BE30))} -> 269564.86 | B30: =IF(A30=0,0,(A30*100/A$14)) -> 3.7183825 | C30: =+E30-G30 -> -165220.05 | D30: =IF(C30=0,0,(C30*100/C$14)) -> 2.0856296 | E30: {=_xll.BC(DB,_xll.ArrayDPT($AA30:$AE30),_xll.ArrayCOA($AG30:$AZ30),YR,PRD,RV,_xll.ArrayDIM($BB30:$BE30))} -> 0 | F30: =IF(E30=0,0,(E30*100/E$14)) -> 0 | G30: {=_xll.AC(DB,_xll.ArrayDPT($AA30:$AE30),_xll.ArrayCOA($AG30:$AZ30),YR,PRD,_xll.ArrayDIM($BB30:$BE30))} -> 165220.05 | H30: =IF(G30=0,0,(G30*100/G$14)) -> 2.0856296 | J30: RESERVATIONS | L30: {=_xll.ACC(DB,_xll.ArrayDPT($AA30:$AE30),_xll.ArrayCOA($AG30:$AZ30),YR,PRD,_xll.ArrayDIM($BB30:$BE30))} -> 165220.05 | M30: =IF(L30=0,0,(L30*100/L$14)) -> 2.0856296 | N30: {=_xll.BCC(DB,_xll.ArrayDPT($AA30:$AE30),_xll.ArrayCOA($AG30:$AZ30),YR,PRD,RV,_xll.ArrayDIM($BB30:$BE30))} -> 0 | O30: =IF(N30=0,0,(N30*100/N$14)) -> 0 | P30: =+N30-L30 -> -165220.05 | Q30: =IF(P30=0,0,(P30*100/P$14)) -> 2.0856296 | R30: {=_xll.ACC(DB,_xll.ArrayDPT($AA30:$AE30),_xll.ArrayCOA($AG30:$AZ30),YR-1,PRD,_xll.ArrayDIM($BB30:$BE30))} -> 269564.86 | S30: =IF(R30=0,0,(R30*100/R$14)) -> 3.7183825 | AA30: 107 | AG30: 51025 | AH30: 51025
